Workbook
Name 경조사회비: OFFSET(항목!$P$4,0,0,COUNTA(항목!$P$4:$P$18),1)
Name 계정: OFFSET(항목!$B$4,0,0,COUNTA(항목!$B$4:$B$18),1)
Name 계좌명: OFFSET(투자관리!$C$27,0,0,COUNTA(투자관리!$C$27:$C$31),1)
Name 계좌이름: 매매!$C$4:$C$1000
Name 교육계발비: OFFSET(항목!$K$4,0,0,COUNTA(항목!$K$4:$K$18),1)
Name 대분류: 항목!$C$3:$Q$3
Name 매도금액: 매매!$U$4:$U$1000
Name 매도수량: 매매!$T$4:$T$1000
Name 매도월: 매매!$K$4:$K$1000
Name 매도일: 매매!$Q$4:$Q$1000
Name 매수금액: 매매!$J$4:$J$1000
Name 매수수량: 매매!$I$4:$I$1000
Name 매수일: 매매!$G$4:$G$1000
Name 문화생활비: OFFSET(항목!$L$4,0,0,COUNTA(항목!$L$4:$L$18),1)
Name 미용비: OFFSET(항목!$J$4,0,0,COUNTA(항목!$J$4:$J$18),1)
Name 반려동물비: OFFSET(항목!$H$4,0,0,COUNTA(항목!$H$4:$H$18),1)
Name 생활용품비: OFFSET(항목!$G$4,0,0,COUNTA(항목!$G$4:$G$18),1)
Name 소분류: 항목!$C$4:$Q$18
Name 수입: OFFSET(항목!$C$4,0,0,COUNTA(항목!$C$4:$C$18),1)
Name 순매도금액: 매매!$W$4:$W$1000
Name 식비: OFFSET(항목!$E$4,0,0,COUNTA(항목!$E$4:$E$18),1)
Name 용돈지출: OFFSET(항목!$Q$4,0,0,COUNTA(항목!$Q$4:$Q$18),1)
Name 유류교통비: OFFSET(항목!$N$4,0,0,COUNTA(항목!$N$4:$N$18),1)
Name 의료비: OFFSET(항목!$M$4,0,0,COUNTA(항목!$M$4:$M$18),1)
Name 의류비: OFFSET(항목!$I$4,0,0,COUNTA(항목!$I$4:$I$18),1)
Name 저축성지출: OFFSET(항목!$D$4,0,0,COUNTA(항목!$D$4:$D$18),1)
Name 종목명: 매매!$E$4:$E$1000
Name 주거비: OFFSET(항목!$F$4,0,0,COUNTA(항목!$F$4:$F$18),1)
Name 총비용: 매매!$V$4:$V$1000
Name 총손익: 매매!$X$4:$X$1000
Name 통신비: OFFSET(항목!$O$4,0,0,COUNTA(항목!$O$4:$O$18),1)
Name 평가금액: 매매!$O$4:$O$1000
Name 평가손익: 매매!$P$4:$P$1000
Name 항목: OFFSET(항목!$C$3,0,0,1,COUNTA(항목!$C$3:$Q$3))

Sheet 사용안내
B1: 탭다 엑셀 양식 사용 안내
B3: 탭다 블로그 내 엑셀 양식은
B4: 사용 범위를 준수할 경우 모두 무료입니다.
B5: 금지 사항 적발 시 관련법에 의거 제재 및 법적 처벌을 받을 수 있습니다.
B7: O | G7: X
B8: 개인적 비상업적 용도의 사용 | G8: 디자인 무단 도용 및 판매 금지
B9: 온라인 및 오프라인 이용 가능 | G9: 재배포(개인적, 비상업적 용도라도) 금지
B10: 회사원 개인의 회사 내부 보고, 제출, 공유용 | G10: 외부 유출, 대외적 게시 금지
B11: 비영리 단체에서의 사용 | G11: 영리 목적의 강의에 사용 금지
G12: 기타 이에 준하는 모든 상업적 유사 행위 금지
B14: 탭다의 최신 소식을 가장 빨리 받는 방법!
B15: 카카오톡 친구 검색에서 '탭다'를 찾아 친구 추가하기!
B16: 탭다 블로그 북마크 또는 즐겨찾기 http://tabda.tistory.com
B18: 탭다 엑셀 양식이 마음에 드셨나요?
B19: 지금 블로그, SNS에 탭다를 홍보해주세요.
B20: #탭다, #무료엑셀양식, #고퀄리티, #개이득
B21: 여러분들의 우쭈쭈는 저에게 큰 힘이 됩니다.
B23: 탭다 엑셀 양식이 유용하셨나요?
B24: 앞으로도 고퀄리티 엑셀 양식이 꾸준히
B25: 만들어질 수 있도록 탭다를 후원해주세요.
B26: 여러분들의 피드백에 더 나은 컨텐츠 제작으로 보답하겠습니다.
B28: 네이버 페이 포인트 선물하기 : mkjang0202(네이버 앱→메뉴→네이버 페이→포인트 선물)
... B30: 문의 : 카카오톡 1:1 오픈채팅에서 '탭다' 검색
C31: 오픈채팅 입장 링크 및 QR코드 → | G31: https://open.kakao.com/o/s3L8L5Tb
B34: ※ 사용안내 시트를 제외하고는 시트보호 암호가 걸려있지 않습니다. 필요하신 경우 사용안내 시트를 삭제하세요.
B35: ※ PC 자체에서 매크로가 포함된 파일을 자동으로 차단하기도 합니다. 보안 관련은 질문주셔도 잘 모릅니다ㅜ 경고문구 키워드로 검색해보시길 추천드립니다.

Sheet 메인
B1: ="▶ "&$R$3&"년 가계부" -> ▶ 2025년 가계부
D3: =$R$3&"년 재무목표" -> 2025년 재무목표 | J3: =$R$3&"년 재무일정" -> 2025년 재무일정 | R3: 2025
B4: ▷ 항목설정 | D4: 매월 저축 및 투자 250만원 이상 | J4: 매년 1월 신용카드 연회비 지출
B5: ▷ 수입 | D5: 추가 종자돈 3천만원 모으기 | J5: 1월 7월 부가세, 4월, 10월 예정고지
B6: └ 연간 항목별 수입
B7: ▷ 지출 | Q7: 월목표저축액 | R7: 2500000
B8: └ 연간 카드별 지출 | Q8: 월목표저축률 | R8: 0.6
B9: └ 연간 항목별 지출
B10: └ 연간 세부항목별 지출 | D10: 월별 리포트
B11: ▷ 예산 | E11: 1 | F11: 2 | G11: 3 | H11: 4 | I11: 5 | J11: 6 | K11: 7 | L11: 8 | M11: 9 | N11: 10 | O11: 11 | P11: 12 | Q11: 계 | R11: 평균
B12: ▷ 결산 | D12: 이월 | E12: =SUMIF('1월'!$D$33:$D$145,"이월",'1월'!$H$33:$H$145) -> 0 | F12: =SUMIF('2월'!$D$33:$D$145,"이월",'2월'!$H$33:$H$145) -> 0 | G12: =SUMIF('3월'!$D$33:$D$145,"이월",'3월'!$H$33:$H$145) -> 0 | H12: =SUMIF('4월'!$D$34:$D$145,"이월",'4월'!$H$34:$H$145) -> 0 | I12: =SUMIF('5월'!$D$33:$D$145,"이월",'5월'!$H$33:$H$145) -> 0 | J12: =SUMIF('6월'!$D$33:$D$145,"이월",'6월'!$H$33:$H$145) -> 0 | K12: =SUMIF('7월'!$D$33:$D$145,"이월",'7월'!$H$33:$H$145) -> 0 | L12: =SUMIF('8월'!$D$33:$D$145,"이월",'8월'!$H$33:$H$145) -> 0 | M12: =SUMIF('9월'!$D$33:$D$145,"이월",'9월'!$H$33:$H$145) -> 0 | N12: =SUMIF('10월'!$D$33:$D$145,"이월",'10월'!$H$33:$H$145) -> 0 | O12: =SUMIF('11월'!$D$33:$D$145,"이월",'11월'!$H$33:$H$145) -> 0 | P12: =SUMIF('12월'!$D$33:$D$145,"이월",'12월'!$H$33:$H$145) -> 0 | Q12: =SUM(E12:P12) -> 0 | R12: =SUM(E12:P12)/COUNTIF(E12:P12,"<>0") -> #DIV/0!
B13: ▷ 자산현황 | D13: 순수입 | E13: =연간_항목별수입!C20 -> 3515000 | F13: =연간_항목별수입!D20 -> 0 | G13: =연간_항목별수입!E20 -> 0 | H13: =연간_항목별수입!F20 -> 0 | I13: =연간_항목별수입!G20 -> 0 | J13: =연간_항목별수입!H20 -> 0 | K13: =연간_항목별수입!I20 -> 0 | L13: =연간_항목별수입!J20 -> 0 | ... P13: =연간_항목별수입!N20 -> 0 | Q13: =SUM(E13:P13) -> 3515000 | R13: =SUM(E13:P13)/COUNTIF(E13:P13,"<>0") -> 3515000
D14: 총지출 | E14: =연간_항목별지출!C19 -> 3295100 | F14: =연간_항목별지출!D19 -> 0 | G14: =연간_항목별지출!E19 -> 0 | H14: =연간_항목별지출!F19 -> 0 | I14: =연간_항목별지출!G19 -> 0 | J14: =연간_항목별지출!H19 -> 0 | K14: =연간_항목별지출!I19 -> 0 | L14: =연간_항목별지출!J19 -> 0 | ... P14: =연간_항목별지출!N19 -> 0 | Q14: =SUM(E14:P14) -> 3295100 | R14: =SUM(E14:P14)/COUNTIF(E14:P14,"<>0") -> 3295100
D15: 저축성지출 | E15: =연간_항목별지출!C4 -> 2350000 | F15: =연간_항목별지출!D4 -> 0 | G15: =연간_항목별지출!E4 -> 0 | H15: =연간_항목별지출!F4 -> 0 | I15: =연간_항목별지출!G4 -> 0 | J15: =연간_항목별지출!H4 -> 0 | K15: =연간_항목별지출!I4 -> 0 | L15: =연간_항목별지출!J4 -> 0 | ... P15: =연간_항목별지출!N4 -> 0 | Q15: =SUM(E15:P15) -> 2350000 | R15: =SUM(E15:P15)/COUNTIF(E15:P15,"<>0") -> 2350000
D16: 소비성지출 | E16: =연간_항목별지출!C5 -> 945100 | F16: =연간_항목별지출!D5 -> 0 | G16: =연간_항목별지출!E5 -> 0 | H16: =연간_항목별지출!F5 -> 0 | I16: =연간_항목별지출!G5 -> 0 | J16: =연간_항목별지출!H5 -> 0 | K16: =연간_항목별지출!I5 -> 0 | L16: =연간_항목별지출!J5 -> 0 | ... P16: =연간_항목별지출!N5 -> 0 | Q16: =SUM(E16:P16) -> 945100 | R16: =SUM(E16:P16)/COUNTIF(E16:P16,"<>0") -> 945100
D17: 잔액 | E17: =E12+E13-E14 -> 219900 | F17: =F12+F13-F14 -> 0 | G17: =G12+G13-G14 -> 0 | H17: =H12+H13-H14 -> 0 | I17: =I12+I13-I14 -> 0 | J17: =J12+J13-J14 -> 0 | K17: =K12+K13-K14 -> 0 | L17: =L12+L13-L14 -> 0 | ... P17: =P12+P13-P14 -> 0 | Q17: =SUM(E17:P17) -> 219900 | R17: =SUM(E17:P17)/COUNTIF(E17:P17,"<>0") -> 219900
D18: 이월금 제외 | E18: =E17-F12 -> 219900 | F18: =F17-G12 -> 0 | G18: =G17-H12 -> 0 | H18: =H17-I12 -> 0 | I18: =I17-J12 -> 0 | J18: =J17-K12 -> 0 | K18: =K17-L12 -> 0 | L18: =L17-M12 -> 0 | ... O18: =O17-P12 -> 0 | P18: 0 | Q18: =SUM(E18:P18) -> 219900
D19: 저축비율 | E19: =IF(E14=0,"",E15/E14) -> 0.71318018 | F19: =IF(F14=0,"",F15/F14) | G19: =IF(G14=0,"",G15/G14) | H19: =IF(H14=0,"",H15/H14) | I19: =IF(I14=0,"",I15/I14) | J19: =IF(J14=0,"",J15/J14) | K19: =IF(K14=0,"",K15/K14) | L19: =IF(L14=0,"",L15/L14) | ... Q19: =IF(Q14=0,"",Q15/Q14) -> 0.71318018
D20: 소비비율 | E20: =IF(E14=0,"",E16/E14) -> 0.28681982 | F20: =IF(F14=0,"",F16/F14) | G20: =IF(G14=0,"",G16/G14) | H20: =IF(H14=0,"",H16/H14) | I20: =IF(I14=0,"",I16/I14) | J20: =IF(J14=0,"",J16/J14) | K20: =IF(K14=0,"",K16/K14) | L20: =IF(L14=0,"",L16/L14) | ... Q20: =IF(Q14=0,"",Q16/Q14) -> 0.28681982
D21: 계 | E21: =IF(E19="","",SUM(E19:E20)) -> 1 | F21: =IF(F19="","",SUM(F19:F20)) | G21: =IF(G19="","",SUM(G19:G20)) | H21: =IF(H19="","",SUM(H19:H20)) | I21: =IF(I19="","",SUM(I19:I20)) | J21: =IF(J19="","",SUM(J19:J20)) | K21: =IF(K19="","",SUM(K19:K20)) | L21: =IF(L19="","",SUM(L19:L20)) | ... Q21: =IF(Q19="","",SUM(Q19:Q20)) -> 1
D23: 월별 순수입 및 총지출
D40: 월간 항목별 지출 차트
D41: 1월
D42: 2월
D43: 3월
D44: 4월
D45: 5월
D46: 6월
D47: 7월
D48: 8월
D49: 9월
D50: 10월
... D195: 12월

Sheet 항목
B1: ◀ 항목
B3: 지출구분 | C3: 수입 | D3: 저축성지출 | E3: 식비 | F3: 주거비 | G3: 생활용품비 | H3: 반려동물비 | I3: 의류미용비 | J3: 교육비 | K3: 문화생활비 | L3: 의료비 | M3: 유류교통비 | N3: 통신비 | O3: 경조사회비 | P3: 용돈 | Q3: 추가항목
B4: 계좌이체 | C4: 이월 | D4: 예/적금 | E4: 시장/마트 | F4: 재산세 | G4: 가구/가전 | H4: 사료/간식 | I4: 의류 | J4: 학교 | K4: 영화/관람 | L4: 병원 | M4: 자동차보험 | N4: 핸드폰 | O4: 축의금 | P4: 부모님 용돈 | Q4: 필요한 것
B5: 현금 | C5: 급여 | D5: 주택청약 | E5: 외식/배달 | F5: 월세 | G5: 주방/욕실 | H5: 용품/장난감 | I5: 패션잡화 | J5: 학원 | K5: 여가 | L5: 의약품 | M5: 자동차할부 | N5: 인터넷 | O5: 조의금 | P5: 첫째 용돈 | Q5: 추가하세요
B6: 00신용 | C6: 수당 | D6: 퇴직연금 | E6: 간식 | F6: 주담대 이자 | G6: 오피스/문구 | H6: 병원/접종 | I6: 세탁비 | J6: 도서 | K6: 여행 | L6: 영양제 | M6: 자동차세 | N6: IPTV | O6: 기부금 | P6: 기타 용돈
B7: 00체크 | C7: 상여 | D7: 비상금 | E7: 술/회식 | F7: 주담대 원금 | G7: 멤버십 | H7: 미용 | I7: 기타 의류 | J7: 강의 | K7: OTT | L7: 보험료 | M7: 유류비/충전비 | N7: 우편/택배 | O7: 모임회비
C8: 투자수익 | D8: 투자 | E8: 커피숍 | F8: 관리비 | G8: 기타 생활용품 | H8: 기타 반려동물 | I8: 화장품 | J8: 기타 교육 | K8: 기타 문화생활 | L8: 기타 의료비 | M8: 수리비 | N8: 기타 통신 | O8: 선물
C9: 이자 | D9: 기타 저축 | E9: 기타 식비 | F9: 수도세 | G9: 기타 잡지출 | I9: 미용실 | M9: 톨비/하이패스 | O9: 기타 경조사
C10: 부수익 | F10: 전기세 | I10: 기타 미용 | M10: 주차비
C11: 처분소득 | F11: 가스비 | M11: 버스/지하철
C12: 기타 수입 | F12: 기타 주거비 | M12: 택시
M13: 기차
M14: 항공
M15: 기타 교통

Sheet 1월
A1: =메인!$R$3 -> 2025 | B1: ◀ 01월 ▶
A2: =메인!$E$11 -> 1
B5: 총 수입 | C5: =SUM($C$32+$C$56) -> 3515000 | J5: 이번달 목표 | P5: 필수지출
B6: 총 지출 | C6: =SUM($K$32+$L$56) -> 3295100 | J6: 무지출 20일 이상 달성하기! | P6: 00신용 결제 12일 - 잔액 확인
B7: 차액 | C7: =$C$5-$C$6 -> 219900 | J7: 변동지출 10만원 이하로 쓰기! | P7: 친구 축의금 내야함!
G8: 무지출 성공 | H8: =COUNTIF(B10:H28,"무지출") -> 28
B9: 변동지출 달력 | J9: 소비성 지출 분석
B10: 일 | C10: 월 | D10: 화 | E10: 수 | F10: 목 | G10: 금 | H10: 토 | J10: 항목 | K10: 지출계 | L10: 예산 | M10: 예산대비 | N10: 전월지출 | O10: 전월대비
B11: =DATE($A$1,$A$2,1)-WEEKDAY(DATE($A$1,$A$2,1))+1 -> 45655 | C11: =B11+1 -> 45656 | D11: =C11+1 -> 45657 | E11: =D11+1 -> 45658 | F11: =E11+1 -> 45659 | G11: =F11+1 -> 45660 | H11: =G11+1 -> 45661 | J11: =항목!J$3 -> 교육비 | K11: =SUMIF($L$58:$L$300,J11,$R$58:$R$300) -> 500000 | L11: =VLOOKUP(J11,예산!$B$41:$N$53,2,FALSE) -> 500000 | M11: =L11-K11 -> 0
B12: =IF(MONTH(B11)<>$A$2,"",IF(AND(SUMIF($J$81:$J$145,B11,$R$81:$R$145)=0,B11<TODAY()),"무지출",SUMIF($J$81:$J$145,B11,$R$81:$R$145))) | C12: =IF(MONTH(C11)<>$A$2,"",IF(AND(SUMIF($J$81:$J$145,C11,$R$81:$R$145)=0,C11<TODAY()),"무지출",SUMIF($J$81:$J$145,C11,$R$81:$R$145))) | D12: =IF(MONTH(D11)<>$A$2,"",IF(AND(SUMIF($J$81:$J$145,D11,$R$81:$R$145)=0,D11<TODAY()),"무지출",SUMIF($J$81:$J$145,D11,$R$81:$R$145))) | E12: =IF(MONTH(E11)<>$A$2,"",IF(AND(SUMIF($J$81:$J$145,E11,$R$81:$R$145)=0,E11<TODAY()),"무지출",SUMIF($J$81:$J$145,E11,$R$81:$R$145))) -> 10000 | F12: =IF(MONTH(F11)<>$A$2,"",IF(AND(SUMIF($J$81:$J$145,F11,$R$81:$R$145)=0,F11<TODAY()),"무지출",SUMIF($J$81:$J$145,F11,$R$81:$R$145))) -> 무지출 | G12: =IF(MONTH(G11)<>$A$2,"",IF(AND(SUMIF($J$81:$J$145,G11,$R$81:$R$145)=0,G11<TODAY()),"무지출",SUMIF($J$81:$J$145,G11,$R$81:$R$145))) -> 무지출 | H12: =IF(MONTH(H11)<>$A$2,"",IF(AND(SUMIF($J$81:$J$145,H11,$R$81:$R$145)=0,H11<TODAY()),"무지출",SUMIF($J$81:$J$145,H11,$R$81:$R$145))) -> 무지출 | J12: =항목!F$3 -> 주거비 | K12: =SUMIF($L$58:$L$300,J12,$R$58:$R$300) -> 200000 | L12: =VLOOKUP(J12,예산!$B$41:$N$53,2,FALSE) -> 200000 | M12: =L12-K12 -> 0
J13: =항목!O$3 -> 경조사회비 | K13: =SUMIF($L$58:$L$300,J13,$R$58:$R$300) -> 150000 | L13: =VLOOKUP(J13,예산!$B$41:$N$53,2,FALSE) -> 50000 | M13: =L13-K13 -> -100000
B14: =B11+7 -> 45662 | C14: =C11+7 -> 45663 | D14: =D11+7 -> 45664 | E14: =E11+7 -> 45665 | F14: =F11+7 -> 45666 | G14: =G11+7 -> 45667 | H14: =H11+7 -> 45668 | J14: =항목!E$3 -> 식비 | K14: =SUMIF($L$58:$L$300,J14,$R$58:$R$300) -> 53100 | L14: =VLOOKUP(J14,예산!$B$41:$N$53,2,FALSE) -> 50000 | M14: =L14-K14 -> -3100
B15: =IF(MONTH(B14)<>$A$2,"",IF(AND(SUMIF($J$81:$J$145,B14,$R$81:$R$145)=0,B14<TODAY()),"무지출",SUMIF($J$81:$J$145,B14,$R$81:$R$145))) -> 3700 | C15: =IF(MONTH(C14)<>$A$2,"",IF(AND(SUMIF($J$81:$J$145,C14,$R$81:$R$145)=0,C14<TODAY()),"무지출",SUMIF($J$81:$J$145,C14,$R$81:$R$145))) -> 무지출 | D15: =IF(MONTH(D14)<>$A$2,"",IF(AND(SUMIF($J$81:$J$145,D14,$R$81:$R$145)=0,D14<TODAY()),"무지출",SUMIF($J$81:$J$145,D14,$R$81:$R$145))) -> 무지출 | E15: =IF(MONTH(E14)<>$A$2,"",IF(AND(SUMIF($J$81:$J$145,E14,$R$81:$R$145)=0,E14<TODAY()),"무지출",SUMIF($J$81:$J$145,E14,$R$81:$R$145))) -> 무지출 | F15: =IF(MONTH(F14)<>$A$2,"",IF(AND(SUMIF($J$81:$J$145,F14,$R$81:$R$145)=0,F14<TODAY()),"무지출",SUMIF($J$81:$J$145,F14,$R$81:$R$145))) -> 무지출 | G15: =IF(MONTH(G14)<>$A$2,"",IF(AND(SUMIF($J$81:$J$145,G14,$R$81:$R$145)=0,G14<TODAY()),"무지출",SUMIF($J$81:$J$145,G14,$R$81:$R$145))) -> 무지출 | H15: =IF(MONTH(H14)<>$A$2,"",IF(AND(SUMIF($J$81:$J$145,H14,$R$81:$R$145)=0,H14<TODAY()),"무지출",SUMIF($J$81:$J$145,H14,$R$81:$R$145))) -> 무지출 | J15: =항목!N$3 -> 통신비 | K15: =SUMIF($L$58:$L$300,J15,$R$58:$R$300) -> 20000 | L15: =VLOOKUP(J15,예산!$B$41:$N$53,2,FALSE) -> 50000 | M15: =L15-K15 -> 30000
J16: =항목!L$3 -> 의료비 | K16: =SUMIF($L$58:$L$300,J16,$R$58:$R$300) -> 12000 | L16: =VLOOKUP(J16,예산!$B$41:$N$53,2,FALSE) -> 12000 | M16: =L16-K16 -> 0
B17: =B11+14 -> 45669 | C17: =C11+14 -> 45670 | D17: =D11+14 -> 45671 | E17: =E11+14 -> 45672 | F17: =F11+14 -> 45673 | G17: =G11+14 -> 45674 | H17: =H11+14 -> 45675 | J17: =항목!K$3 -> 문화생활비 | K17: =SUMIF($L$58:$L$300,J17,$R$58:$R$300) -> 10000 | L17: =VLOOKUP(J17,예산!$B$41:$N$53,2,FALSE) -> 0 | M17: =L17-K17 -> -10000
B18: =IF(MONTH(B17)<>$A$2,"",IF(AND(SUMIF($J$81:$J$145,B17,$R$81:$R$145)=0,B17<TODAY()),"무지출",SUMIF($J$81:$J$145,B17,$R$81:$R$145))) -> 무지출 | C18: =IF(MONTH(C17)<>$A$2,"",IF(AND(SUMIF($J$81:$J$145,C17,$R$81:$R$145)=0,C17<TODAY()),"무지출",SUMIF($J$81:$J$145,C17,$R$81:$R$145))) -> 무지출 | D18: =IF(MONTH(D17)<>$A$2,"",IF(AND(SUMIF($J$81:$J$145,D17,$R$81:$R$145)=0,D17<TODAY()),"무지출",SUMIF($J$81:$J$145,D17,$R$81:$R$145))) -> 무지출 | E18: =IF(MONTH(E17)<>$A$2,"",IF(AND(SUMIF($J$81:$J$145,E17,$R$81:$R$145)=0,E17<TODAY()),"무지출",SUMIF($J$81:$J$145,E17,$R$81:$R$145))) -> 무지출 | F18: =IF(MONTH(F17)<>$A$2,"",IF(AND(SUMIF($J$81:$J$145,F17,$R$81:$R$145)=0,F17<TODAY()),"무지출",SUMIF($J$81:$J$145,F17,$R$81:$R$145))) -> 149400 | G18: =IF(MONTH(G17)<>$A$2,"",IF(AND(SUMIF($J$81:$J$145,G17,$R$81:$R$145)=0,G17<TODAY()),"무지출",SUMIF($J$81:$J$145,G17,$R$81:$R$145))) -> 무지출 | H18: =IF(MONTH(H17)<>$A$2,"",IF(AND(SUMIF($J$81:$J$145,H17,$R$81:$R$145)=0,H17<TODAY()),"무지출",SUMIF($J$81:$J$145,H17,$R$81:$R$145))) -> 무지출 | J18: =항목!G$3 -> 생활용품비 | K18: =SUMIF($L$58:$L$300,J18,$R$58:$R$300) -> 0 | L18: =VLOOKUP(J18,예산!$B$41:$N$53,2,FALSE) -> 30000 | M18: =L18-K18 -> 30000
J19: =항목!P$3 -> 용돈 | K19: =SUMIF($L$58:$L$300,J19,$R$58:$R$300) -> 0 | L19: =VLOOKUP(J19,예산!$B$41:$N$53,2,FALSE) -> 50000 | M19: =L19-K19 -> 50000
B20: =B11+21 -> 45676 | C20: =C11+21 -> 45677 | D20: =D11+21 -> 45678 | E20: =E11+21 -> 45679 | F20: =F11+21 -> 45680 | G20: =G11+21 -> 45681 | H20: =H11+21 -> 45682 | J20: =항목!M$3 -> 유류교통비 | K20: =SUMIF($L$58:$L$300,J20,$R$58:$R$300) -> 0 | L20: =VLOOKUP(J20,예산!$B$41:$N$53,2,FALSE) -> 100000 | M20: =L20-K20 -> 100000
B21: =IF(MONTH(B20)<>$A$2,"",IF(AND(SUMIF($J$81:$J$145,B20,$R$81:$R$145)=0,B20<TODAY()),"무지출",SUMIF($J$81:$J$145,B20,$R$81:$R$145))) -> 무지출 | C21: =IF(MONTH(C20)<>$A$2,"",IF(AND(SUMIF($J$81:$J$145,C20,$R$81:$R$145)=0,C20<TODAY()),"무지출",SUMIF($J$81:$J$145,C20,$R$81:$R$145))) -> 무지출 | D21: =IF(MONTH(D20)<>$A$2,"",IF(AND(SUMIF($J$81:$J$145,D20,$R$81:$R$145)=0,D20<TODAY()),"무지출",SUMIF($J$81:$J$145,D20,$R$81:$R$145))) -> 무지출 | E21: =IF(MONTH(E20)<>$A$2,"",IF(AND(SUMIF($J$81:$J$145,E20,$R$81:$R$145)=0,E20<TODAY()),"무지출",SUMIF($J$81:$J$145,E20,$R$81:$R$145))) -> 무지출 | F21: =IF(MONTH(F20)<>$A$2,"",IF(AND(SUMIF($J$81:$J$145,F20,$R$81:$R$145)=0,F20<TODAY()),"무지출",SUMIF($J$81:$J$145,F20,$R$81:$R$145))) -> 무지출 | G21: =IF(MONTH(G20)<>$A$2,"",IF(AND(SUMIF($J$81:$J$145,G20,$R$81:$R$145)=0,G20<TODAY()),"무지출",SUMIF($J$81:$J$145,G20,$R$81:$R$145))) -> 무지출 | H21: =IF(MONTH(H20)<>$A$2,"",IF(AND(SUMIF($J$81:$J$145,H20,$R$81:$R$145)=0,H20<TODAY()),"무지출",SUMIF($J$81:$J$145,H20,$R$81:$R$145))) -> 무지출 | J21: =항목!H$3 -> 반려동물비 | K21: =SUMIF($L$58:$L$300,J21,$R$58:$R$300) -> 0 | L21: =VLOOKUP(J21,예산!$B$41:$N$53,2,FALSE) -> 10000 | M21: =L21-K21 -> 10000
J22: =항목!I$3 -> 의류미용비 | K22: =SUMIF($L$58:$L$300,J22,$R$58:$R$300) -> 0 | L22: =VLOOKUP(J22,예산!$B$41:$N$53,2,FALSE) -> 10000 | M22: =L22-K22 -> 10000
B23: =B11+28 -> 45683 | C23: =C11+28 -> 45684 | D23: =D11+28 -> 45685 | E23: =E11+28 -> 45686 | F23: =F11+28 -> 45687 | G23: =G11+28 -> 45688 | H23: =H11+28 -> 45689 | J23: =항목!Q$3 -> 추가항목 | K23: =SUMIF($L$58:$L$300,J23,$R$58:$R$300) -> 0 | L23: =VLOOKUP(J23,예산!$B$41:$N$53,2,FALSE) -> 0 | M23: =L23-K23 -> 0
B24: =IF(MONTH(B23)<>$A$2,"",IF(AND(SUMIF($J$81:$J$145,B23,$R$81:$R$145)=0,B23<TODAY()),"무지출",SUMIF($J$81:$J$145,B23,$R$81:$R$145))) -> 무지출 | C24: =IF(MONTH(C23)<>$A$2,"",IF(AND(SUMIF($J$81:$J$145,C23,$R$81:$R$145)=0,C23<TODAY()),"무지출",SUMIF($J$81:$J$145,C23,$R$81:$R$145))) -> 무지출 | D24: =IF(MONTH(D23)<>$A$2,"",IF(AND(SUMIF($J$81:$J$145,D23,$R$81:$R$145)=0,D23<TODAY()),"무지출",SUMIF($J$81:$J$145,D23,$R$81:$R$145))) -> 무지출 | E24: =IF(MONTH(E23)<>$A$2,"",IF(AND(SUMIF($J$81:$J$145,E23,$R$81:$R$145)=0,E23<TODAY()),"무지출",SUMIF($J$81:$J$145,E23,$R$81:$R$145))) -> 무지출 | F24: =IF(MONTH(F23)<>$A$2,"",IF(AND(SUMIF($J$81:$J$145,F23,$R$81:$R$145)=0,F23<TODAY()),"무지출",SUMIF($J$81:$J$145,F23,$R$81:$R$145))) -> 무지출 | G24: =IF(MONTH(G23)<>$A$2,"",IF(AND(SUMIF($J$81:$J$145,G23,$R$81:$R$145)=0,G23<TODAY()),"무지출",SUMIF($J$81:$J$145,G23,$R$81:$R$145))) -> 무지출 | H24: =IF(MONTH(H23)<>$A$2,"",IF(AND(SUMIF($J$81:$J$145,H23,$R$81:$R$145)=0,H23<TODAY()),"무지출",SUMIF($J$81:$J$145,H23,$R$81:$R$145)))
J25: MEMO
B26: =B11+35 -> 45690 | C26: =C11+35 -> 45691 | D26: =D11+35 -> 45692 | E26: =E11+35 -> 45693 | F26: =F11+35 -> 45694 | G26: =G11+35 -> 45695 | H26: =H11+35 -> 45696 | J26: 식비를 예산보다 조금 많이 썼다. 다음달에는 냉장고 파먹기를 해서 한끼만큼 식비를 줄여야겠다.
B27: =IF(MONTH(B26)<>$A$2,"",IF(AND(SUMIF($J$81:$J$145,B26,$R$81:$R$145)=0,B26<TODAY()),"무지출",SUMIF($J$81:$J$145,B26,$R$81:$R$145))) | C27: =IF(MONTH(C26)<>$A$2,"",IF(AND(SUMIF($J$81:$J$145,C26,$R$81:$R$145)=0,C26<TODAY()),"무지출",SUMIF($J$81:$J$145,C26,$R$81:$R$145))) | D27: =IF(MONTH(D26)<>$A$2,"",IF(AND(SUMIF($J$81:$J$145,D26,$R$81:$R$145)=0,D26<TODAY()),"무지출",SUMIF($J$81:$J$145,D26,$R$81:$R$145))) | E27: =IF(MONTH(E26)<>$A$2,"",IF(AND(SUMIF($J$81:$J$145,E26,$R$81:$R$145)=0,E26<TODAY()),"무지출",SUMIF($J$81:$J$145,E26,$R$81:$R$145))) | F27: =IF(MONTH(F26)<>$A$2,"",IF(AND(SUMIF($J$81:$J$145,F26,$R$81:$R$145)=0,F26<TODAY()),"무지출",SUMIF($J$81:$J$145,F26,$R$81:$R$145))) | G27: =IF(MONTH(G26)<>$A$2,"",IF(AND(SUMIF($J$81:$J$145,G26,$R$81:$R$145)=0,G26<TODAY()),"무지출",SUMIF($J$81:$J$145,G26,$R$81:$R$145))) | H27: =IF(MONTH(H26)<>$A$2,"",IF(AND(SUMIF($J$81:$J$145,H26,$R$81:$R$145)=0,H26<TODAY()),"무지출",SUMIF($J$81:$J$145,H26,$R$81:$R$145))) | J27: 지난달 예산에서는 생각못한 축의금 지출이 있었지만 비상금에서 쓰지 않고 다른 지출을 줄였다! 칭찬!
B30: 수입 | J30: 지출
B32: 고정수입 | C32: =SUM($H$34:$H$53) -> 3500000 | J32: 저축성지출 | K32: =SUM($R$34:$R$53) -> 2350000
B33: 날짜 | C33: 대분류 | D33: 소분류 | E33: 내용 | H33: 금액 | J33: 날짜 | K33: 구분 | L33: 대분류 | M33: 소분류 | N33: 지출 내용 | P33: 결제금액 | Q33: 할인 | R33: 실지출 | S33: 비고
B34: 45658 | C34: 수입 | D34: 급여 | E34: 월급 | H34: 3500000 | J34: 45658 | K34: 계좌이체 | L34: 저축성지출 | M34: 예/적금 | N34: 적금 | P34: 500000 | Q34: 0 | R34: =IF(P34="","",P34-Q34) -> 500000 | S34: 매월 5일 출금
J35: 45658 | K35: 계좌이체 | L35: 저축성지출 | M35: 퇴직연금 | N35: 개인 연금 | P35: 250000 | Q35: 0 | R35: =IF(P35="","",P35-Q35) -> 250000
J36: 45658 | K36: 계좌이체 | L36: 저축성지출 | M36: 주택청약 | N36: 주택청약 | P36: 100000 | Q36: 0 | R36: =IF(P36="","",P36-Q36) -> 100000
J37: 45658 | K37: 계좌이체 | L37: 저축성지출 | M37: 비상금 | N37: 비상금 | P37: 1500000 | Q37: 0 | R37: =IF(P37="","",P37-Q37) -> 1500000
R38: =IF(P38="","",P38-Q38)
R39: =IF(P39="","",P39-Q39)
R40: =IF(P40="","",P40-Q40)
R41: =IF(P41="","",P41-Q41)
R42: =IF(P42="","",P42-Q42)
R43: =IF(P43="","",P43-Q43)
R44: =IF(P44="","",P44-Q44)
R45: =IF(P45="","",P45-Q45)
...

Sheet 2월
A1: =메인!$R$3 -> 2025 | B1: ◀ 02월 ▶
A2: =메인!$F$11 -> 2
B5: 총 수입 | C5: =SUM($C$32+$C$56) -> 0 | J5: ='1월'!J5 -> 이번달 목표 | P5: 필수지출
B6: 총 지출 | C6: =SUM($K$32+$L$56) -> 0
B7: 차액 | C7: =$C$5-$C$6 -> 0
G8: 무지출 성공 | H8: =COUNTIF(B10:H28,"무지출") -> 28
B9: 변동지출 달력 | J9: 소비성 지출 분석
B10: 일 | C10: 월 | D10: 화 | E10: 수 | F10: 목 | G10: 금 | H10: 토 | J10: 항목 | K10: 지출계 | L10: 예산 | M10: 예산대비 | N10: 전월지출 | O10: 전월대비
B11: =DATE($A$1,$A$2,1)-WEEKDAY(DATE($A$1,$A$2,1))+1 -> 45683 | C11: =B11+1 -> 45684 | D11: =C11+1 -> 45685 | E11: =D11+1 -> 45686 | F11: =E11+1 -> 45687 | G11: =F11+1 -> 45688 | H11: =G11+1 -> 45689 | J11: =항목!N$3 -> 통신비 | K11: =SUMIF($L$58:$L$300,J11,$R$58:$R$300) -> 0 | L11: =VLOOKUP(J11,예산!$B$41:$N$53,3,FALSE) -> 0 | M11: =L11-K11 -> 0 | N11: =VLOOKUP(J11,'1월'!$J$10:$K$23,2,FALSE) -> 20000 | O11: =K11-N11 -> -20000
B12: =IF(MONTH(B11)<>$A$2,"",IF(AND(SUMIF($J$81:$J$145,B11,$R$81:$R$145)=0,B11<TODAY()),"무지출",SUMIF($J$81:$J$145,B11,$R$81:$R$145))) | C12: =IF(MONTH(C11)<>$A$2,"",IF(AND(SUMIF($J$81:$J$145,C11,$R$81:$R$145)=0,C11<TODAY()),"무지출",SUMIF($J$81:$J$145,C11,$R$81:$R$145))) | D12: =IF(MONTH(D11)<>$A$2,"",IF(AND(SUMIF($J$81:$J$145,D11,$R$81:$R$145)=0,D11<TODAY()),"무지출",SUMIF($J$81:$J$145,D11,$R$81:$R$145))) | E12: =IF(MONTH(E11)<>$A$2,"",IF(AND(SUMIF($J$81:$J$145,E11,$R$81:$R$145)=0,E11<TODAY()),"무지출",SUMIF($J$81:$J$145,E11,$R$81:$R$145))) | F12: =IF(MONTH(F11)<>$A$2,"",IF(AND(SUMIF($J$81:$J$145,F11,$R$81:$R$145)=0,F11<TODAY()),"무지출",SUMIF($J$81:$J$145,F11,$R$81:$R$145))) | G12: =IF(MONTH(G11)<>$A$2,"",IF(AND(SUMIF($J$81:$J$145,G11,$R$81:$R$145)=0,G11<TODAY()),"무지출",SUMIF($J$81:$J$145,G11,$R$81:$R$145))) | H12: =IF(MONTH(H11)<>$A$2,"",IF(AND(SUMIF($J$81:$J$145,H11,$R$81:$R$145)=0,H11<TODAY()),"무지출",SUMIF($J$81:$J$145,H11,$R$81:$R$145))) -> 무지출 | J12: =항목!J$3 -> 교육비 | K12: =SUMIF($L$58:$L$300,J12,$R$58:$R$300) -> 0 | L12: =VLOOKUP(J12,예산!$B$41:$N$53,3,FALSE) -> 0 | M12: =L12-K12 -> 0 | N12: =VLOOKUP(J12,'1월'!$J$10:$K$23,2,FALSE) -> 500000 | O12: =K12-N12 -> -500000
J13: =항목!G$3 -> 생활용품비 | K13: =SUMIF($L$58:$L$300,J13,$R$58:$R$300) -> 0 | L13: =VLOOKUP(J13,예산!$B$41:$N$53,3,FALSE) -> 0 | M13: =L13-K13 -> 0 | N13: =VLOOKUP(J13,'1월'!$J$10:$K$23,2,FALSE) -> 0 | O13: =K13-N13 -> 0
B14: =B11+7 -> 45690 | C14: =C11+7 -> 45691 | D14: =D11+7 -> 45692 | E14: =E11+7 -> 45693 | F14: =F11+7 -> 45694 | G14: =G11+7 -> 45695 | H14: =H11+7 -> 45696 | J14: =항목!P$3 -> 용돈 | K14: =SUMIF($L$58:$L$300,J14,$R$58:$R$300) -> 0 | L14: =VLOOKUP(J14,예산!$B$41:$N$53,3,FALSE) -> 0 | M14: =L14-K14 -> 0 | N14: =VLOOKUP(J14,'1월'!$J$10:$K$23,2,FALSE) -> 0 | O14: =K14-N14 -> 0
B15: =IF(MONTH(B14)<>$A$2,"",IF(AND(SUMIF($J$81:$J$145,B14,$R$81:$R$145)=0,B14<TODAY()),"무지출",SUMIF($J$81:$J$145,B14,$R$81:$R$145))) -> 무지출 | C15: =IF(MONTH(C14)<>$A$2,"",IF(AND(SUMIF($J$81:$J$145,C14,$R$81:$R$145)=0,C14<TODAY()),"무지출",SUMIF($J$81:$J$145,C14,$R$81:$R$145))) -> 무지출 | D15: =IF(MONTH(D14)<>$A$2,"",IF(AND(SUMIF($J$81:$J$145,D14,$R$81:$R$145)=0,D14<TODAY()),"무지출",SUMIF($J$81:$J$145,D14,$R$81:$R$145))) -> 무지출 | E15: =IF(MONTH(E14)<>$A$2,"",IF(AND(SUMIF($J$81:$J$145,E14,$R$81:$R$145)=0,E14<TODAY()),"무지출",SUMIF($J$81:$J$145,E14,$R$81:$R$145))) -> 무지출 | F15: =IF(MONTH(F14)<>$A$2,"",IF(AND(SUMIF($J$81:$J$145,F14,$R$81:$R$145)=0,F14<TODAY()),"무지출",SUMIF($J$81:$J$145,F14,$R$81:$R$145))) -> 무지출 | G15: =IF(MONTH(G14)<>$A$2,"",IF(AND(SUMIF($J$81:$J$145,G14,$R$81:$R$145)=0,G14<TODAY()),"무지출",SUMIF($J$81:$J$145,G14,$R$81:$R$145))) -> 무지출 | H15: =IF(MONTH(H14)<>$A$2,"",IF(AND(SUMIF($J$81:$J$145,H14,$R$81:$R$145)=0,H14<TODAY()),"무지출",SUMIF($J$81:$J$145,H14,$R$81:$R$145))) -> 무지출 | J15: =항목!O$3 -> 경조사회비 | K15: =SUMIF($L$58:$L$300,J15,$R$58:$R$300) -> 0 | L15: =VLOOKUP(J15,예산!$B$41:$N$53,3,FALSE) -> 0 | M15: =L15-K15 -> 0 | N15: =VLOOKUP(J15,'1월'!$J$10:$K$23,2,FALSE) -> 150000 | O15: =K15-N15 -> -150000
J16: =항목!M$3 -> 유류교통비 | K16: =SUMIF($L$58:$L$300,J16,$R$58:$R$300) -> 0 | L16: =VLOOKUP(J16,예산!$B$41:$N$53,3,FALSE) -> 0 | M16: =L16-K16 -> 0 | N16: =VLOOKUP(J16,'1월'!$J$10:$K$23,2,FALSE) -> 0 | O16: =K16-N16 -> 0
B17: =B11+14 -> 45697 | C17: =C11+14 -> 45698 | D17: =D11+14 -> 45699 | E17: =E11+14 -> 45700 | F17: =F11+14 -> 45701 | G17: =G11+14 -> 45702 | H17: =H11+14 -> 45703 | J17: =항목!E$3 -> 식비 | K17: =SUMIF($L$58:$L$300,J17,$R$58:$R$300) -> 0 | L17: =VLOOKUP(J17,예산!$B$41:$N$53,3,FALSE) -> 0 | M17: =L17-K17 -> 0 | N17: =VLOOKUP(J17,'1월'!$J$10:$K$23,2,FALSE) -> 53100 | O17: =K17-N17 -> -53100
B18: =IF(MONTH(B17)<>$A$2,"",IF(AND(SUMIF($J$81:$J$145,B17,$R$81:$R$145)=0,B17<TODAY()),"무지출",SUMIF($J$81:$J$145,B17,$R$81:$R$145))) -> 무지출 | C18: =IF(MONTH(C17)<>$A$2,"",IF(AND(SUMIF($J$81:$J$145,C17,$R$81:$R$145)=0,C17<TODAY()),"무지출",SUMIF($J$81:$J$145,C17,$R$81:$R$145))) -> 무지출 | D18: =IF(MONTH(D17)<>$A$2,"",IF(AND(SUMIF($J$81:$J$145,D17,$R$81:$R$145)=0,D17<TODAY()),"무지출",SUMIF($J$81:$J$145,D17,$R$81:$R$145))) -> 무지출 | E18: =IF(MONTH(E17)<>$A$2,"",IF(AND(SUMIF($J$81:$J$145,E17,$R$81:$R$145)=0,E17<TODAY()),"무지출",SUMIF($J$81:$J$145,E17,$R$81:$R$145))) -> 무지출 | F18: =IF(MONTH(F17)<>$A$2,"",IF(AND(SUMIF($J$81:$J$145,F17,$R$81:$R$145)=0,F17<TODAY()),"무지출",SUMIF($J$81:$J$145,F17,$R$81:$R$145))) -> 무지출 | G18: =IF(MONTH(G17)<>$A$2,"",IF(AND(SUMIF($J$81:$J$145,G17,$R$81:$R$145)=0,G17<TODAY()),"무지출",SUMIF($J$81:$J$145,G17,$R$81:$R$145))) -> 무지출 | H18: =IF(MONTH(H17)<>$A$2,"",IF(AND(SUMIF($J$81:$J$145,H17,$R$81:$R$145)=0,H17<TODAY()),"무지출",SUMIF($J$81:$J$145,H17,$R$81:$R$145))) -> 무지출 | J18: =항목!F$3 -> 주거비 | K18: =SUMIF($L$58:$L$300,J18,$R$58:$R$300) -> 0 | L18: =VLOOKUP(J18,예산!$B$41:$N$53,3,FALSE) -> 0 | M18: =L18-K18 -> 0 | N18: =VLOOKUP(J18,'1월'!$J$10:$K$23,2,FALSE) -> 200000 | O18: =K18-N18 -> -200000
J19: =항목!H$3 -> 반려동물비 | K19: =SUMIF($L$58:$L$300,J19,$R$58:$R$300) -> 0 | L19: =VLOOKUP(J19,예산!$B$41:$N$53,3,FALSE) -> 0 | M19: =L19-K19 -> 0 | N19: =VLOOKUP(J19,'1월'!$J$10:$K$23,2,FALSE) -> 0 | O19: =K19-N19 -> 0
B20: =B11+21 -> 45704 | C20: =C11+21 -> 45705 | D20: =D11+21 -> 45706 | E20: =E11+21 -> 45707 | F20: =F11+21 -> 45708 | G20: =G11+21 -> 45709 | H20: =H11+21 -> 45710 | J20: =항목!I$3 -> 의류미용비 | K20: =SUMIF($L$58:$L$300,J20,$R$58:$R$300) -> 0 | L20: =VLOOKUP(J20,예산!$B$41:$N$53,3,FALSE) -> 0 | M20: =L20-K20 -> 0 | N20: =VLOOKUP(J20,'1월'!$J$10:$K$23,2,FALSE) -> 0 | O20: =K20-N20 -> 0
B21: =IF(MONTH(B20)<>$A$2,"",IF(AND(SUMIF($J$81:$J$145,B20,$R$81:$R$145)=0,B20<TODAY()),"무지출",SUMIF($J$81:$J$145,B20,$R$81:$R$145))) -> 무지출 | C21: =IF(MONTH(C20)<>$A$2,"",IF(AND(SUMIF($J$81:$J$145,C20,$R$81:$R$145)=0,C20<TODAY()),"무지출",SUMIF($J$81:$J$145,C20,$R$81:$R$145))) -> 무지출 | D21: =IF(MONTH(D20)<>$A$2,"",IF(AND(SUMIF($J$81:$J$145,D20,$R$81:$R$145)=0,D20<TODAY()),"무지출",SUMIF($J$81:$J$145,D20,$R$81:$R$145))) -> 무지출 | E21: =IF(MONTH(E20)<>$A$2,"",IF(AND(SUMIF($J$81:$J$145,E20,$R$81:$R$145)=0,E20<TODAY()),"무지출",SUMIF($J$81:$J$145,E20,$R$81:$R$145))) -> 무지출 | F21: =IF(MONTH(F20)<>$A$2,"",IF(AND(SUMIF($J$81:$J$145,F20,$R$81:$R$145)=0,F20<TODAY()),"무지출",SUMIF($J$81:$J$145,F20,$R$81:$R$145))) -> 무지출 | G21: =IF(MONTH(G20)<>$A$2,"",IF(AND(SUMIF($J$81:$J$145,G20,$R$81:$R$145)=0,G20<TODAY()),"무지출",SUMIF($J$81:$J$145,G20,$R$81:$R$145))) -> 무지출 | H21: =IF(MONTH(H20)<>$A$2,"",IF(AND(SUMIF($J$81:$J$145,H20,$R$81:$R$145)=0,H20<TODAY()),"무지출",SUMIF($J$81:$J$145,H20,$R$81:$R$145))) -> 무지출 | J21: =항목!K$3 -> 문화생활비 | K21: =SUMIF($L$58:$L$300,J21,$R$58:$R$300) -> 0 | L21: =VLOOKUP(J21,예산!$B$41:$N$53,3,FALSE) -> 0 | M21: =L21-K21 -> 0 | N21: =VLOOKUP(J21,'1월'!$J$10:$K$23,2,FALSE) -> 10000 | O21: =K21-N21 -> -10000
J22: =항목!L$3 -> 의료비 | K22: =SUMIF($L$58:$L$300,J22,$R$58:$R$300) -> 0 | L22: =VLOOKUP(J22,예산!$B$41:$N$53,3,FALSE) -> 0 | M22: =L22-K22 -> 0 | N22: =VLOOKUP(J22,'1월'!$J$10:$K$23,2,FALSE) -> 12000 | O22: =K22-N22 -> -12000
B23: =B11+28 -> 45711 | C23: =C11+28 -> 45712 | D23: =D11+28 -> 45713 | E23: =E11+28 -> 45714 | F23: =F11+28 -> 45715 | G23: =G11+28 -> 45716 | H23: =H11+28 -> 45717 | J23: =항목!Q$3 -> 추가항목 | K23: =SUMIF($L$58:$L$300,J23,$R$58:$R$300) -> 0 | L23: =VLOOKUP(J23,예산!$B$41:$N$53,3,FALSE) -> 0 | M23: =L23-K23 -> 0 | N23: =VLOOKUP(J23,'1월'!$J$10:$K$23,2,FALSE) -> 0 | O23: =K23-N23 -> 0
B24: =IF(MONTH(B23)<>$A$2,"",IF(AND(SUMIF($J$81:$J$145,B23,$R$81:$R$145)=0,B23<TODAY()),"무지출",SUMIF($J$81:$J$145,B23,$R$81:$R$145))) -> 무지출 | C24: =IF(MONTH(C23)<>$A$2,"",IF(AND(SUMIF($J$81:$J$145,C23,$R$81:$R$145)=0,C23<TODAY()),"무지출",SUMIF($J$81:$J$145,C23,$R$81:$R$145))) -> 무지출 | D24: =IF(MONTH(D23)<>$A$2,"",IF(AND(SUMIF($J$81:$J$145,D23,$R$81:$R$145)=0,D23<TODAY()),"무지출",SUMIF($J$81:$J$145,D23,$R$81:$R$145))) -> 무지출 | E24: =IF(MONTH(E23)<>$A$2,"",IF(AND(SUMIF($J$81:$J$145,E23,$R$81:$R$145)=0,E23<TODAY()),"무지출",SUMIF($J$81:$J$145,E23,$R$81:$R$145))) -> 무지출 | F24: =IF(MONTH(F23)<>$A$2,"",IF(AND(SUMIF($J$81:$J$145,F23,$R$81:$R$145)=0,F23<TODAY()),"무지출",SUMIF($J$81:$J$145,F23,$R$81:$R$145))) -> 무지출 | G24: =IF(MONTH(G23)<>$A$2,"",IF(AND(SUMIF($J$81:$J$145,G23,$R$81:$R$145)=0,G23<TODAY()),"무지출",SUMIF($J$81:$J$145,G23,$R$81:$R$145))) -> 무지출 | H24: =IF(MONTH(H23)<>$A$2,"",IF(AND(SUMIF($J$81:$J$145,H23,$R$81:$R$145)=0,H23<TODAY()),"무지출",SUMIF($J$81:$J$145,H23,$R$81:$R$145)))
J25: MEMO
B26: =B11+35 -> 45718 | C26: =C11+35 -> 45719 | D26: =D11+35 -> 45720 | E26: =E11+35 -> 45721 | F26: =F11+35 -> 45722 | G26: =G11+35 -> 45723 | H26: =H11+35 -> 45724
B27: =IF(MONTH(B26)<>$A$2,"",IF(AND(SUMIF($J$81:$J$145,B26,$R$81:$R$145)=0,B26<TODAY()),"무지출",SUMIF($J$81:$J$145,B26,$R$81:$R$145))) | C27: =IF(MONTH(C26)<>$A$2,"",IF(AND(SUMIF($J$81:$J$145,C26,$R$81:$R$145)=0,C26<TODAY()),"무지출",SUMIF($J$81:$J$145,C26,$R$81:$R$145))) | D27: =IF(MONTH(D26)<>$A$2,"",IF(AND(SUMIF($J$81:$J$145,D26,$R$81:$R$145)=0,D26<TODAY()),"무지출",SUMIF($J$81:$J$145,D26,$R$81:$R$145))) | E27: =IF(MONTH(E26)<>$A$2,"",IF(AND(SUMIF($J$81:$J$145,E26,$R$81:$R$145)=0,E26<TODAY()),"무지출",SUMIF($J$81:$J$145,E26,$R$81:$R$145))) | F27: =IF(MONTH(F26)<>$A$2,"",IF(AND(SUMIF($J$81:$J$145,F26,$R$81:$R$145)=0,F26<TODAY()),"무지출",SUMIF($J$81:$J$145,F26,$R$81:$R$145))) | G27: =IF(MONTH(G26)<>$A$2,"",IF(AND(SUMIF($J$81:$J$145,G26,$R$81:$R$145)=0,G26<TODAY()),"무지출",SUMIF($J$81:$J$145,G26,$R$81:$R$145))) | H27: =IF(MONTH(H26)<>$A$2,"",IF(AND(SUMIF($J$81:$J$145,H26,$R$81:$R$145)=0,H26<TODAY()),"무지출",SUMIF($J$81:$J$145,H26,$R$81:$R$145)))
B30: 수입 | J30: 지출
B32: ='1월'!B32 -> 고정수입 | C32: =SUM($H$34:$H$53) -> 0 | J32: ='1월'!J32 -> 저축성지출 | K32: =SUM($R$34:$R$53) -> 0
B33: 날짜 | C33: 대분류 | D33: 소분류 | E33: 내용 | H33: 금액 | J33: 날짜 | K33: 구분 | L33: 대분류 | M33: 소분류 | N33: 지출 내용 | P33: 결제금액 | Q33: 할인 | R33: 실지출 | S33: 비고
R34: =IF(P34="","",P34-Q34)
R35: =IF(P35="","",P35-Q35)
R36: =IF(P36="","",P36-Q36)
R37: =IF(P37="","",P37-Q37)
R38: =IF(P38="","",P38-Q38)
R39: =IF(P39="","",P39-Q39)
R40: =IF(P40="","",P40-Q40)
R41: =IF(P41="","",P41-Q41)
R42: =IF(P42="","",P42-Q42)
R43: =IF(P43="","",P43-Q43)
R44: =IF(P44="","",P44-Q44)
R45: =IF(P45="","",P45-Q45)
...

Sheet 3월
A1: =메인!$R$3 -> 2025 | B1: ◀ 03월 ▶
A2: =메인!$G$11 -> 3
B5: 총 수입 | C5: =SUM($C$32+$C$56) -> 0 | J5: ='1월'!J5 -> 이번달 목표 | P5: ='1월'!P5 -> 필수지출
B6: 총 지출 | C6: =SUM($K$32+$L$56) -> 0
B7: 차액 | C7: =$C$5-$C$6 -> 0
G8: 무지출 성공 | H8: =COUNTIF(B10:H28,"무지출") -> 31
B9: 변동지출 달력 | J9: 소비성 지출 분석
B10: 일 | C10: 월 | D10: 화 | E10: 수 | F10: 목 | G10: 금 | H10: 토 | J10: 항목 | K10: 지출계 | L10: 예산 | M10: 예산대비 | N10: 전월지출 | O10: 전월대비
B11: =DATE($A$1,$A$2,1)-WEEKDAY(DATE($A$1,$A$2,1))+1 -> 45711 | C11: =B11+1 -> 45712 | D11: =C11+1 -> 45713 | E11: =D11+1 -> 45714 | F11: =E11+1 -> 45715 | G11: =F11+1 -> 45716 | H11: =G11+1 -> 45717 | J11: =항목!N$3 -> 통신비 | K11: =SUMIF($L$58:$L$300,J11,$R$58:$R$300) -> 0 | L11: =VLOOKUP(J11,예산!$B$41:$N$53,4,FALSE) -> 0 | M11: =L11-K11 -> 0 | N11: =VLOOKUP(J11,'2월'!$J$10:$K$23,2,FALSE) -> 0 | O11: =K11-N11 -> 0
B12: =IF(MONTH(B11)<>$A$2,"",IF(AND(SUMIF($J$81:$J$145,B11,$R$81:$R$145)=0,B11<TODAY()),"무지출",SUMIF($J$81:$J$145,B11,$R$81:$R$145))) | C12: =IF(MONTH(C11)<>$A$2,"",IF(AND(SUMIF($J$81:$J$145,C11,$R$81:$R$145)=0,C11<TODAY()),"무지출",SUMIF($J$81:$J$145,C11,$R$81:$R$145))) | D12: =IF(MONTH(D11)<>$A$2,"",IF(AND(SUMIF($J$81:$J$145,D11,$R$81:$R$145)=0,D11<TODAY()),"무지출",SUMIF($J$81:$J$145,D11,$R$81:$R$145))) | E12: =IF(MONTH(E11)<>$A$2,"",IF(AND(SUMIF($J$81:$J$145,E11,$R$81:$R$145)=0,E11<TODAY()),"무지출",SUMIF($J$81:$J$145,E11,$R$81:$R$145))) | F12: =IF(MONTH(F11)<>$A$2,"",IF(AND(SUMIF($J$81:$J$145,F11,$R$81:$R$145)=0,F11<TODAY()),"무지출",SUMIF($J$81:$J$145,F11,$R$81:$R$145))) | G12: =IF(MONTH(G11)<>$A$2,"",IF(AND(SUMIF($J$81:$J$145,G11,$R$81:$R$145)=0,G11<TODAY()),"무지출",SUMIF($J$81:$J$145,G11,$R$81:$R$145))) | H12: =IF(MONTH(H11)<>$A$2,"",IF(AND(SUMIF($J$81:$J$145,H11,$R$81:$R$145)=0,H11<TODAY()),"무지출",SUMIF($J$81:$J$145,H11,$R$81:$R$145))) -> 무지출 | J12: =항목!J$3 -> 교육비 | K12: =SUMIF($L$58:$L$300,J12,$R$58:$R$300) -> 0 | L12: =VLOOKUP(J12,예산!$B$41:$N$53,4,FALSE) -> 0 | M12: =L12-K12 -> 0 | N12: =VLOOKUP(J12,'2월'!$J$10:$K$23,2,FALSE) -> 0 | O12: =K12-N12 -> 0
J13: =항목!P$3 -> 용돈 | K13: =SUMIF($L$58:$L$300,J13,$R$58:$R$300) -> 0 | L13: =VLOOKUP(J13,예산!$B$41:$N$53,4,FALSE) -> 0 | M13: =L13-K13 -> 0 | N13: =VLOOKUP(J13,'2월'!$J$10:$K$23,2,FALSE) -> 0 | O13: =K13-N13 -> 0
B14: =B11+7 -> 45718 | C14: =C11+7 -> 45719 | D14: =D11+7 -> 45720 | E14: =E11+7 -> 45721 | F14: =F11+7 -> 45722 | G14: =G11+7 -> 45723 | H14: =H11+7 -> 45724 | J14: =항목!E$3 -> 식비 | K14: =SUMIF($L$58:$L$300,J14,$R$58:$R$300) -> 0 | L14: =VLOOKUP(J14,예산!$B$41:$N$53,4,FALSE) -> 0 | M14: =L14-K14 -> 0 | N14: =VLOOKUP(J14,'2월'!$J$10:$K$23,2,FALSE) -> 0 | O14: =K14-N14 -> 0
B15: =IF(MONTH(B14)<>$A$2,"",IF(AND(SUMIF($J$81:$J$145,B14,$R$81:$R$145)=0,B14<TODAY()),"무지출",SUMIF($J$81:$J$145,B14,$R$81:$R$145))) -> 무지출 | C15: =IF(MONTH(C14)<>$A$2,"",IF(AND(SUMIF($J$81:$J$145,C14,$R$81:$R$145)=0,C14<TODAY()),"무지출",SUMIF($J$81:$J$145,C14,$R$81:$R$145))) -> 무지출 | D15: =IF(MONTH(D14)<>$A$2,"",IF(AND(SUMIF($J$81:$J$145,D14,$R$81:$R$145)=0,D14<TODAY()),"무지출",SUMIF($J$81:$J$145,D14,$R$81:$R$145))) -> 무지출 | E15: =IF(MONTH(E14)<>$A$2,"",IF(AND(SUMIF($J$81:$J$145,E14,$R$81:$R$145)=0,E14<TODAY()),"무지출",SUMIF($J$81:$J$145,E14,$R$81:$R$145))) -> 무지출 | F15: =IF(MONTH(F14)<>$A$2,"",IF(AND(SUMIF($J$81:$J$145,F14,$R$81:$R$145)=0,F14<TODAY()),"무지출",SUMIF($J$81:$J$145,F14,$R$81:$R$145))) -> 무지출 | G15: =IF(MONTH(G14)<>$A$2,"",IF(AND(SUMIF($J$81:$J$145,G14,$R$81:$R$145)=0,G14<TODAY()),"무지출",SUMIF($J$81:$J$145,G14,$R$81:$R$145))) -> 무지출 | H15: =IF(MONTH(H14)<>$A$2,"",IF(AND(SUMIF($J$81:$J$145,H14,$R$81:$R$145)=0,H14<TODAY()),"무지출",SUMIF($J$81:$J$145,H14,$R$81:$R$145))) -> 무지출 | J15: =항목!O$3 -> 경조사회비 | K15: =SUMIF($L$58:$L$300,J15,$R$58:$R$300) -> 0 | L15: =VLOOKUP(J15,예산!$B$41:$N$53,4,FALSE) -> 0 | M15: =L15-K15 -> 0 | N15: =VLOOKUP(J15,'2월'!$J$10:$K$23,2,FALSE) -> 0 | O15: =K15-N15 -> 0
J16: =항목!I$3 -> 의류미용비 | K16: =SUMIF($L$58:$L$300,J16,$R$58:$R$300) -> 0 | L16: =VLOOKUP(J16,예산!$B$41:$N$53,4,FALSE) -> 0 | M16: =L16-K16 -> 0 | N16: =VLOOKUP(J16,'2월'!$J$10:$K$23,2,FALSE) -> 0 | O16: =K16-N16 -> 0
B17: =B11+14 -> 45725 | C17: =C11+14 -> 45726 | D17: =D11+14 -> 45727 | E17: =E11+14 -> 45728 | F17: =F11+14 -> 45729 | G17: =G11+14 -> 45730 | H17: =H11+14 -> 45731 | J17: =항목!M$3 -> 유류교통비 | K17: =SUMIF($L$58:$L$300,J17,$R$58:$R$300) -> 0 | L17: =VLOOKUP(J17,예산!$B$41:$N$53,4,FALSE) -> 0 | M17: =L17-K17 -> 0 | N17: =VLOOKUP(J17,'2월'!$J$10:$K$23,2,FALSE) -> 0 | O17: =K17-N17 -> 0
B18: =IF(MONTH(B17)<>$A$2,"",IF(AND(SUMIF($J$81:$J$145,B17,$R$81:$R$145)=0,B17<TODAY()),"무지출",SUMIF($J$81:$J$145,B17,$R$81:$R$145))) -> 무지출 | C18: =IF(MONTH(C17)<>$A$2,"",IF(AND(SUMIF($J$81:$J$145,C17,$R$81:$R$145)=0,C17<TODAY()),"무지출",SUMIF($J$81:$J$145,C17,$R$81:$R$145))) -> 무지출 | D18: =IF(MONTH(D17)<>$A$2,"",IF(AND(SUMIF($J$81:$J$145,D17,$R$81:$R$145)=0,D17<TODAY()),"무지출",SUMIF($J$81:$J$145,D17,$R$81:$R$145))) -> 무지출 | E18: =IF(MONTH(E17)<>$A$2,"",IF(AND(SUMIF($J$81:$J$145,E17,$R$81:$R$145)=0,E17<TODAY()),"무지출",SUMIF($J$81:$J$145,E17,$R$81:$R$145))) -> 무지출 | F18: =IF(MONTH(F17)<>$A$2,"",IF(AND(SUMIF($J$81:$J$145,F17,$R$81:$R$145)=0,F17<TODAY()),"무지출",SUMIF($J$81:$J$145,F17,$R$81:$R$145))) -> 무지출 | G18: =IF(MONTH(G17)<>$A$2,"",IF(AND(SUMIF($J$81:$J$145,G17,$R$81:$R$145)=0,G17<TODAY()),"무지출",SUMIF($J$81:$J$145,G17,$R$81:$R$145))) -> 무지출 | H18: =IF(MONTH(H17)<>$A$2,"",IF(AND(SUMIF($J$81:$J$145,H17,$R$81:$R$145)=0,H17<TODAY()),"무지출",SUMIF($J$81:$J$145,H17,$R$81:$R$145))) -> 무지출 | J18: =항목!L$3 -> 의료비 | K18: =SUMIF($L$58:$L$300,J18,$R$58:$R$300) -> 0 | L18: =VLOOKUP(J18,예산!$B$41:$N$53,4,FALSE) -> 0 | M18: =L18-K18 -> 0 | N18: =VLOOKUP(J18,'2월'!$J$10:$K$23,2,FALSE) -> 0 | O18: =K18-N18 -> 0
J19: =항목!G$3 -> 생활용품비 | K19: =SUMIF($L$58:$L$300,J19,$R$58:$R$300) -> 0 | L19: =VLOOKUP(J19,예산!$B$41:$N$53,4,FALSE) -> 0 | M19: =L19-K19 -> 0 | N19: =VLOOKUP(J19,'2월'!$J$10:$K$23,2,FALSE) -> 0 | O19: =K19-N19 -> 0
B20: =B11+21 -> 45732 | C20: =C11+21 -> 45733 | D20: =D11+21 -> 45734 | E20: =E11+21 -> 45735 | F20: =F11+21 -> 45736 | G20: =G11+21 -> 45737 | H20: =H11+21 -> 45738 | J20: =항목!F$3 -> 주거비 | K20: =SUMIF($L$58:$L$300,J20,$R$58:$R$300) -> 0 | L20: =VLOOKUP(J20,예산!$B$41:$N$53,4,FALSE) -> 0 | M20: =L20-K20 -> 0 | N20: =VLOOKUP(J20,'2월'!$J$10:$K$23,2,FALSE) -> 0 | O20: =K20-N20 -> 0
B21: =IF(MONTH(B20)<>$A$2,"",IF(AND(SUMIF($J$81:$J$145,B20,$R$81:$R$145)=0,B20<TODAY()),"무지출",SUMIF($J$81:$J$145,B20,$R$81:$R$145))) -> 무지출 | C21: =IF(MONTH(C20)<>$A$2,"",IF(AND(SUMIF($J$81:$J$145,C20,$R$81:$R$145)=0,C20<TODAY()),"무지출",SUMIF($J$81:$J$145,C20,$R$81:$R$145))) -> 무지출 | D21: =IF(MONTH(D20)<>$A$2,"",IF(AND(SUMIF($J$81:$J$145,D20,$R$81:$R$145)=0,D20<TODAY()),"무지출",SUMIF($J$81:$J$145,D20,$R$81:$R$145))) -> 무지출 | E21: =IF(MONTH(E20)<>$A$2,"",IF(AND(SUMIF($J$81:$J$145,E20,$R$81:$R$145)=0,E20<TODAY()),"무지출",SUMIF($J$81:$J$145,E20,$R$81:$R$145))) -> 무지출 | F21: =IF(MONTH(F20)<>$A$2,"",IF(AND(SUMIF($J$81:$J$145,F20,$R$81:$R$145)=0,F20<TODAY()),"무지출",SUMIF($J$81:$J$145,F20,$R$81:$R$145))) -> 무지출 | G21: =IF(MONTH(G20)<>$A$2,"",IF(AND(SUMIF($J$81:$J$145,G20,$R$81:$R$145)=0,G20<TODAY()),"무지출",SUMIF($J$81:$J$145,G20,$R$81:$R$145))) -> 무지출 | H21: =IF(MONTH(H20)<>$A$2,"",IF(AND(SUMIF($J$81:$J$145,H20,$R$81:$R$145)=0,H20<TODAY()),"무지출",SUMIF($J$81:$J$145,H20,$R$81:$R$145))) -> 무지출 | J21: =항목!H$3 -> 반려동물비 | K21: =SUMIF($L$58:$L$300,J21,$R$58:$R$300) -> 0 | L21: =VLOOKUP(J21,예산!$B$41:$N$53,4,FALSE) -> 0 | M21: =L21-K21 -> 0 | N21: =VLOOKUP(J21,'2월'!$J$10:$K$23,2,FALSE) -> 0 | O21: =K21-N21 -> 0
J22: =항목!K$3 -> 문화생활비 | K22: =SUMIF($L$58:$L$300,J22,$R$58:$R$300) -> 0 | L22: =VLOOKUP(J22,예산!$B$41:$N$53,4,FALSE) -> 0 | M22: =L22-K22 -> 0 | N22: =VLOOKUP(J22,'2월'!$J$10:$K$23,2,FALSE) -> 0 | O22: =K22-N22 -> 0
B23: =B11+28 -> 45739 | C23: =C11+28 -> 45740 | D23: =D11+28 -> 45741 | E23: =E11+28 -> 45742 | F23: =F11+28 -> 45743 | G23: =G11+28 -> 45744 | H23: =H11+28 -> 45745 | J23: =항목!Q$3 -> 추가항목 | K23: =SUMIF($L$58:$L$300,J23,$R$58:$R$300) -> 0 | L23: =VLOOKUP(J23,예산!$B$41:$N$53,4,FALSE) -> 0 | M23: =L23-K23 -> 0 | N23: =VLOOKUP(J23,'2월'!$J$10:$K$23,2,FALSE) -> 0 | O23: =K23-N23 -> 0
B24: =IF(MONTH(B23)<>$A$2,"",IF(AND(SUMIF($J$81:$J$145,B23,$R$81:$R$145)=0,B23<TODAY()),"무지출",SUMIF($J$81:$J$145,B23,$R$81:$R$145))) -> 무지출 | C24: =IF(MONTH(C23)<>$A$2,"",IF(AND(SUMIF($J$81:$J$145,C23,$R$81:$R$145)=0,C23<TODAY()),"무지출",SUMIF($J$81:$J$145,C23,$R$81:$R$145))) -> 무지출 | D24: =IF(MONTH(D23)<>$A$2,"",IF(AND(SUMIF($J$81:$J$145,D23,$R$81:$R$145)=0,D23<TODAY()),"무지출",SUMIF($J$81:$J$145,D23,$R$81:$R$145))) -> 무지출 | E24: =IF(MONTH(E23)<>$A$2,"",IF(AND(SUMIF($J$81:$J$145,E23,$R$81:$R$145)=0,E23<TODAY()),"무지출",SUMIF($J$81:$J$145,E23,$R$81:$R$145))) -> 무지출 | F24: =IF(MONTH(F23)<>$A$2,"",IF(AND(SUMIF($J$81:$J$145,F23,$R$81:$R$145)=0,F23<TODAY()),"무지출",SUMIF($J$81:$J$145,F23,$R$81:$R$145))) -> 무지출 | G24: =IF(MONTH(G23)<>$A$2,"",IF(AND(SUMIF($J$81:$J$145,G23,$R$81:$R$145)=0,G23<TODAY()),"무지출",SUMIF($J$81:$J$145,G23,$R$81:$R$145))) -> 무지출 | H24: =IF(MONTH(H23)<>$A$2,"",IF(AND(SUMIF($J$81:$J$145,H23,$R$81:$R$145)=0,H23<TODAY()),"무지출",SUMIF($J$81:$J$145,H23,$R$81:$R$145))) -> 무지출
J25: MEMO
B26: =B11+35 -> 45746 | C26: =C11+35 -> 45747 | D26: =D11+35 -> 45748 | E26: =E11+35 -> 45749 | F26: =F11+35 -> 45750 | G26: =G11+35 -> 45751 | H26: =H11+35 -> 45752
B27: =IF(MONTH(B26)<>$A$2,"",IF(AND(SUMIF($J$81:$J$145,B26,$R$81:$R$145)=0,B26<TODAY()),"무지출",SUMIF($J$81:$J$145,B26,$R$81:$R$145))) -> 무지출 | C27: =IF(MONTH(C26)<>$A$2,"",IF(AND(SUMIF($J$81:$J$145,C26,$R$81:$R$145)=0,C26<TODAY()),"무지출",SUMIF($J$81:$J$145,C26,$R$81:$R$145))) -> 무지출 | D27: =IF(MONTH(D26)<>$A$2,"",IF(AND(SUMIF($J$81:$J$145,D26,$R$81:$R$145)=0,D26<TODAY()),"무지출",SUMIF($J$81:$J$145,D26,$R$81:$R$145))) | E27: =IF(MONTH(E26)<>$A$2,"",IF(AND(SUMIF($J$81:$J$145,E26,$R$81:$R$145)=0,E26<TODAY()),"무지출",SUMIF($J$81:$J$145,E26,$R$81:$R$145))) | F27: =IF(MONTH(F26)<>$A$2,"",IF(AND(SUMIF($J$81:$J$145,F26,$R$81:$R$145)=0,F26<TODAY()),"무지출",SUMIF($J$81:$J$145,F26,$R$81:$R$145))) | G27: =IF(MONTH(G26)<>$A$2,"",IF(AND(SUMIF($J$81:$J$145,G26,$R$81:$R$145)=0,G26<TODAY()),"무지출",SUMIF($J$81:$J$145,G26,$R$81:$R$145))) | H27: =IF(MONTH(H26)<>$A$2,"",IF(AND(SUMIF($J$81:$J$145,H26,$R$81:$R$145)=0,H26<TODAY()),"무지출",SUMIF($J$81:$J$145,H26,$R$81:$R$145)))
B30: 수입 | J30: 지출
B32: ='1월'!B32 -> 고정수입 | C32: =SUM($H$34:$H$53) -> 0 | J32: ='1월'!J32 -> 저축성지출 | K32: =SUM($R$34:$R$53) -> 0
B33: 날짜 | C33: 대분류 | D33: 소분류 | E33: 내용 | H33: 금액 | J33: 날짜 | K33: 구분 | L33: 대분류 | M33: 소분류 | N33: 지출 내용 | P33: 결제금액 | Q33: 할인 | R33: 실지출 | S33: 비고
R34: =IF(P34="","",P34-Q34)
R35: =IF(P35="","",P35-Q35)
R36: =IF(P36="","",P36-Q36)
R37: =IF(P37="","",P37-Q37)
R38: =IF(P38="","",P38-Q38)
R39: =IF(P39="","",P39-Q39)
R40: =IF(P40="","",P40-Q40)
R41: =IF(P41="","",P41-Q41)
R42: =IF(P42="","",P42-Q42)
R43: =IF(P43="","",P43-Q43)
R44: =IF(P44="","",P44-Q44)
R45: =IF(P45="","",P45-Q45)
...

Sheet 4월
A1: =메인!$R$3 -> 2025 | B1: ◀ 04월 ▶
A2: =메인!$H$11 -> 4
B5: 총 수입 | C5: =SUM($C$32+$C$56) -> 0 | J5: ='1월'!J5 -> 이번달 목표 | P5: 필수지출
B6: 총 지출 | C6: =SUM($K$32+$L$56) -> 0
B7: 차액 | C7: =$C$5-$C$6 -> 0
G8: 무지출 성공 | H8: =COUNTIF(B10:H28,"무지출") -> 30
B9: 변동지출 달력 | J9: 소비성 지출 분석
B10: 일 | C10: 월 | D10: 화 | E10: 수 | F10: 목 | G10: 금 | H10: 토 | J10: 항목 | K10: 지출계 | L10: 예산 | M10: 예산대비 | N10: 전월지출 | O10: 전월대비
B11: =DATE($A$1,$A$2,1)-WEEKDAY(DATE($A$1,$A$2,1))+1 -> 45746 | C11: =B11+1 -> 45747 | D11: =C11+1 -> 45748 | E11: =D11+1 -> 45749 | F11: =E11+1 -> 45750 | G11: =F11+1 -> 45751 | H11: =G11+1 -> 45752 | J11: =항목!N$3 -> 통신비 | K11: =SUMIF($L$58:$L$300,J11,$R$58:$R$300) -> 0 | L11: =VLOOKUP(J11,예산!$B$41:$N$53,5,FALSE) -> 0 | M11: =L11-K11 -> 0 | N11: =VLOOKUP(J11,'3월'!$J$10:$K$23,2,FALSE) -> 0 | O11: =K11-N11 -> 0
B12: =IF(MONTH(B11)<>$A$2,"",IF(AND(SUMIF($J$81:$J$145,B11,$R$81:$R$145)=0,B11<TODAY()),"무지출",SUMIF($J$81:$J$145,B11,$R$81:$R$145))) | C12: =IF(MONTH(C11)<>$A$2,"",IF(AND(SUMIF($J$81:$J$145,C11,$R$81:$R$145)=0,C11<TODAY()),"무지출",SUMIF($J$81:$J$145,C11,$R$81:$R$145))) | D12: =IF(MONTH(D11)<>$A$2,"",IF(AND(SUMIF($J$81:$J$145,D11,$R$81:$R$145)=0,D11<TODAY()),"무지출",SUMIF($J$81:$J$145,D11,$R$81:$R$145))) -> 무지출 | E12: =IF(MONTH(E11)<>$A$2,"",IF(AND(SUMIF($J$81:$J$145,E11,$R$81:$R$145)=0,E11<TODAY()),"무지출",SUMIF($J$81:$J$145,E11,$R$81:$R$145))) -> 무지출 | F12: =IF(MONTH(F11)<>$A$2,"",IF(AND(SUMIF($J$81:$J$145,F11,$R$81:$R$145)=0,F11<TODAY()),"무지출",SUMIF($J$81:$J$145,F11,$R$81:$R$145))) -> 무지출 | G12: =IF(MONTH(G11)<>$A$2,"",IF(AND(SUMIF($J$81:$J$145,G11,$R$81:$R$145)=0,G11<TODAY()),"무지출",SUMIF($J$81:$J$145,G11,$R$81:$R$145))) -> 무지출 | H12: =IF(MONTH(H11)<>$A$2,"",IF(AND(SUMIF($J$81:$J$145,H11,$R$81:$R$145)=0,H11<TODAY()),"무지출",SUMIF($J$81:$J$145,H11,$R$81:$R$145))) -> 무지출 | J12: =항목!J$3 -> 교육비 | K12: =SUMIF($L$58:$L$300,J12,$R$58:$R$300) -> 0 | L12: =VLOOKUP(J12,예산!$B$41:$N$53,5,FALSE) -> 0 | M12: =L12-K12 -> 0 | N12: =VLOOKUP(J12,'3월'!$J$10:$K$23,2,FALSE) -> 0 | O12: =K12-N12 -> 0
J13: =항목!P$3 -> 용돈 | K13: =SUMIF($L$58:$L$300,J13,$R$58:$R$300) -> 0 | L13: =VLOOKUP(J13,예산!$B$41:$N$53,5,FALSE) -> 0 | M13: =L13-K13 -> 0 | N13: =VLOOKUP(J13,'3월'!$J$10:$K$23,2,FALSE) -> 0 | O13: =K13-N13 -> 0
B14: =B11+7 -> 45753 | C14: =C11+7 -> 45754 | D14: =D11+7 -> 45755 | E14: =E11+7 -> 45756 | F14: =F11+7 -> 45757 | G14: =G11+7 -> 45758 | H14: =H11+7 -> 45759 | J14: =항목!E$3 -> 식비 | K14: =SUMIF($L$58:$L$300,J14,$R$58:$R$300) -> 0 | L14: =VLOOKUP(J14,예산!$B$41:$N$53,5,FALSE) -> 0 | M14: =L14-K14 -> 0 | N14: =VLOOKUP(J14,'3월'!$J$10:$K$23,2,FALSE) -> 0 | O14: =K14-N14 -> 0
B15: =IF(MONTH(B14)<>$A$2,"",IF(AND(SUMIF($J$81:$J$145,B14,$R$81:$R$145)=0,B14<TODAY()),"무지출",SUMIF($J$81:$J$145,B14,$R$81:$R$145))) -> 무지출 | C15: =IF(MONTH(C14)<>$A$2,"",IF(AND(SUMIF($J$81:$J$145,C14,$R$81:$R$145)=0,C14<TODAY()),"무지출",SUMIF($J$81:$J$145,C14,$R$81:$R$145))) -> 무지출 | D15: =IF(MONTH(D14)<>$A$2,"",IF(AND(SUMIF($J$81:$J$145,D14,$R$81:$R$145)=0,D14<TODAY()),"무지출",SUMIF($J$81:$J$145,D14,$R$81:$R$145))) -> 무지출 | E15: =IF(MONTH(E14)<>$A$2,"",IF(AND(SUMIF($J$81:$J$145,E14,$R$81:$R$145)=0,E14<TODAY()),"무지출",SUMIF($J$81:$J$145,E14,$R$81:$R$145))) -> 무지출 | F15: =IF(MONTH(F14)<>$A$2,"",IF(AND(SUMIF($J$81:$J$145,F14,$R$81:$R$145)=0,F14<TODAY()),"무지출",SUMIF($J$81:$J$145,F14,$R$81:$R$145))) -> 무지출 | G15: =IF(MONTH(G14)<>$A$2,"",IF(AND(SUMIF($J$81:$J$145,G14,$R$81:$R$145)=0,G14<TODAY()),"무지출",SUMIF($J$81:$J$145,G14,$R$81:$R$145))) -> 무지출 | H15: =IF(MONTH(H14)<>$A$2,"",IF(AND(SUMIF($J$81:$J$145,H14,$R$81:$R$145)=0,H14<TODAY()),"무지출",SUMIF($J$81:$J$145,H14,$R$81:$R$145))) -> 무지출 | J15: =항목!O$3 -> 경조사회비 | K15: =SUMIF($L$58:$L$300,J15,$R$58:$R$300) -> 0 | L15: =VLOOKUP(J15,예산!$B$41:$N$53,5,FALSE) -> 0 | M15: =L15-K15 -> 0 | N15: =VLOOKUP(J15,'3월'!$J$10:$K$23,2,FALSE) -> 0 | O15: =K15-N15 -> 0
J16: =항목!M$3 -> 유류교통비 | K16: =SUMIF($L$58:$L$300,J16,$R$58:$R$300) -> 0 | L16: =VLOOKUP(J16,예산!$B$41:$N$53,5,FALSE) -> 0 | M16: =L16-K16 -> 0 | N16: =VLOOKUP(J16,'3월'!$J$10:$K$23,2,FALSE) -> 0 | O16: =K16-N16 -> 0
B17: =B11+14 -> 45760 | C17: =C11+14 -> 45761 | D17: =D11+14 -> 45762 | E17: =E11+14 -> 45763 | F17: =F11+14 -> 45764 | G17: =G11+14 -> 45765 | H17: =H11+14 -> 45766 | J17: =항목!I$3 -> 의류미용비 | K17: =SUMIF($L$58:$L$300,J17,$R$58:$R$300) -> 0 | L17: =VLOOKUP(J17,예산!$B$41:$N$53,5,FALSE) -> 0 | M17: =L17-K17 -> 0 | N17: =VLOOKUP(J17,'3월'!$J$10:$K$23,2,FALSE) -> 0 | O17: =K17-N17 -> 0
B18: =IF(MONTH(B17)<>$A$2,"",IF(AND(SUMIF($J$81:$J$145,B17,$R$81:$R$145)=0,B17<TODAY()),"무지출",SUMIF($J$81:$J$145,B17,$R$81:$R$145))) -> 무지출 | C18: =IF(MONTH(C17)<>$A$2,"",IF(AND(SUMIF($J$81:$J$145,C17,$R$81:$R$145)=0,C17<TODAY()),"무지출",SUMIF($J$81:$J$145,C17,$R$81:$R$145))) -> 무지출 | D18: =IF(MONTH(D17)<>$A$2,"",IF(AND(SUMIF($J$81:$J$145,D17,$R$81:$R$145)=0,D17<TODAY()),"무지출",SUMIF($J$81:$J$145,D17,$R$81:$R$145))) -> 무지출 | E18: =IF(MONTH(E17)<>$A$2,"",IF(AND(SUMIF($J$81:$J$145,E17,$R$81:$R$145)=0,E17<TODAY()),"무지출",SUMIF($J$81:$J$145,E17,$R$81:$R$145))) -> 무지출 | F18: =IF(MONTH(F17)<>$A$2,"",IF(AND(SUMIF($J$81:$J$145,F17,$R$81:$R$145)=0,F17<TODAY()),"무지출",SUMIF($J$81:$J$145,F17,$R$81:$R$145))) -> 무지출 | G18: =IF(MONTH(G17)<>$A$2,"",IF(AND(SUMIF($J$81:$J$145,G17,$R$81:$R$145)=0,G17<TODAY()),"무지출",SUMIF($J$81:$J$145,G17,$R$81:$R$145))) -> 무지출 | H18: =IF(MONTH(H17)<>$A$2,"",IF(AND(SUMIF($J$81:$J$145,H17,$R$81:$R$145)=0,H17<TODAY()),"무지출",SUMIF($J$81:$J$145,H17,$R$81:$R$145))) -> 무지출 | J18: =항목!L$3 -> 의료비 | K18: =SUMIF($L$58:$L$300,J18,$R$58:$R$300) -> 0 | L18: =VLOOKUP(J18,예산!$B$41:$N$53,5,FALSE) -> 0 | M18: =L18-K18 -> 0 | N18: =VLOOKUP(J18,'3월'!$J$10:$K$23,2,FALSE) -> 0 | O18: =K18-N18 -> 0
J19: =항목!G$3 -> 생활용품비 | K19: =SUMIF($L$58:$L$300,J19,$R$58:$R$300) -> 0 | L19: =VLOOKUP(J19,예산!$B$41:$N$53,5,FALSE) -> 0 | M19: =L19-K19 -> 0 | N19: =VLOOKUP(J19,'3월'!$J$10:$K$23,2,FALSE) -> 0 | O19: =K19-N19 -> 0
B20: =B11+21 -> 45767 | C20: =C11+21 -> 45768 | D20: =D11+21 -> 45769 | E20: =E11+21 -> 45770 | F20: =F11+21 -> 45771 | G20: =G11+21 -> 45772 | H20: =H11+21 -> 45773 | J20: =항목!F$3 -> 주거비 | K20: =SUMIF($L$58:$L$300,J20,$R$58:$R$300) -> 0 | L20: =VLOOKUP(J20,예산!$B$41:$N$53,5,FALSE) -> 0 | M20: =L20-K20 -> 0 | N20: =VLOOKUP(J20,'3월'!$J$10:$K$23,2,FALSE) -> 0 | O20: =K20-N20 -> 0
B21: =IF(MONTH(B20)<>$A$2,"",IF(AND(SUMIF($J$81:$J$145,B20,$R$81:$R$145)=0,B20<TODAY()),"무지출",SUMIF($J$81:$J$145,B20,$R$81:$R$145))) -> 무지출 | C21: =IF(MONTH(C20)<>$A$2,"",IF(AND(SUMIF($J$81:$J$145,C20,$R$81:$R$145)=0,C20<TODAY()),"무지출",SUMIF($J$81:$J$145,C20,$R$81:$R$145))) -> 무지출 | D21: =IF(MONTH(D20)<>$A$2,"",IF(AND(SUMIF($J$81:$J$145,D20,$R$81:$R$145)=0,D20<TODAY()),"무지출",SUMIF($J$81:$J$145,D20,$R$81:$R$145))) -> 무지출 | E21: =IF(MONTH(E20)<>$A$2,"",IF(AND(SUMIF($J$81:$J$145,E20,$R$81:$R$145)=0,E20<TODAY()),"무지출",SUMIF($J$81:$J$145,E20,$R$81:$R$145))) -> 무지출 | F21: =IF(MONTH(F20)<>$A$2,"",IF(AND(SUMIF($J$81:$J$145,F20,$R$81:$R$145)=0,F20<TODAY()),"무지출",SUMIF($J$81:$J$145,F20,$R$81:$R$145))) -> 무지출 | G21: =IF(MONTH(G20)<>$A$2,"",IF(AND(SUMIF($J$81:$J$145,G20,$R$81:$R$145)=0,G20<TODAY()),"무지출",SUMIF($J$81:$J$145,G20,$R$81:$R$145))) -> 무지출 | H21: =IF(MONTH(H20)<>$A$2,"",IF(AND(SUMIF($J$81:$J$145,H20,$R$81:$R$145)=0,H20<TODAY()),"무지출",SUMIF($J$81:$J$145,H20,$R$81:$R$145))) -> 무지출 | J21: =항목!H$3 -> 반려동물비 | K21: =SUMIF($L$58:$L$300,J21,$R$58:$R$300) -> 0 | L21: =VLOOKUP(J21,예산!$B$41:$N$53,5,FALSE) -> 0 | M21: =L21-K21 -> 0 | N21: =VLOOKUP(J21,'3월'!$J$10:$K$23,2,FALSE) -> 0 | O21: =K21-N21 -> 0
J22: =항목!K$3 -> 문화생활비 | K22: =SUMIF($L$58:$L$300,J22,$R$58:$R$300) -> 0 | L22: =VLOOKUP(J22,예산!$B$41:$N$53,5,FALSE) -> 0 | M22: =L22-K22 -> 0 | N22: =VLOOKUP(J22,'3월'!$J$10:$K$23,2,FALSE) -> 0 | O22: =K22-N22 -> 0
B23: =B11+28 -> 45774 | C23: =C11+28 -> 45775 | D23: =D11+28 -> 45776 | E23: =E11+28 -> 45777 | F23: =F11+28 -> 45778 | G23: =G11+28 -> 45779 | H23: =H11+28 -> 45780 | J23: =항목!Q$3 -> 추가항목 | K23: =SUMIF($L$58:$L$300,J23,$R$58:$R$300) -> 0 | L23: =VLOOKUP(J23,예산!$B$41:$N$53,5,FALSE) -> 0 | M23: =L23-K23 -> 0 | N23: =VLOOKUP(J23,'3월'!$J$10:$K$23,2,FALSE) -> 0 | O23: =K23-N23 -> 0
B24: =IF(MONTH(B23)<>$A$2,"",IF(AND(SUMIF($J$81:$J$145,B23,$R$81:$R$145)=0,B23<TODAY()),"무지출",SUMIF($J$81:$J$145,B23,$R$81:$R$145))) -> 무지출 | C24: =IF(MONTH(C23)<>$A$2,"",IF(AND(SUMIF($J$81:$J$145,C23,$R$81:$R$145)=0,C23<TODAY()),"무지출",SUMIF($J$81:$J$145,C23,$R$81:$R$145))) -> 무지출 | D24: =IF(MONTH(D23)<>$A$2,"",IF(AND(SUMIF($J$81:$J$145,D23,$R$81:$R$145)=0,D23<TODAY()),"무지출",SUMIF($J$81:$J$145,D23,$R$81:$R$145))) -> 무지출 | E24: =IF(MONTH(E23)<>$A$2,"",IF(AND(SUMIF($J$81:$J$145,E23,$R$81:$R$145)=0,E23<TODAY()),"무지출",SUMIF($J$81:$J$145,E23,$R$81:$R$145))) -> 무지출 | F24: =IF(MONTH(F23)<>$A$2,"",IF(AND(SUMIF($J$81:$J$145,F23,$R$81:$R$145)=0,F23<TODAY()),"무지출",SUMIF($J$81:$J$145,F23,$R$81:$R$145))) | G24: =IF(MONTH(G23)<>$A$2,"",IF(AND(SUMIF($J$81:$J$145,G23,$R$81:$R$145)=0,G23<TODAY()),"무지출",SUMIF($J$81:$J$145,G23,$R$81:$R$145))) | H24: =IF(MONTH(H23)<>$A$2,"",IF(AND(SUMIF($J$81:$J$145,H23,$R$81:$R$145)=0,H23<TODAY()),"무지출",SUMIF($J$81:$J$145,H23,$R$81:$R$145)))
J25: MEMO
B26: =B11+35 -> 45781 | C26: =C11+35 -> 45782 | D26: =D11+35 -> 45783 | E26: =E11+35 -> 45784 | F26: =F11+35 -> 45785 | G26: =G11+35 -> 45786 | H26: =H11+35 -> 45787
B27: =IF(MONTH(B26)<>$A$2,"",IF(AND(SUMIF($J$81:$J$145,B26,$R$81:$R$145)=0,B26<TODAY()),"무지출",SUMIF($J$81:$J$145,B26,$R$81:$R$145))) | C27: =IF(MONTH(C26)<>$A$2,"",IF(AND(SUMIF($J$81:$J$145,C26,$R$81:$R$145)=0,C26<TODAY()),"무지출",SUMIF($J$81:$J$145,C26,$R$81:$R$145))) | D27: =IF(MONTH(D26)<>$A$2,"",IF(AND(SUMIF($J$81:$J$145,D26,$R$81:$R$145)=0,D26<TODAY()),"무지출",SUMIF($J$81:$J$145,D26,$R$81:$R$145))) | E27: =IF(MONTH(E26)<>$A$2,"",IF(AND(SUMIF($J$81:$J$145,E26,$R$81:$R$145)=0,E26<TODAY()),"무지출",SUMIF($J$81:$J$145,E26,$R$81:$R$145))) | F27: =IF(MONTH(F26)<>$A$2,"",IF(AND(SUMIF($J$81:$J$145,F26,$R$81:$R$145)=0,F26<TODAY()),"무지출",SUMIF($J$81:$J$145,F26,$R$81:$R$145))) | G27: =IF(MONTH(G26)<>$A$2,"",IF(AND(SUMIF($J$81:$J$145,G26,$R$81:$R$145)=0,G26<TODAY()),"무지출",SUMIF($J$81:$J$145,G26,$R$81:$R$145))) | H27: =IF(MONTH(H26)<>$A$2,"",IF(AND(SUMIF($J$81:$J$145,H26,$R$81:$R$145)=0,H26<TODAY()),"무지출",SUMIF($J$81:$J$145,H26,$R$81:$R$145)))
B30: 수입 | J30: 지출
B32: ='1월'!B32 -> 고정수입 | C32: =SUM($H$34:$H$53) -> 0 | J32: ='1월'!J32 -> 저축성지출 | K32: =SUM($R$34:$R$53) -> 0
B33: 날짜 | C33: 대분류 | D33: 소분류 | E33: 내용 | H33: 금액 | J33: 날짜 | K33: 구분 | L33: 대분류 | M33: 소분류 | N33: 지출 내용 | P33: 결제금액 | Q33: 할인 | R33: 실지출 | S33: 비고
R34: =IF(P34="","",P34-Q34)
R35: =IF(P35="","",P35-Q35)
R36: =IF(P36="","",P36-Q36)
R37: =IF(P37="","",P37-Q37)
R38: =IF(P38="","",P38-Q38)
R39: =IF(P39="","",P39-Q39)
R40: =IF(P40="","",P40-Q40)
R41: =IF(P41="","",P41-Q41)
R42: =IF(P42="","",P42-Q42)
R43: =IF(P43="","",P43-Q43)
R44: =IF(P44="","",P44-Q44)
R45: =IF(P45="","",P45-Q45)
...

Sheet 5월
A1: =메인!$R$3 -> 2025 | B1: ◀ 05월 ▶
A2: =메인!$I$11 -> 5
B5: 총 수입 | C5: =SUM($C$32+$C$56) -> 0 | J5: ='1월'!J5 -> 이번달 목표 | P5: 필수지출
B6: 총 지출 | C6: =SUM($K$32+$L$56) -> 0
B7: 차액 | C7: =$C$5-$C$6 -> 0
G8: 무지출 성공 | H8: =COUNTIF(B10:H28,"무지출") -> 31
B9: 변동지출 달력 | J9: 소비성 지출 분석
B10: 일 | C10: 월 | D10: 화 | E10: 수 | F10: 목 | G10: 금 | H10: 토 | J10: 항목 | K10: 지출계 | L10: 예산 | M10: 예산대비 | N10: 전월지출 | O10: 전월대비
B11: =DATE($A$1,$A$2,1)-WEEKDAY(DATE($A$1,$A$2,1))+1 -> 45774 | C11: =B11+1 -> 45775 | D11: =C11+1 -> 45776 | E11: =D11+1 -> 45777 | F11: =E11+1 -> 45778 | G11: =F11+1 -> 45779 | H11: =G11+1 -> 45780 | J11: =항목!N$3 -> 통신비 | K11: =SUMIF($L$58:$L$300,J11,$R$58:$R$300) -> 0 | L11: =VLOOKUP(J11,예산!$B$41:$N$53,6,FALSE) -> 0 | M11: =L11-K11 -> 0 | N11: =VLOOKUP(J11,'4월'!$J$10:$K$23,2,FALSE) -> 0 | O11: =K11-N11 -> 0
B12: =IF(MONTH(B11)<>$A$2,"",IF(AND(SUMIF($J$81:$J$164,B11,$R$81:$R$164)=0,B11<TODAY()),"무지출",SUMIF($J$81:$J$164,B11,$R$81:$R$164))) | C12: =IF(MONTH(C11)<>$A$2,"",IF(AND(SUMIF($J$81:$J$164,C11,$R$81:$R$164)=0,C11<TODAY()),"무지출",SUMIF($J$81:$J$164,C11,$R$81:$R$164))) | D12: =IF(MONTH(D11)<>$A$2,"",IF(AND(SUMIF($J$81:$J$164,D11,$R$81:$R$164)=0,D11<TODAY()),"무지출",SUMIF($J$81:$J$164,D11,$R$81:$R$164))) | E12: =IF(MONTH(E11)<>$A$2,"",IF(AND(SUMIF($J$81:$J$164,E11,$R$81:$R$164)=0,E11<TODAY()),"무지출",SUMIF($J$81:$J$164,E11,$R$81:$R$164))) | F12: =IF(MONTH(F11)<>$A$2,"",IF(AND(SUMIF($J$81:$J$164,F11,$R$81:$R$164)=0,F11<TODAY()),"무지출",SUMIF($J$81:$J$164,F11,$R$81:$R$164))) -> 무지출 | G12: =IF(MONTH(G11)<>$A$2,"",IF(AND(SUMIF($J$81:$J$164,G11,$R$81:$R$164)=0,G11<TODAY()),"무지출",SUMIF($J$81:$J$164,G11,$R$81:$R$164))) -> 무지출 | H12: =IF(MONTH(H11)<>$A$2,"",IF(AND(SUMIF($J$81:$J$164,H11,$R$81:$R$164)=0,H11<TODAY()),"무지출",SUMIF($J$81:$J$164,H11,$R$81:$R$164))) -> 무지출 | J12: =항목!J$3 -> 교육비 | K12: =SUMIF($L$58:$L$300,J12,$R$58:$R$300) -> 0 | L12: =VLOOKUP(J12,예산!$B$41:$N$53,6,FALSE) -> 0 | M12: =L12-K12 -> 0 | N12: =VLOOKUP(J12,'4월'!$J$10:$K$23,2,FALSE) -> 0 | O12: =K12-N12 -> 0
J13: =항목!P$3 -> 용돈 | K13: =SUMIF($L$58:$L$300,J13,$R$58:$R$300) -> 0 | L13: =VLOOKUP(J13,예산!$B$41:$N$53,6,FALSE) -> 0 | M13: =L13-K13 -> 0 | N13: =VLOOKUP(J13,'4월'!$J$10:$K$23,2,FALSE) -> 0 | O13: =K13-N13 -> 0
B14: =B11+7 -> 45781 | C14: =C11+7 -> 45782 | D14: =D11+7 -> 45783 | E14: =E11+7 -> 45784 | F14: =F11+7 -> 45785 | G14: =G11+7 -> 45786 | H14: =H11+7 -> 45787 | J14: =항목!E$3 -> 식비 | K14: =SUMIF($L$58:$L$300,J14,$R$58:$R$300) -> 0 | L14: =VLOOKUP(J14,예산!$B$41:$N$53,6,FALSE) -> 0 | M14: =L14-K14 -> 0 | N14: =VLOOKUP(J14,'4월'!$J$10:$K$23,2,FALSE) -> 0 | O14: =K14-N14 -> 0
B15: =IF(MONTH(B14)<>$A$2,"",IF(AND(SUMIF($J$81:$J$164,B14,$R$81:$R$164)=0,B14<TODAY()),"무지출",SUMIF($J$81:$J$164,B14,$R$81:$R$164))) -> 무지출 | C15: =IF(MONTH(C14)<>$A$2,"",IF(AND(SUMIF($J$81:$J$164,C14,$R$81:$R$164)=0,C14<TODAY()),"무지출",SUMIF($J$81:$J$164,C14,$R$81:$R$164))) -> 무지출 | D15: =IF(MONTH(D14)<>$A$2,"",IF(AND(SUMIF($J$81:$J$164,D14,$R$81:$R$164)=0,D14<TODAY()),"무지출",SUMIF($J$81:$J$164,D14,$R$81:$R$164))) -> 무지출 | E15: =IF(MONTH(E14)<>$A$2,"",IF(AND(SUMIF($J$81:$J$164,E14,$R$81:$R$164)=0,E14<TODAY()),"무지출",SUMIF($J$81:$J$164,E14,$R$81:$R$164))) -> 무지출 | F15: =IF(MONTH(F14)<>$A$2,"",IF(AND(SUMIF($J$81:$J$164,F14,$R$81:$R$164)=0,F14<TODAY()),"무지출",SUMIF($J$81:$J$164,F14,$R$81:$R$164))) -> 무지출 | G15: =IF(MONTH(G14)<>$A$2,"",IF(AND(SUMIF($J$81:$J$164,G14,$R$81:$R$164)=0,G14<TODAY()),"무지출",SUMIF($J$81:$J$164,G14,$R$81:$R$164))) -> 무지출 | H15: =IF(MONTH(H14)<>$A$2,"",IF(AND(SUMIF($J$81:$J$164,H14,$R$81:$R$164)=0,H14<TODAY()),"무지출",SUMIF($J$81:$J$164,H14,$R$81:$R$164))) -> 무지출 | J15: =항목!O$3 -> 경조사회비 | K15: =SUMIF($L$58:$L$300,J15,$R$58:$R$300) -> 0 | L15: =VLOOKUP(J15,예산!$B$41:$N$53,6,FALSE) -> 0 | M15: =L15-K15 -> 0 | N15: =VLOOKUP(J15,'4월'!$J$10:$K$23,2,FALSE) -> 0 | O15: =K15-N15 -> 0
J16: =항목!M$3 -> 유류교통비 | K16: =SUMIF($L$58:$L$300,J16,$R$58:$R$300) -> 0 | L16: =VLOOKUP(J16,예산!$B$41:$N$53,6,FALSE) -> 0 | M16: =L16-K16 -> 0 | N16: =VLOOKUP(J16,'4월'!$J$10:$K$23,2,FALSE) -> 0 | O16: =K16-N16 -> 0
B17: =B11+14 -> 45788 | C17: =C11+14 -> 45789 | D17: =D11+14 -> 45790 | E17: =E11+14 -> 45791 | F17: =F11+14 -> 45792 | G17: =G11+14 -> 45793 | H17: =H11+14 -> 45794 | J17: =항목!L$3 -> 의료비 | K17: =SUMIF($L$58:$L$300,J17,$R$58:$R$300) -> 0 | L17: =VLOOKUP(J17,예산!$B$41:$N$53,6,FALSE) -> 0 | M17: =L17-K17 -> 0 | N17: =VLOOKUP(J17,'4월'!$J$10:$K$23,2,FALSE) -> 0 | O17: =K17-N17 -> 0
B18: =IF(MONTH(B17)<>$A$2,"",IF(AND(SUMIF($J$81:$J$164,B17,$R$81:$R$164)=0,B17<TODAY()),"무지출",SUMIF($J$81:$J$164,B17,$R$81:$R$164))) -> 무지출 | C18: =IF(MONTH(C17)<>$A$2,"",IF(AND(SUMIF($J$81:$J$164,C17,$R$81:$R$164)=0,C17<TODAY()),"무지출",SUMIF($J$81:$J$164,C17,$R$81:$R$164))) -> 무지출 | D18: =IF(MONTH(D17)<>$A$2,"",IF(AND(SUMIF($J$81:$J$164,D17,$R$81:$R$164)=0,D17<TODAY()),"무지출",SUMIF($J$81:$J$164,D17,$R$81:$R$164))) -> 무지출 | E18: =IF(MONTH(E17)<>$A$2,"",IF(AND(SUMIF($J$81:$J$164,E17,$R$81:$R$164)=0,E17<TODAY()),"무지출",SUMIF($J$81:$J$164,E17,$R$81:$R$164))) -> 무지출 | F18: =IF(MONTH(F17)<>$A$2,"",IF(AND(SUMIF($J$81:$J$164,F17,$R$81:$R$164)=0,F17<TODAY()),"무지출",SUMIF($J$81:$J$164,F17,$R$81:$R$164))) -> 무지출 | G18: =IF(MONTH(G17)<>$A$2,"",IF(AND(SUMIF($J$81:$J$164,G17,$R$81:$R$164)=0,G17<TODAY()),"무지출",SUMIF($J$81:$J$164,G17,$R$81:$R$164))) -> 무지출 | H18: =IF(MONTH(H17)<>$A$2,"",IF(AND(SUMIF($J$81:$J$164,H17,$R$81:$R$164)=0,H17<TODAY()),"무지출",SUMIF($J$81:$J$164,H17,$R$81:$R$164))) -> 무지출 | J18: =항목!G$3 -> 생활용품비 | K18: =SUMIF($L$58:$L$300,J18,$R$58:$R$300) -> 0 | L18: =VLOOKUP(J18,예산!$B$41:$N$53,6,FALSE) -> 0 | M18: =L18-K18 -> 0 | N18: =VLOOKUP(J18,'4월'!$J$10:$K$23,2,FALSE) -> 0 | O18: =K18-N18 -> 0
J19: =항목!I$3 -> 의류미용비 | K19: =SUMIF($L$58:$L$300,J19,$R$58:$R$300) -> 0 | L19: =VLOOKUP(J19,예산!$B$41:$N$53,6,FALSE) -> 0 | M19: =L19-K19 -> 0 | N19: =VLOOKUP(J19,'4월'!$J$10:$K$23,2,FALSE) -> 0 | O19: =K19-N19 -> 0
B20: =B11+21 -> 45795 | C20: =C11+21 -> 45796 | D20: =D11+21 -> 45797 | E20: =E11+21 -> 45798 | F20: =F11+21 -> 45799 | G20: =G11+21 -> 45800 | H20: =H11+21 -> 45801 | J20: =항목!F$3 -> 주거비 | K20: =SUMIF($L$58:$L$300,J20,$R$58:$R$300) -> 0 | L20: =VLOOKUP(J20,예산!$B$41:$N$53,6,FALSE) -> 0 | M20: =L20-K20 -> 0 | N20: =VLOOKUP(J20,'4월'!$J$10:$K$23,2,FALSE) -> 0 | O20: =K20-N20 -> 0
B21: =IF(MONTH(B20)<>$A$2,"",IF(AND(SUMIF($J$81:$J$164,B20,$R$81:$R$164)=0,B20<TODAY()),"무지출",SUMIF($J$81:$J$164,B20,$R$81:$R$164))) -> 무지출 | C21: =IF(MONTH(C20)<>$A$2,"",IF(AND(SUMIF($J$81:$J$164,C20,$R$81:$R$164)=0,C20<TODAY()),"무지출",SUMIF($J$81:$J$164,C20,$R$81:$R$164))) -> 무지출 | D21: =IF(MONTH(D20)<>$A$2,"",IF(AND(SUMIF($J$81:$J$164,D20,$R$81:$R$164)=0,D20<TODAY()),"무지출",SUMIF($J$81:$J$164,D20,$R$81:$R$164))) -> 무지출 | E21: =IF(MONTH(E20)<>$A$2,"",IF(AND(SUMIF($J$81:$J$164,E20,$R$81:$R$164)=0,E20<TODAY()),"무지출",SUMIF($J$81:$J$164,E20,$R$81:$R$164))) -> 무지출 | F21: =IF(MONTH(F20)<>$A$2,"",IF(AND(SUMIF($J$81:$J$164,F20,$R$81:$R$164)=0,F20<TODAY()),"무지출",SUMIF($J$81:$J$164,F20,$R$81:$R$164))) -> 무지출 | G21: =IF(MONTH(G20)<>$A$2,"",IF(AND(SUMIF($J$81:$J$164,G20,$R$81:$R$164)=0,G20<TODAY()),"무지출",SUMIF($J$81:$J$164,G20,$R$81:$R$164))) -> 무지출 | H21: =IF(MONTH(H20)<>$A$2,"",IF(AND(SUMIF($J$81:$J$164,H20,$R$81:$R$164)=0,H20<TODAY()),"무지출",SUMIF($J$81:$J$164,H20,$R$81:$R$164))) -> 무지출 | J21: =항목!H$3 -> 반려동물비 | K21: =SUMIF($L$58:$L$300,J21,$R$58:$R$300) -> 0 | L21: =VLOOKUP(J21,예산!$B$41:$N$53,6,FALSE) -> 0 | M21: =L21-K21 -> 0 | N21: =VLOOKUP(J21,'4월'!$J$10:$K$23,2,FALSE) -> 0 | O21: =K21-N21 -> 0
J22: =항목!K$3 -> 문화생활비 | K22: =SUMIF($L$58:$L$300,J22,$R$58:$R$300) -> 0 | L22: =VLOOKUP(J22,예산!$B$41:$N$53,6,FALSE) -> 0 | M22: =L22-K22 -> 0 | N22: =VLOOKUP(J22,'4월'!$J$10:$K$23,2,FALSE) -> 0 | O22: =K22-N22 -> 0
B23: =B11+28 -> 45802 | C23: =C11+28 -> 45803 | D23: =D11+28 -> 45804 | E23: =E11+28 -> 45805 | F23: =F11+28 -> 45806 | G23: =G11+28 -> 45807 | H23: =H11+28 -> 45808 | J23: =항목!Q$3 -> 추가항목 | K23: =SUMIF($L$58:$L$300,J23,$R$58:$R$300) -> 0 | L23: =VLOOKUP(J23,예산!$B$41:$N$53,6,FALSE) -> 0 | M23: =L23-K23 -> 0 | N23: =VLOOKUP(J23,'4월'!$J$10:$K$23,2,FALSE) -> 0 | O23: =K23-N23 -> 0
B24: =IF(MONTH(B23)<>$A$2,"",IF(AND(SUMIF($J$81:$J$164,B23,$R$81:$R$164)=0,B23<TODAY()),"무지출",SUMIF($J$81:$J$164,B23,$R$81:$R$164))) -> 무지출 | C24: =IF(MONTH(C23)<>$A$2,"",IF(AND(SUMIF($J$81:$J$164,C23,$R$81:$R$164)=0,C23<TODAY()),"무지출",SUMIF($J$81:$J$164,C23,$R$81:$R$164))) -> 무지출 | D24: =IF(MONTH(D23)<>$A$2,"",IF(AND(SUMIF($J$81:$J$164,D23,$R$81:$R$164)=0,D23<TODAY()),"무지출",SUMIF($J$81:$J$164,D23,$R$81:$R$164))) -> 무지출 | E24: =IF(MONTH(E23)<>$A$2,"",IF(AND(SUMIF($J$81:$J$164,E23,$R$81:$R$164)=0,E23<TODAY()),"무지출",SUMIF($J$81:$J$164,E23,$R$81:$R$164))) -> 무지출 | F24: =IF(MONTH(F23)<>$A$2,"",IF(AND(SUMIF($J$81:$J$164,F23,$R$81:$R$164)=0,F23<TODAY()),"무지출",SUMIF($J$81:$J$164,F23,$R$81:$R$164))) -> 무지출 | G24: =IF(MONTH(G23)<>$A$2,"",IF(AND(SUMIF($J$81:$J$164,G23,$R$81:$R$164)=0,G23<TODAY()),"무지출",SUMIF($J$81:$J$164,G23,$R$81:$R$164))) -> 무지출 | H24: =IF(MONTH(H23)<>$A$2,"",IF(AND(SUMIF($J$81:$J$164,H23,$R$81:$R$164)=0,H23<TODAY()),"무지출",SUMIF($J$81:$J$164,H23,$R$81:$R$164))) -> 무지출
J25: MEMO
B26: =B11+35 -> 45809 | C26: =C11+35 -> 45810 | D26: =D11+35 -> 45811 | E26: =E11+35 -> 45812 | F26: =F11+35 -> 45813 | G26: =G11+35 -> 45814 | H26: =H11+35 -> 45815
