Workbook
Name _10_결제분류: 항목!$H$21:$K$21
Name _10_결제분류상세: 항목!$H$22:$K$36
Name _10_결제항목: OFFSET(항목!$B$4,0,0,COUNTA(항목!$B$4:$B$18),1)
Name _10_계좌종류: OFFSET(항목!$D$22,0,0,COUNTA(항목!$D$22:$D$36),1)
Name _10_대상분류: OFFSET(항목!$C$22,0,0,COUNTA(항목!$C$22:$C$36),1)
Name _10_은행종류: OFFSET(항목!$B$22,0,0,COUNTA(항목!$B$22:$B$36),1)
Name _20_대분류: 항목!$C$3:$Q$3
Name _20_대분류항목: OFFSET(항목!$C$3,0,0,1,COUNTA(항목!$C$3:$Q$3))
Name _20_소분류: 항목!$C$4:$Q$18
Name _21_수입: OFFSET(항목!$C$4,0,0,COUNTA(항목!$C$4:$C$18),1)
Name _22_저축성지출: OFFSET(항목!$D$4,0,0,COUNTA(항목!$D$4:$D$18),1)
Name _23_경조사회비: OFFSET(항목!$P$4,0,0,COUNTA(항목!$P$4:$P$18),1)
Name _23E_식비: OFFSET(항목!$E$4,0,0,COUNTA(항목!$E$4:$E$18),1)
Name _23F_주거비: OFFSET(항목!$F$4,0,0,COUNTA(항목!$F$4:$F$18),1)
Name _23G_생활용품비: OFFSET(항목!$G$4,0,0,COUNTA(항목!$G$4:$G$18),1)
Name _23H_반려동물비: OFFSET(항목!$H$4,0,0,COUNTA(항목!$H$4:$H$18),1)
Name _23I_의류미용비: OFFSET(항목!$I$4,0,0,COUNTA(항목!$I$4:$I$18),1)
Name _23J_교육계발비: OFFSET(항목!$J$4,0,0,COUNTA(항목!$J$4:$J$18),1)
Name _23K_문화생활비: OFFSET(항목!$K$4,0,0,COUNTA(항목!$K$4:$K$18),1)
Name _23L_의료비: OFFSET(항목!$L$4,0,0,COUNTA(항목!$L$4:$L$18),1)
Name _23M_유류교통비: OFFSET(항목!$M$4,0,0,COUNTA(항목!$M$4:$M$18),1)
Name _23N_통신비: OFFSET(항목!$N$4,0,0,COUNTA(항목!$N$4:$N$18),1)
Name _23P_용돈지출: OFFSET(항목!$P$4,0,0,COUNTA(항목!$P$4:$P$18),1)

Sheet 메인
B1: ="▶ "&$R$3&"년 가계부" -> ▶ 2025년 가계부
D3: =$R$3&"년 재무목표" -> 2025년 재무목표 | J3: =$R$3&"년 재무일정" -> 2025년 재무일정 | R3: 2025
B4: ▷ 항목설정 | D4: 매월 저축 및 투자 250만원 이상 | J4: 매년 1월 신용카드 연회비 지출
B5: ▷ 수입 | D5: 추가 종자돈 3천만원 모으기 | J5: 1월 7월 부가세, 4월, 10월 예정고지
B6: └ 연간 항목별 수입
B7: ▷ 지출 | Q7: 월목표저축액 | R7: 2500000
B8: └ 연간 카드별 지출 | Q8: 월목표저축률 | R8: 0.6
B9: └ 연간 항목별 지출
B10: └ 연간 세부항목별 지출 | D10: 월별 리포트
B11: ▷ 예산 | E11: 1 | F11: 2 | G11: 3 | H11: 4 | I11: 5 | J11: 6 | K11: 7 | L11: 8 | M11: 9 | N11: 10 | O11: 11 | P11: 12 | Q11: 계 | R11: 평균
B12: ▷ 결산 | D12: 이월 | E12: 1000000 | F12: =SUMIF('2월'!$D$33:$D$145,"이월",'2월'!$H$33:$H$145) -> 0 | G12: =SUMIF('3월'!$D$33:$D$145,"이월",'3월'!$H$33:$H$145) -> 0 | H12: =SUMIF('4월'!$D$34:$D$145,"이월",'4월'!$H$34:$H$145) -> 0 | I12: =SUMIF('5월'!$D$33:$D$145,"이월",'5월'!$H$33:$H$145) -> 0 | J12: =SUMIF('6월'!$D$33:$D$145,"이월",'6월'!$H$33:$H$145) -> 0 | K12: =SUMIF('7월'!$D$33:$D$145,"이월",'7월'!$H$33:$H$145) -> 0 | L12: =SUMIF('8월'!$D$33:$D$145,"이월",'8월'!$H$33:$H$145) -> 0 | M12: =SUMIF('9월'!$D$33:$D$145,"이월",'9월'!$H$33:$H$145) -> 0 | N12: =SUMIF('10월'!$D$33:$D$145,"이월",'10월'!$H$33:$H$145) -> 0 | O12: =SUMIF('11월'!$D$33:$D$145,"이월",'11월'!$H$33:$H$145) -> 0 | P12: =SUMIF('12월'!$D$33:$D$145,"이월",'12월'!$H$33:$H$145) -> 0 | Q12: =SUM(E12:P12) -> 1000000 | R12: =SUM(E12:P12)/COUNTIF(E12:P12,"<>0") -> 1000000
B13: ▷ 자산현황 | D13: 순수입 | E13: =연간_항목별수입!C20 -> 0 | F13: =연간_항목별수입!D20 -> 0 | G13: =연간_항목별수입!E20 -> 0 | H13: =연간_항목별수입!F20 -> 0 | I13: =연간_항목별수입!G20 -> 0 | J13: =연간_항목별수입!H20 -> 0 | K13: =연간_항목별수입!I20 -> 0 | L13: =연간_항목별수입!J20 -> 0 | ... P13: =연간_항목별수입!N20 -> 0 | Q13: =SUM(E13:P13) -> 0 | R13: =SUM(E13:P13)/COUNTIF(E13:P13,"<>0") -> #DIV/0!
D14: 총지출 | E14: =연간_항목별지출!C19 -> 0 | F14: =연간_항목별지출!D19 -> 0 | G14: =연간_항목별지출!E19 -> 0 | H14: =연간_항목별지출!F19 -> 0 | I14: =연간_항목별지출!G19 -> 0 | J14: =연간_항목별지출!H19 -> 0 | K14: =연간_항목별지출!I19 -> 0 | L14: =연간_항목별지출!J19 -> 0 | ... P14: =연간_항목별지출!N19 -> 0 | Q14: =SUM(E14:P14) -> 0 | R14: =SUM(E14:P14)/COUNTIF(E14:P14,"<>0") -> #DIV/0!
D15: 저축성지출 | E15: =연간_항목별지출!C4 -> 0 | F15: =연간_항목별지출!D4 -> 0 | G15: =연간_항목별지출!E4 -> 0 | H15: =연간_항목별지출!F4 -> 0 | I15: =연간_항목별지출!G4 -> 0 | J15: =연간_항목별지출!H4 -> 0 | K15: =연간_항목별지출!I4 -> 0 | L15: =연간_항목별지출!J4 -> 0 | ... P15: =연간_항목별지출!N4 -> 0 | Q15: =SUM(E15:P15) -> 0 | R15: =SUM(E15:P15)/COUNTIF(E15:P15,"<>0") -> #DIV/0!
D16: 소비성지출 | E16: =연간_항목별지출!C5 -> 0 | F16: =연간_항목별지출!D5 -> 0 | G16: =연간_항목별지출!E5 -> 0 | H16: =연간_항목별지출!F5 -> 0 | I16: =연간_항목별지출!G5 -> 0 | J16: =연간_항목별지출!H5 -> 0 | K16: =연간_항목별지출!I5 -> 0 | L16: =연간_항목별지출!J5 -> 0 | ... P16: =연간_항목별지출!N5 -> 0 | Q16: =SUM(E16:P16) -> 0 | R16: =SUM(E16:P16)/COUNTIF(E16:P16,"<>0") -> #DIV/0!
D17: 잔액 | E17: =E12+E13-E14 -> 1000000 | F17: =F12+F13-F14 -> 0 | G17: =G12+G13-G14 -> 0 | H17: =H12+H13-H14 -> 0 | I17: =I12+I13-I14 -> 0 | J17: =J12+J13-J14 -> 0 | K17: =K12+K13-K14 -> 0 | L17: =L12+L13-L14 -> 0 | ... P17: =P12+P13-P14 -> 0 | Q17: =SUM(E17:P17) -> 1000000 | R17: =SUM(E17:P17)/COUNTIF(E17:P17,"<>0") -> 1000000
D18: 이월금 제외 | E18: =E17-F12 -> 1000000 | F18: =F17-G12 -> 0 | G18: =G17-H12 -> 0 | H18: =H17-I12 -> 0 | I18: =I17-J12 -> 0 | J18: =J17-K12 -> 0 | K18: =K17-L12 -> 0 | L18: =L17-M12 -> 0 | ... O18: =O17-P12 -> 0 | P18: 0 | Q18: =SUM(E18:P18) -> 1000000
D19: 저축비율 | E19: =IF(E14=0,"",E15/E14) | F19: =IF(F14=0,"",F15/F14) | G19: =IF(G14=0,"",G15/G14) | H19: =IF(H14=0,"",H15/H14) | I19: =IF(I14=0,"",I15/I14) | J19: =IF(J14=0,"",J15/J14) | K19: =IF(K14=0,"",K15/K14) | L19: =IF(L14=0,"",L15/L14) | ... Q19: =IF(Q14=0,"",Q15/Q14)
D20: 소비비율 | E20: =IF(E14=0,"",E16/E14) | F20: =IF(F14=0,"",F16/F14) | G20: =IF(G14=0,"",G16/G14) | H20: =IF(H14=0,"",H16/H14) | I20: =IF(I14=0,"",I16/I14) | J20: =IF(J14=0,"",J16/J14) | K20: =IF(K14=0,"",K16/K14) | L20: =IF(L14=0,"",L16/L14) | ... Q20: =IF(Q14=0,"",Q16/Q14)
D21: 계 | E21: =IF(E19="","",SUM(E19:E20)) | F21: =IF(F19="","",SUM(F19:F20)) | G21: =IF(G19="","",SUM(G19:G20)) | H21: =IF(H19="","",SUM(H19:H20)) | I21: =IF(I19="","",SUM(I19:I20)) | J21: =IF(J19="","",SUM(J19:J20)) | K21: =IF(K19="","",SUM(K19:K20)) | L21: =IF(L19="","",SUM(L19:L20)) | ... Q21: =IF(Q19="","",SUM(Q19:Q20))
D23: 월별 순수입 및 총지출

Sheet 항목
B1: ◀ 항목
B3: 결제구분 | C3: 수입 | D3: 저축성지출 | E3: 식비 | F3: 주거비 | G3: 생활용품비 | H3: 반려동물비 | I3: 의류미용비 | J3: 교육비 | K3: 문화생활비 | L3: 의료비 | M3: 유류교통비 | N3: 통신비 | O3: 경조사회비 | P3: 용돈 | Q3: 추가항목
B4: 현금 | C4: 이월 | D4: 예/적금 | E4: 시장/마트 | F4: 재산세 | G4: 가구/가전 | H4: 사료/간식 | I4: 의류 | J4: 학교 | K4: 영화 | L4: 병원 | M4: 자동차보험 | N4: 핸드폰 | O4: 축의금 | P4: 부모님 용돈 | Q4: 필요한 것
B5: 계좌이체 | C5: 급여 | D5: 주택청약 | E5: 외식/배달 | F5: 월세 | G5: 주방/욕실 | H5: 용품/장난감 | I5: 패션잡화 | J5: 학원 | K5: 여가 | L5: 의약품 | M5: 자동차할부 | N5: 인터넷 | O5: 조의금 | P5: 첫째 용돈 | Q5: 추가하세요
B6: 신용카드 | C6: 수당 | D6: 퇴직연금 | E6: 간식 | F6: 주담대 이자 | G6: 오피스/문구 | H6: 병원/접종 | I6: 세탁비 | J6: 도서 | K6: 여행 | L6: 영양제 | M6: 자동차세 | N6: IPTV | O6: 기부금 | P6: 기타 용돈
B7: 체크카드 | C7: 상여 | D7: 비상금 | E7: 술/회식 | F7: 주담대 원금 | G7: 멤버십 | H7: 미용 | I7: 기타 의류 | J7: 강의 | K7: OTT | L7: 보험료 | M7: 유류비/충전비 | N7: 우편/택배 | O7: 모임회비
C8: 투자수익 | D8: 투자 | E8: 커피숍 | F8: 관리비 | G8: 기타 생활용품 | H8: 기타 반려동물 | I8: 화장품 | J8: 기타 교육 | K8: 기타 문화생활 | L8: 기타 의료비 | M8: 수리비 | N8: 기타 통신 | O8: 선물
C9: 이자 | D9: 기타 저축 | E9: 기타 식비 | F9: 수도세 | G9: 기타 잡지출 | I9: 미용실 | M9: 톨비/하이패스 | O9: 기타 경조사
C10: 부수익 | F10: 전기세 | I10: 기타 미용 | M10: 주차비
C11: 처분소득 | F11: 가스비 | M11: 버스/지하철
C12: 기타 수입 | F12: 기타 주거비 | M12: 택시
M13: 기차
M14: 항공
M15: 기타 교통
B21: 은행 | C21: 대상분류 | D21: 계좌종류 | H21: =B4 -> 현금 | I21: =B5 -> 계좌이체 | J21: =B6 -> 신용카드 | K21: =B7 -> 체크카드
B22: 우리은행 | C22: 본인 | D22: 입출금 | J22: 삼성_텝텝오
B23: 하나은행 | C23: 가족 | D23: 예금 | J23: 롯데_로카
B24: 카카오뱅크 | C24: 친구 | D24: 적금
C25: 데이트 | D25: 증권
C26: 회사 | D26: 기타

Sheet 계좌현황
B1: ◀ 보유 계좌 현황
J3: =항목!$D$22 -> 입출금 | K3: =SUMIF($D$9:$D$43,J3,$K$9:$K$43) -> 0 | L3: =항목!$D$25 -> 증권 | M3: =SUMIF($D$9:$D$43,L3,$K$9:$K$43) -> 0
J4: =항목!$D$23 -> 예금 | K4: =SUMIF($D$9:$D$43,J4,$K$9:$K$43) -> 0 | L4: =항목!$D$26 -> 기타 | M4: =SUMIF($D$9:$D$43,L4,$K$9:$K$43) -> 0
J5: =항목!$D$24 -> 적금 | K5: =SUMIF($D$9:$D$43,J5,$K$9:$K$43) -> 0
L6: 총계 | M6: =SUM($K$3:$K$5,$M$3:$M$4) -> 0
B8: No. | C8: 은행 | D8: 계좌종류 | E8: 기간 | F8: 계좌명 | G8: 계좌번호 | H8: 용도 | I8: 비고 | J8: 가입일 | K8: 현재금액
B9: =ROW(A9)-8 -> 1 | K9: =INDIRECT("'"&L9&"'!c7:c7") -> -2610100 | L9: =MONTH(TODAY())&"월" -> 11월
B10: =ROW(A10)-8 -> 2
B11: =ROW(A11)-8 -> 3
B12: =ROW(A12)-8 -> 4
B13: =ROW(A13)-8 -> 5
B14: =ROW(A14)-8 -> 6
B15: =ROW(A15)-8 -> 7
B16: =ROW(A16)-8 -> 8
B17: =ROW(A17)-8 -> 9
B18: =ROW(A18)-8 -> 10
B19: =ROW(A19)-8 -> 11
B20: =ROW(A20)-8 -> 12
B21: =ROW(A21)-8 -> 13
... B43: =ROW(A43)-8 -> 35

Sheet 예금관리
B1: ◀ 예금관리
M3: 총계 | N3: 원금 | O3: 예상수령액
N4: =SUM($J$7:$J$56) -> 40000000 | O4: =SUM($O$7:$O$56) -> 46548040
B6: No. | C6: 은행 | D6: 예금명 | E6: 가입일 | F6: 만기일 | G6: 기간 | H6: 가입기간 | I6: 남은기간 | J6: 원금 | K6: 이율 | L6: 과세 | M6: 세전이자 | N6: 세후이자 | O6: 예상수령액
B7: 1 | C7: 국민 | D7: 00예금 | E7: 44927 | F7: 46388 | G7: =IF(H7="","",IF(H7>37,"장기",IF(H7<36,"단기","중기"))) -> 장기 | H7: =IF(F7="","",DATEDIF(E7,F7+1,"m")) -> 48 | I7: =IF(F7="","",IF(F7<TODAY(),0,DATEDIF(TODAY(),F7,"m"))) -> 13 | J7: 30000000 | K7: 0.052 | L7: 0.154 | M7: =IF(K7="","",J7*K7*((DATEDIF(E7,F7,"m"))/12)) -> 6240000 | N7: =IF(M7="","",M7-(M7*L7)) -> 5279040 | O7: =IF(N7="","",J7+N7) -> 35279040
B8: 2 | C8: 신한 | D8: 00예금 | E8: 44995 | F8: 46091 | G8: =IF(H8="","",IF(H8>37,"장기",IF(H8<36,"단기","중기"))) -> 중기 | H8: =IF(F8="","",DATEDIF(E8,F8+1,"m")) -> 36 | I8: =IF(F8="","",IF(F8<TODAY(),0,DATEDIF(TODAY(),F8,"m"))) -> 4 | J8: 10000000 | K8: 0.05 | L8: 0.154 | M8: =IF(K8="","",J8*K8*((DATEDIF(E8,F8,"m"))/12)) -> 1500000 | N8: =IF(M8="","",M8-(M8*L8)) -> 1269000 | O8: =IF(N8="","",J8+N8) -> 11269000
B9: 3 | G9: =IF(H9="","",IF(H9>37,"장기",IF(H9<36,"단기","중기"))) | H9: =IF(F9="","",DATEDIF(E9,F9+1,"m")) | I9: =IF(F9="","",IF(F9<TODAY(),0,DATEDIF(TODAY(),F9,"m"))) | M9: =IF(K9="","",J9*K9*((DATEDIF(E9,F9,"m"))/12)) | N9: =IF(M9="","",M9-(M9*L9)) | O9: =IF(N9="","",J9+N9)
B10: 4 | G10: =IF(H10="","",IF(H10>37,"장기",IF(H10<36,"단기","중기"))) | H10: =IF(F10="","",DATEDIF(E10,F10+1,"m")) | I10: =IF(F10="","",IF(F10<TODAY(),0,DATEDIF(TODAY(),F10,"m"))) | M10: =IF(K10="","",J10*K10*((DATEDIF(E10,F10,"m"))/12)) | N10: =IF(M10="","",M10-(M10*L10)) | O10: =IF(N10="","",J10+N10)
B11: 5 | G11: =IF(H11="","",IF(H11>37,"장기",IF(H11<36,"단기","중기"))) | H11: =IF(F11="","",DATEDIF(E11,F11+1,"m")) | I11: =IF(F11="","",IF(F11<TODAY(),0,DATEDIF(TODAY(),F11,"m"))) | M11: =IF(K11="","",J11*K11*((DATEDIF(E11,F11,"m"))/12)) | N11: =IF(M11="","",M11-(M11*L11)) | O11: =IF(N11="","",J11+N11)
B12: 6 | G12: =IF(H12="","",IF(H12>37,"장기",IF(H12<36,"단기","중기"))) | H12: =IF(F12="","",DATEDIF(E12,F12+1,"m")) | I12: =IF(F12="","",IF(F12<TODAY(),0,DATEDIF(TODAY(),F12,"m"))) | M12: =IF(K12="","",J12*K12*((DATEDIF(E12,F12,"m"))/12)) | N12: =IF(M12="","",M12-(M12*L12)) | O12: =IF(N12="","",J12+N12)
B13: 7 | G13: =IF(H13="","",IF(H13>37,"장기",IF(H13<36,"단기","중기"))) | H13: =IF(F13="","",DATEDIF(E13,F13+1,"m")) | I13: =IF(F13="","",IF(F13<TODAY(),0,DATEDIF(TODAY(),F13,"m"))) | M13: =IF(K13="","",J13*K13*((DATEDIF(E13,F13,"m"))/12)) | N13: =IF(M13="","",M13-(M13*L13)) | O13: =IF(N13="","",J13+N13)
B14: 8 | G14: =IF(H14="","",IF(H14>37,"장기",IF(H14<36,"단기","중기"))) | H14: =IF(F14="","",DATEDIF(E14,F14+1,"m")) | I14: =IF(F14="","",IF(F14<TODAY(),0,DATEDIF(TODAY(),F14,"m"))) | M14: =IF(K14="","",J14*K14*((DATEDIF(E14,F14,"m"))/12)) | N14: =IF(M14="","",M14-(M14*L14)) | O14: =IF(N14="","",J14+N14)
B15: 9 | G15: =IF(H15="","",IF(H15>37,"장기",IF(H15<36,"단기","중기"))) | H15: =IF(F15="","",DATEDIF(E15,F15+1,"m")) | I15: =IF(F15="","",IF(F15<TODAY(),0,DATEDIF(TODAY(),F15,"m"))) | M15: =IF(K15="","",J15*K15*((DATEDIF(E15,F15,"m"))/12)) | N15: =IF(M15="","",M15-(M15*L15)) | O15: =IF(N15="","",J15+N15)
B16: 10 | G16: =IF(H16="","",IF(H16>37,"장기",IF(H16<36,"단기","중기"))) | H16: =IF(F16="","",DATEDIF(E16,F16+1,"m")) | I16: =IF(F16="","",IF(F16<TODAY(),0,DATEDIF(TODAY(),F16,"m"))) | M16: =IF(K16="","",J16*K16*((DATEDIF(E16,F16,"m"))/12)) | N16: =IF(M16="","",M16-(M16*L16)) | O16: =IF(N16="","",J16+N16)

Sheet 적금관리
B1: ◀ 적금관리
Q3: 총계 | R3: 현재저축액 | S3: 예상수령액
R4: =SUM($P$7:$P$16) -> 41100000 | S4: =SUM($S$7:$S$16) -> 109284218
B6: No. | C6: 은행 | D6: 적금명 | E6: 비고 | F6: 가입일 | G6: 만기일 | H6: 기간 | I6: 가입기간 | J6: 남은기간 | K6: 월 적립액 | L6: 이율 | M6: 과세 | N6: 방식 | O6: 만기시 원금 | P6: 현재저축액 | Q6: 세전이자 | R6: 세후이자 | S6: 예상수령액
B7: 1 | C7: 국민 | D7: 청년희망적금 | F7: 44594 | G7: 46055 | H7: =IF(I7="","",IF(I7>37,"장기",IF(I7<36,"단기","중기"))) -> 장기 | I7: =IF(G7="","",DATEDIF(F7,G7+1,"m")) -> 48 | J7: =IF(G7="","",IF(G7<TODAY(),0,DATEDIF(TODAY(),G7,"m"))) -> 2 | K7: 500000 | L7: 0.05 | M7: 0 | N7: 단리 | O7: =IF(K7="","",I7*K7) -> 24000000 | P7: =IF(K7="","",(K7*I7)-(K7*J7)) -> 23000000 | Q7: =IF(L7="","",IF(N7="단리",K7*((I7*(I7+1))/2*(L7/12)),IF(N7="월복리",-FV(L7/12,I7,K7,0,1)-K7*I7,""))) -> 2450000 | R7: =IF(Q7="","",Q7-(Q7*M7)) -> 2450000 | S7: =IF(L7="","",O7+R7) -> 26450000
B8: 2 | C8: 국민 | D8: 주택청약 | F8: 40476 | G8: 56912 | H8: =IF(I8="","",IF(I8>37,"장기",IF(I8<36,"단기","중기"))) -> 장기 | I8: =IF(G8="","",DATEDIF(F8,G8+1,"m")) -> 540 | J8: =IF(G8="","",IF(G8<TODAY(),0,DATEDIF(TODAY(),G8,"m"))) -> 359 | K8: 100000 | L8: 0.028 | M8: 0.154 | N8: 단리 | O8: =IF(K8="","",I8*K8) -> 54000000 | P8: =IF(K8="","",(K8*I8)-(K8*J8)) -> 18100000 | Q8: =IF(L8="","",IF(N8="단리",K8*((I8*(I8+1))/2*(L8/12)),IF(N8="월복리",-FV(L8/12,I8,K8,0,1)-K8*I8,""))) -> 34083000 | R8: =IF(Q8="","",Q8-(Q8*M8)) -> 28834218 | S8: =IF(L8="","",O8+R8) -> 82834218
B9: 3 | H9: =IF(I9="","",IF(I9>37,"장기",IF(I9<36,"단기","중기"))) | I9: =IF(G9="","",DATEDIF(F9,G9+1,"m")) | J9: =IF(G9="","",IF(G9<TODAY(),0,DATEDIF(TODAY(),G9,"m"))) | O9: =IF(K9="","",I9*K9) | P9: =IF(K9="","",(K9*I9)-(K9*J9)) | Q9: =IF(L9="","",IF(N9="단리",K9*((I9*(I9+1))/2*(L9/12)),IF(N9="월복리",-FV(L9/12,I9,K9,0,1)-K9*I9,""))) | R9: =IF(Q9="","",Q9-(Q9*M9)) | S9: =IF(L9="","",O9+R9)
B10: 4 | H10: =IF(I10="","",IF(I10>37,"장기",IF(I10<36,"단기","중기"))) | I10: =IF(G10="","",DATEDIF(F10,G10+1,"m")) | J10: =IF(G10="","",IF(G10<TODAY(),0,DATEDIF(TODAY(),G10,"m"))) | O10: =IF(K10="","",I10*K10) | P10: =IF(K10="","",(K10*I10)-(K10*J10)) | Q10: =IF(L10="","",IF(N10="단리",K10*((I10*(I10+1))/2*(L10/12)),IF(N10="월복리",-FV(L10/12,I10,K10,0,1)-K10*I10,""))) | R10: =IF(Q10="","",Q10-(Q10*M10)) | S10: =IF(L10="","",O10+R10)
B11: 5 | H11: =IF(I11="","",IF(I11>37,"장기",IF(I11<36,"단기","중기"))) | I11: =IF(G11="","",DATEDIF(F11,G11+1,"m")) | J11: =IF(G11="","",IF(G11<TODAY(),0,DATEDIF(TODAY(),G11,"m"))) | O11: =IF(K11="","",I11*K11) | P11: =IF(K11="","",(K11*I11)-(K11*J11)) | Q11: =IF(L11="","",IF(N11="단리",K11*((I11*(I11+1))/2*(L11/12)),IF(N11="월복리",-FV(L11/12,I11,K11,0,1)-K11*I11,""))) | R11: =IF(Q11="","",Q11-(Q11*M11)) | S11: =IF(L11="","",O11+R11)
B12: 6 | H12: =IF(I12="","",IF(I12>37,"장기",IF(I12<36,"단기","중기"))) | I12: =IF(G12="","",DATEDIF(F12,G12+1,"m")) | J12: =IF(G12="","",IF(G12<TODAY(),0,DATEDIF(TODAY(),G12,"m"))) | O12: =IF(K12="","",I12*K12) | P12: =IF(K12="","",(K12*I12)-(K12*J12)) | Q12: =IF(L12="","",IF(N12="단리",K12*((I12*(I12+1))/2*(L12/12)),IF(N12="월복리",-FV(L12/12,I12,K12,0,1)-K12*I12,""))) | R12: =IF(Q12="","",Q12-(Q12*M12)) | S12: =IF(L12="","",O12+R12)
B13: 7 | H13: =IF(I13="","",IF(I13>37,"장기",IF(I13<36,"단기","중기"))) | I13: =IF(G13="","",DATEDIF(F13,G13+1,"m")) | J13: =IF(G13="","",IF(G13<TODAY(),0,DATEDIF(TODAY(),G13,"m"))) | O13: =IF(K13="","",I13*K13) | P13: =IF(K13="","",(K13*I13)-(K13*J13)) | Q13: =IF(L13="","",IF(N13="단리",K13*((I13*(I13+1))/2*(L13/12)),IF(N13="월복리",-FV(L13/12,I13,K13,0,1)-K13*I13,""))) | R13: =IF(Q13="","",Q13-(Q13*M13)) | S13: =IF(L13="","",O13+R13)
B14: 8 | H14: =IF(I14="","",IF(I14>37,"장기",IF(I14<36,"단기","중기"))) | I14: =IF(G14="","",DATEDIF(F14,G14+1,"m")) | J14: =IF(G14="","",IF(G14<TODAY(),0,DATEDIF(TODAY(),G14,"m"))) | O14: =IF(K14="","",I14*K14) | P14: =IF(K14="","",(K14*I14)-(K14*J14)) | Q14: =IF(L14="","",IF(N14="단리",K14*((I14*(I14+1))/2*(L14/12)),IF(N14="월복리",-FV(L14/12,I14,K14,0,1)-K14*I14,""))) | R14: =IF(Q14="","",Q14-(Q14*M14)) | S14: =IF(L14="","",O14+R14)
B15: 9 | H15: =IF(I15="","",IF(I15>37,"장기",IF(I15<36,"단기","중기"))) | I15: =IF(G15="","",DATEDIF(F15,G15+1,"m")) | J15: =IF(G15="","",IF(G15<TODAY(),0,DATEDIF(TODAY(),G15,"m"))) | O15: =IF(K15="","",I15*K15) | P15: =IF(K15="","",(K15*I15)-(K15*J15)) | Q15: =IF(L15="","",IF(N15="단리",K15*((I15*(I15+1))/2*(L15/12)),IF(N15="월복리",-FV(L15/12,I15,K15,0,1)-K15*I15,""))) | R15: =IF(Q15="","",Q15-(Q15*M15)) | S15: =IF(L15="","",O15+R15)
B16: 10 | H16: =IF(I16="","",IF(I16>37,"장기",IF(I16<36,"단기","중기"))) | I16: =IF(G16="","",DATEDIF(F16,G16+1,"m")) | J16: =IF(G16="","",IF(G16<TODAY(),0,DATEDIF(TODAY(),G16,"m"))) | O16: =IF(K16="","",I16*K16) | P16: =IF(K16="","",(K16*I16)-(K16*J16)) | Q16: =IF(L16="","",IF(N16="단리",K16*((I16*(I16+1))/2*(L16/12)),IF(N16="월복리",-FV(L16/12,I16,K16,0,1)-K16*I16,""))) | R16: =IF(Q16="","",Q16-(Q16*M16)) | S16: =IF(L16="","",O16+R16)

Sheet 1월
A1: =메인!$R$3 -> 2025 | B1: ◀ 01월 ▶
A2: =메인!$E$11 -> 1
B5: 총 수입 | C5: =SUM($C$32+$C$56) -> 15000 | J5: 이번달 목표 | Q5: 필수지출
B6: 총 지출 | C6: =SUM($K$32+$L$56) -> 2625100 | J6: 무지출 20일 이상 달성하기! | Q6: 00신용 결제 12일 - 잔액 확인
B7: 차액 | C7: =$C$5-$C$6 -> -2610100 | J7: 변동지출 10만원 이하로 쓰기! | Q7: 친구 축의금 내야함!
G8: 무지출 성공 | H8: =COUNTIF(B10:H28,"무지출") -> 29
B9: 변동지출 달력 | J9: 소비성 지출 분석
B10: 일 | C10: 월 | D10: 화 | E10: 수 | F10: 목 | G10: 금 | H10: 토 | J10: 항목 | K10: 지출계 | L10: 예산 | M10: 예산대비 | N10: 전월지출 | O10: 전월대비
B11: =DATE($A$1,$A$2,1)-WEEKDAY(DATE($A$1,$A$2,1))+1 -> 45655 | C11: =B11+1 -> 45656 | D11: =C11+1 -> 45657 | E11: =D11+1 -> 45658 | F11: =E11+1 -> 45659 | G11: =F11+1 -> 45660 | H11: =G11+1 -> 45661 | J11: =항목!E$3 -> 식비 | K11: =SUMIF($N$58:$N$165,J11,$T$58:$T$165) -> 0 | L11: =VLOOKUP(J11,예산!$B$41:$N$53,2,FALSE) -> 50000 | M11: =L11-K11 -> 50000
B12: =IF(MONTH(B11)<>$A$2,"",IF(AND(SUMIF($J$81:$J$165,B11,$T$81:$T$165)=0,B11<TODAY()),"무지출",SUMIF($J$81:$J$165,B11,$T$81:$T$165))) | C12: =IF(MONTH(C11)<>$A$2,"",IF(AND(SUMIF($J$81:$J$165,C11,$T$81:$T$165)=0,C11<TODAY()),"무지출",SUMIF($J$81:$J$165,C11,$T$81:$T$165))) | D12: =IF(MONTH(D11)<>$A$2,"",IF(AND(SUMIF($J$81:$J$165,D11,$T$81:$T$165)=0,D11<TODAY()),"무지출",SUMIF($J$81:$J$165,D11,$T$81:$T$165))) | E12: =IF(MONTH(E11)<>$A$2,"",IF(AND(SUMIF($J$81:$J$165,E11,$T$81:$T$165)=0,E11<TODAY()),"무지출",SUMIF($J$81:$J$165,E11,$T$81:$T$165))) -> 13700 | F12: =IF(MONTH(F11)<>$A$2,"",IF(AND(SUMIF($J$81:$J$165,F11,$T$81:$T$165)=0,F11<TODAY()),"무지출",SUMIF($J$81:$J$165,F11,$T$81:$T$165))) -> 무지출 | G12: =IF(MONTH(G11)<>$A$2,"",IF(AND(SUMIF($J$81:$J$165,G11,$T$81:$T$165)=0,G11<TODAY()),"무지출",SUMIF($J$81:$J$165,G11,$T$81:$T$165))) -> 무지출 | H12: =IF(MONTH(H11)<>$A$2,"",IF(AND(SUMIF($J$81:$J$165,H11,$T$81:$T$165)=0,H11<TODAY()),"무지출",SUMIF($J$81:$J$165,H11,$T$81:$T$165))) -> 무지출 | J12: =항목!F$3 -> 주거비 | K12: =SUMIF($N$58:$N$165,J12,$T$58:$T$165) -> 212000 | L12: =VLOOKUP(J12,예산!$B$41:$N$53,2,FALSE) -> 200000 | M12: =L12-K12 -> -12000
J13: =항목!G$3 -> 생활용품비 | K13: =SUMIF($N$58:$N$165,J13,$T$58:$T$165) -> 0 | L13: =VLOOKUP(J13,예산!$B$41:$N$53,2,FALSE) -> 30000 | M13: =L13-K13 -> 30000
B14: =B11+7 -> 45662 | C14: =C11+7 -> 45663 | D14: =D11+7 -> 45664 | E14: =E11+7 -> 45665 | F14: =F11+7 -> 45666 | G14: =G11+7 -> 45667 | H14: =H11+7 -> 45668 | J14: =항목!H$3 -> 반려동물비 | K14: =SUMIF($N$58:$N$165,J14,$T$58:$T$165) -> 0 | L14: =VLOOKUP(J14,예산!$B$41:$N$53,2,FALSE) -> 10000 | M14: =L14-K14 -> 10000
B15: =IF(MONTH(B14)<>$A$2,"",IF(AND(SUMIF($J$81:$J$165,B14,$T$81:$T$165)=0,B14<TODAY()),"무지출",SUMIF($J$81:$J$165,B14,$T$81:$T$165))) -> 무지출 | C15: =IF(MONTH(C14)<>$A$2,"",IF(AND(SUMIF($J$81:$J$165,C14,$T$81:$T$165)=0,C14<TODAY()),"무지출",SUMIF($J$81:$J$165,C14,$T$81:$T$165))) -> 무지출 | D15: =IF(MONTH(D14)<>$A$2,"",IF(AND(SUMIF($J$81:$J$165,D14,$T$81:$T$165)=0,D14<TODAY()),"무지출",SUMIF($J$81:$J$165,D14,$T$81:$T$165))) -> 무지출 | E15: =IF(MONTH(E14)<>$A$2,"",IF(AND(SUMIF($J$81:$J$165,E14,$T$81:$T$165)=0,E14<TODAY()),"무지출",SUMIF($J$81:$J$165,E14,$T$81:$T$165))) -> 무지출 | F15: =IF(MONTH(F14)<>$A$2,"",IF(AND(SUMIF($J$81:$J$165,F14,$T$81:$T$165)=0,F14<TODAY()),"무지출",SUMIF($J$81:$J$165,F14,$T$81:$T$165))) -> 무지출 | G15: =IF(MONTH(G14)<>$A$2,"",IF(AND(SUMIF($J$81:$J$165,G14,$T$81:$T$165)=0,G14<TODAY()),"무지출",SUMIF($J$81:$J$165,G14,$T$81:$T$165))) -> 무지출 | H15: =IF(MONTH(H14)<>$A$2,"",IF(AND(SUMIF($J$81:$J$165,H14,$T$81:$T$165)=0,H14<TODAY()),"무지출",SUMIF($J$81:$J$165,H14,$T$81:$T$165))) -> 무지출 | J15: =항목!I$3 -> 의류미용비 | K15: =SUMIF($N$58:$N$165,J15,$T$58:$T$165) -> 0 | L15: =VLOOKUP(J15,예산!$B$41:$N$53,2,FALSE) -> 10000 | M15: =L15-K15 -> 10000
J16: =항목!J$3 -> 교육비 | K16: =SUMIF($N$58:$N$165,J16,$T$58:$T$165) -> 0 | L16: =VLOOKUP(J16,예산!$B$41:$N$53,2,FALSE) -> 500000 | M16: =L16-K16 -> 500000
B17: =B11+14 -> 45669 | C17: =C11+14 -> 45670 | D17: =D11+14 -> 45671 | E17: =E11+14 -> 45672 | F17: =F11+14 -> 45673 | G17: =G11+14 -> 45674 | H17: =H11+14 -> 45675 | J17: =항목!K$3 -> 문화생활비 | K17: =SUMIF($N$58:$N$165,J17,$T$58:$T$165) -> 63100 | L17: =VLOOKUP(J17,예산!$B$41:$N$53,2,FALSE) -> 0 | M17: =L17-K17 -> -63100
B18: =IF(MONTH(B17)<>$A$2,"",IF(AND(SUMIF($J$81:$J$165,B17,$T$81:$T$165)=0,B17<TODAY()),"무지출",SUMIF($J$81:$J$165,B17,$T$81:$T$165))) -> 무지출 | C18: =IF(MONTH(C17)<>$A$2,"",IF(AND(SUMIF($J$81:$J$165,C17,$T$81:$T$165)=0,C17<TODAY()),"무지출",SUMIF($J$81:$J$165,C17,$T$81:$T$165))) -> 무지출 | D18: =IF(MONTH(D17)<>$A$2,"",IF(AND(SUMIF($J$81:$J$165,D17,$T$81:$T$165)=0,D17<TODAY()),"무지출",SUMIF($J$81:$J$165,D17,$T$81:$T$165))) -> 무지출 | E18: =IF(MONTH(E17)<>$A$2,"",IF(AND(SUMIF($J$81:$J$165,E17,$T$81:$T$165)=0,E17<TODAY()),"무지출",SUMIF($J$81:$J$165,E17,$T$81:$T$165))) -> 무지출 | F18: =IF(MONTH(F17)<>$A$2,"",IF(AND(SUMIF($J$81:$J$165,F17,$T$81:$T$165)=0,F17<TODAY()),"무지출",SUMIF($J$81:$J$165,F17,$T$81:$T$165))) -> 49400 | G18: =IF(MONTH(G17)<>$A$2,"",IF(AND(SUMIF($J$81:$J$165,G17,$T$81:$T$165)=0,G17<TODAY()),"무지출",SUMIF($J$81:$J$165,G17,$T$81:$T$165))) -> 무지출 | H18: =IF(MONTH(H17)<>$A$2,"",IF(AND(SUMIF($J$81:$J$165,H17,$T$81:$T$165)=0,H17<TODAY()),"무지출",SUMIF($J$81:$J$165,H17,$T$81:$T$165))) -> 무지출 | J18: =항목!L$3 -> 의료비 | K18: =SUMIF($N$58:$N$165,J18,$T$58:$T$165) -> 0 | L18: =VLOOKUP(J18,예산!$B$41:$N$53,2,FALSE) -> 12000 | M18: =L18-K18 -> 12000
J19: =항목!M$3 -> 유류교통비 | K19: =SUMIF($N$58:$N$165,J19,$T$58:$T$165) -> 0 | L19: =VLOOKUP(J19,예산!$B$41:$N$53,2,FALSE) -> 100000 | M19: =L19-K19 -> 100000
B20: =B11+21 -> 45676 | C20: =C11+21 -> 45677 | D20: =D11+21 -> 45678 | E20: =E11+21 -> 45679 | F20: =F11+21 -> 45680 | G20: =G11+21 -> 45681 | H20: =H11+21 -> 45682 | J20: =항목!N$3 -> 통신비 | K20: =SUMIF($N$58:$N$165,J20,$T$58:$T$165) -> 0 | L20: =VLOOKUP(J20,예산!$B$41:$N$53,2,FALSE) -> 50000 | M20: =L20-K20 -> 50000
B21: =IF(MONTH(B20)<>$A$2,"",IF(AND(SUMIF($J$81:$J$165,B20,$T$81:$T$165)=0,B20<TODAY()),"무지출",SUMIF($J$81:$J$165,B20,$T$81:$T$165))) -> 무지출 | C21: =IF(MONTH(C20)<>$A$2,"",IF(AND(SUMIF($J$81:$J$165,C20,$T$81:$T$165)=0,C20<TODAY()),"무지출",SUMIF($J$81:$J$165,C20,$T$81:$T$165))) -> 무지출 | D21: =IF(MONTH(D20)<>$A$2,"",IF(AND(SUMIF($J$81:$J$165,D20,$T$81:$T$165)=0,D20<TODAY()),"무지출",SUMIF($J$81:$J$165,D20,$T$81:$T$165))) -> 무지출 | E21: =IF(MONTH(E20)<>$A$2,"",IF(AND(SUMIF($J$81:$J$165,E20,$T$81:$T$165)=0,E20<TODAY()),"무지출",SUMIF($J$81:$J$165,E20,$T$81:$T$165))) -> 무지출 | F21: =IF(MONTH(F20)<>$A$2,"",IF(AND(SUMIF($J$81:$J$165,F20,$T$81:$T$165)=0,F20<TODAY()),"무지출",SUMIF($J$81:$J$165,F20,$T$81:$T$165))) -> 무지출 | G21: =IF(MONTH(G20)<>$A$2,"",IF(AND(SUMIF($J$81:$J$165,G20,$T$81:$T$165)=0,G20<TODAY()),"무지출",SUMIF($J$81:$J$165,G20,$T$81:$T$165))) -> 무지출 | H21: =IF(MONTH(H20)<>$A$2,"",IF(AND(SUMIF($J$81:$J$165,H20,$T$81:$T$165)=0,H20<TODAY()),"무지출",SUMIF($J$81:$J$165,H20,$T$81:$T$165))) -> 무지출 | J21: =항목!O$3 -> 경조사회비 | K21: =SUMIF($N$58:$N$165,J21,$T$58:$T$165) -> 0 | L21: =VLOOKUP(J21,예산!$B$41:$N$53,2,FALSE) -> 50000 | M21: =L21-K21 -> 50000
J22: =항목!P$3 -> 용돈 | K22: =SUMIF($N$58:$N$165,J22,$T$58:$T$165) -> 0 | L22: =VLOOKUP(J22,예산!$B$41:$N$53,2,FALSE) -> 50000 | M22: =L22-K22 -> 50000
B23: =B11+28 -> 45683 | C23: =C11+28 -> 45684 | D23: =D11+28 -> 45685 | E23: =E11+28 -> 45686 | F23: =F11+28 -> 45687 | G23: =G11+28 -> 45688 | H23: =H11+28 -> 45689 | J23: =항목!Q$3 -> 추가항목 | K23: =SUMIF($N$58:$N$165,J23,$T$58:$T$165) -> 0 | L23: =VLOOKUP(J23,예산!$B$41:$N$53,2,FALSE) -> 0 | M23: =L23-K23 -> 0
B24: =IF(MONTH(B23)<>$A$2,"",IF(AND(SUMIF($J$81:$J$165,B23,$T$81:$T$165)=0,B23<TODAY()),"무지출",SUMIF($J$81:$J$165,B23,$T$81:$T$165))) -> 무지출 | C24: =IF(MONTH(C23)<>$A$2,"",IF(AND(SUMIF($J$81:$J$165,C23,$T$81:$T$165)=0,C23<TODAY()),"무지출",SUMIF($J$81:$J$165,C23,$T$81:$T$165))) -> 무지출 | D24: =IF(MONTH(D23)<>$A$2,"",IF(AND(SUMIF($J$81:$J$165,D23,$T$81:$T$165)=0,D23<TODAY()),"무지출",SUMIF($J$81:$J$165,D23,$T$81:$T$165))) -> 무지출 | E24: =IF(MONTH(E23)<>$A$2,"",IF(AND(SUMIF($J$81:$J$165,E23,$T$81:$T$165)=0,E23<TODAY()),"무지출",SUMIF($J$81:$J$165,E23,$T$81:$T$165))) -> 무지출 | F24: =IF(MONTH(F23)<>$A$2,"",IF(AND(SUMIF($J$81:$J$165,F23,$T$81:$T$165)=0,F23<TODAY()),"무지출",SUMIF($J$81:$J$165,F23,$T$81:$T$165))) -> 무지출 | G24: =IF(MONTH(G23)<>$A$2,"",IF(AND(SUMIF($J$81:$J$165,G23,$T$81:$T$165)=0,G23<TODAY()),"무지출",SUMIF($J$81:$J$165,G23,$T$81:$T$165))) -> 무지출 | H24: =IF(MONTH(H23)<>$A$2,"",IF(AND(SUMIF($J$81:$J$165,H23,$T$81:$T$165)=0,H23<TODAY()),"무지출",SUMIF($J$81:$J$165,H23,$T$81:$T$165)))
J25: MEMO
B26: =B11+35 -> 45690 | C26: =C11+35 -> 45691 | D26: =D11+35 -> 45692 | E26: =E11+35 -> 45693 | F26: =F11+35 -> 45694 | G26: =G11+35 -> 45695 | H26: =H11+35 -> 45696 | J26: 식비를 예산보다 조금 많이 썼다. 다음달에는 냉장고 파먹기를 해서 한끼만큼 식비를 줄여야겠다.
B27: =IF(MONTH(B26)<>$A$2,"",IF(AND(SUMIF($J$81:$J$165,B26,$T$81:$T$165)=0,B26<TODAY()),"무지출",SUMIF($J$81:$J$165,B26,$T$81:$T$165))) | C27: =IF(MONTH(C26)<>$A$2,"",IF(AND(SUMIF($J$81:$J$165,C26,$T$81:$T$165)=0,C26<TODAY()),"무지출",SUMIF($J$81:$J$165,C26,$T$81:$T$165))) | D27: =IF(MONTH(D26)<>$A$2,"",IF(AND(SUMIF($J$81:$J$165,D26,$T$81:$T$165)=0,D26<TODAY()),"무지출",SUMIF($J$81:$J$165,D26,$T$81:$T$165))) | E27: =IF(MONTH(E26)<>$A$2,"",IF(AND(SUMIF($J$81:$J$165,E26,$T$81:$T$165)=0,E26<TODAY()),"무지출",SUMIF($J$81:$J$165,E26,$T$81:$T$165))) | F27: =IF(MONTH(F26)<>$A$2,"",IF(AND(SUMIF($J$81:$J$165,F26,$T$81:$T$165)=0,F26<TODAY()),"무지출",SUMIF($J$81:$J$165,F26,$T$81:$T$165))) | G27: =IF(MONTH(G26)<>$A$2,"",IF(AND(SUMIF($J$81:$J$165,G26,$T$81:$T$165)=0,G26<TODAY()),"무지출",SUMIF($J$81:$J$165,G26,$T$81:$T$165))) | H27: =IF(MONTH(H26)<>$A$2,"",IF(AND(SUMIF($J$81:$J$165,H26,$T$81:$T$165)=0,H26<TODAY()),"무지출",SUMIF($J$81:$J$165,H26,$T$81:$T$165))) | J27: 지난달 예산에서는 생각못한 축의금 지출이 있었지만 비상금에서 쓰지 않고 다른 지출을 줄였다! 칭찬!
B30: 수입 | J30: 지출
B32: 고정수입 | C32: =SUM($H$34:$H$53) -> 0 | J32: 저축성지출 | K32: =SUM($T$34:$T$53) -> 2350000
B33: 날짜 | C33: 대상분류 | D33: 대분류 | E33: 소분류 | F33: 내용 | H33: 금액 | J33: 날짜 | K33: 대상분류 | L33: 결제분류 | M33: 결제상세 | N33: 대분류 | O33: 소분류 | P33: 지출 내용 | R33: 결제금액 | S33: 할인 | T33: 실지출 | U33: 비고
B34: 45658 | C34: 본인 | D34: 수입 | E34: 급여 | F34: 월급 | J34: 45658 | K34: 본인 | L34: 신용카드 | M34: 삼성_텝텝오 | N34: 저축성지출 | O34: 예/적금 | P34: 적금 | R34: 500000 | S34: 0 | T34: =IF(R34="","",R34-S34) -> 500000 | U34: 매월 5일 출금
J35: 45658 | K35: 본인 | L35: 신용카드 | M35: 삼성_텝텝오 | N35: 저축성지출 | O35: 퇴직연금 | P35: 개인 연금 | R35: 250000 | S35: 0 | T35: =IF(R35="","",R35-S35) -> 250000
J36: 45658 | K36: 본인 | L36: 신용카드 | M36: 삼성_텝텝오 | N36: 저축성지출 | O36: 주택청약 | P36: 주택청약 | R36: 100000 | S36: 0 | T36: =IF(R36="","",R36-S36) -> 100000
J37: 45658 | K37: 본인 | L37: 신용카드 | M37: 삼성_텝텝오 | N37: 저축성지출 | O37: 비상금 | P37: 비상금 | R37: 1500000 | S37: 0 | T37: =IF(R37="","",R37-S37) -> 1500000
T38: =IF(R38="","",R38-S38)
T39: =IF(R39="","",R39-S39)
T40: =IF(R40="","",R40-S40)
T41: =IF(R41="","",R41-S41)
T42: =IF(R42="","",R42-S42)
T43: =IF(R43="","",R43-S43)
T44: =IF(R44="","",R44-S44)
T45: =IF(R45="","",R45-S45)
...

Sheet 2월
A1: =메인!$R$3 -> 2025 | B1: ◀ 02월 ▶
A2: =메인!$F$11 -> 2
B5: 총 수입 | C5: =SUM($C$32+$C$56) -> 15000 | J5: ='1월'!J5 -> 이번달 목표 | Q5: 필수지출
B6: 총 지출 | C6: =SUM($K$32+$L$56) -> 2625100
B7: 차액 | C7: =$C$5-$C$6 -> -2610100
G8: 무지출 성공 | H8: =COUNTIF(B10:H28,"무지출") -> 28
B9: 변동지출 달력 | J9: 소비성 지출 분석
B10: 일 | C10: 월 | D10: 화 | E10: 수 | F10: 목 | G10: 금 | H10: 토 | J10: 항목 | K10: 지출계 | L10: 예산 | M10: 예산대비 | N10: 전월지출 | O10: 전월대비
B11: =DATE($A$1,$A$2,1)-WEEKDAY(DATE($A$1,$A$2,1))+1 -> 45683 | C11: =B11+1 -> 45684 | D11: =C11+1 -> 45685 | E11: =D11+1 -> 45686 | F11: =E11+1 -> 45687 | G11: =F11+1 -> 45688 | H11: =G11+1 -> 45689 | J11: =항목!E$3 -> 식비 | K11: =SUMIF($N$58:$N$165,J11,$T$58:$T$165) -> 0 | L11: =VLOOKUP(J11,예산!$B$41:$N$53,3,FALSE) -> 0 | M11: =L11-K11 -> 0 | N11: =VLOOKUP(J11,'1월'!$J$10:$K$23,2,FALSE) -> 0 | O11: =K11-N11 -> 0
B12: =IF(MONTH(B11)<>$A$2,"",IF(AND(SUMIF($J$81:$J$145,B11,$T$81:$T$145)=0,B11<TODAY()),"무지출",SUMIF($J$81:$J$145,B11,$T$81:$T$145))) | C12: =IF(MONTH(C11)<>$A$2,"",IF(AND(SUMIF($J$81:$J$145,C11,$T$81:$T$145)=0,C11<TODAY()),"무지출",SUMIF($J$81:$J$145,C11,$T$81:$T$145))) | D12: =IF(MONTH(D11)<>$A$2,"",IF(AND(SUMIF($J$81:$J$145,D11,$T$81:$T$145)=0,D11<TODAY()),"무지출",SUMIF($J$81:$J$145,D11,$T$81:$T$145))) | E12: =IF(MONTH(E11)<>$A$2,"",IF(AND(SUMIF($J$81:$J$145,E11,$T$81:$T$145)=0,E11<TODAY()),"무지출",SUMIF($J$81:$J$145,E11,$T$81:$T$145))) | F12: =IF(MONTH(F11)<>$A$2,"",IF(AND(SUMIF($J$81:$J$145,F11,$T$81:$T$145)=0,F11<TODAY()),"무지출",SUMIF($J$81:$J$145,F11,$T$81:$T$145))) | G12: =IF(MONTH(G11)<>$A$2,"",IF(AND(SUMIF($J$81:$J$145,G11,$T$81:$T$145)=0,G11<TODAY()),"무지출",SUMIF($J$81:$J$145,G11,$T$81:$T$145))) | H12: =IF(MONTH(H11)<>$A$2,"",IF(AND(SUMIF($J$81:$J$145,H11,$T$81:$T$145)=0,H11<TODAY()),"무지출",SUMIF($J$81:$J$145,H11,$T$81:$T$145))) -> 무지출 | J12: =항목!F$3 -> 주거비 | K12: =SUMIF($N$58:$N$165,J12,$T$58:$T$165) -> 212000 | L12: =VLOOKUP(J12,예산!$B$41:$N$53,3,FALSE) -> 0 | M12: =L12-K12 -> -212000 | N12: =VLOOKUP(J12,'1월'!$J$10:$K$23,2,FALSE) -> 212000 | O12: =K12-N12 -> 0
J13: =항목!G$3 -> 생활용품비 | K13: =SUMIF($N$58:$N$165,J13,$T$58:$T$165) -> 0 | L13: =VLOOKUP(J13,예산!$B$41:$N$53,3,FALSE) -> 0 | M13: =L13-K13 -> 0 | N13: =VLOOKUP(J13,'1월'!$J$10:$K$23,2,FALSE) -> 0 | O13: =K13-N13 -> 0
B14: =B11+7 -> 45690 | C14: =C11+7 -> 45691 | D14: =D11+7 -> 45692 | E14: =E11+7 -> 45693 | F14: =F11+7 -> 45694 | G14: =G11+7 -> 45695 | H14: =H11+7 -> 45696 | J14: =항목!H$3 -> 반려동물비 | K14: =SUMIF($N$58:$N$165,J14,$T$58:$T$165) -> 0 | L14: =VLOOKUP(J14,예산!$B$41:$N$53,3,FALSE) -> 0 | M14: =L14-K14 -> 0 | N14: =VLOOKUP(J14,'1월'!$J$10:$K$23,2,FALSE) -> 0 | O14: =K14-N14 -> 0
B15: =IF(MONTH(B14)<>$A$2,"",IF(AND(SUMIF($J$81:$J$145,B14,$T$81:$T$145)=0,B14<TODAY()),"무지출",SUMIF($J$81:$J$145,B14,$T$81:$T$145))) -> 무지출 | C15: =IF(MONTH(C14)<>$A$2,"",IF(AND(SUMIF($J$81:$J$145,C14,$T$81:$T$145)=0,C14<TODAY()),"무지출",SUMIF($J$81:$J$145,C14,$T$81:$T$145))) -> 무지출 | D15: =IF(MONTH(D14)<>$A$2,"",IF(AND(SUMIF($J$81:$J$145,D14,$T$81:$T$145)=0,D14<TODAY()),"무지출",SUMIF($J$81:$J$145,D14,$T$81:$T$145))) -> 무지출 | E15: =IF(MONTH(E14)<>$A$2,"",IF(AND(SUMIF($J$81:$J$145,E14,$T$81:$T$145)=0,E14<TODAY()),"무지출",SUMIF($J$81:$J$145,E14,$T$81:$T$145))) -> 무지출 | F15: =IF(MONTH(F14)<>$A$2,"",IF(AND(SUMIF($J$81:$J$145,F14,$T$81:$T$145)=0,F14<TODAY()),"무지출",SUMIF($J$81:$J$145,F14,$T$81:$T$145))) -> 무지출 | G15: =IF(MONTH(G14)<>$A$2,"",IF(AND(SUMIF($J$81:$J$145,G14,$T$81:$T$145)=0,G14<TODAY()),"무지출",SUMIF($J$81:$J$145,G14,$T$81:$T$145))) -> 무지출 | H15: =IF(MONTH(H14)<>$A$2,"",IF(AND(SUMIF($J$81:$J$145,H14,$T$81:$T$145)=0,H14<TODAY()),"무지출",SUMIF($J$81:$J$145,H14,$T$81:$T$145))) -> 무지출 | J15: =항목!I$3 -> 의류미용비 | K15: =SUMIF($N$58:$N$165,J15,$T$58:$T$165) -> 0 | L15: =VLOOKUP(J15,예산!$B$41:$N$53,3,FALSE) -> 0 | M15: =L15-K15 -> 0 | N15: =VLOOKUP(J15,'1월'!$J$10:$K$23,2,FALSE) -> 0 | O15: =K15-N15 -> 0
J16: =항목!J$3 -> 교육비 | K16: =SUMIF($N$58:$N$165,J16,$T$58:$T$165) -> 0 | L16: =VLOOKUP(J16,예산!$B$41:$N$53,3,FALSE) -> 0 | M16: =L16-K16 -> 0 | N16: =VLOOKUP(J16,'1월'!$J$10:$K$23,2,FALSE) -> 0 | O16: =K16-N16 -> 0
B17: =B11+14 -> 45697 | C17: =C11+14 -> 45698 | D17: =D11+14 -> 45699 | E17: =E11+14 -> 45700 | F17: =F11+14 -> 45701 | G17: =G11+14 -> 45702 | H17: =H11+14 -> 45703 | J17: =항목!K$3 -> 문화생활비 | K17: =SUMIF($N$58:$N$165,J17,$T$58:$T$165) -> 63100 | L17: =VLOOKUP(J17,예산!$B$41:$N$53,3,FALSE) -> 0 | M17: =L17-K17 -> -63100 | N17: =VLOOKUP(J17,'1월'!$J$10:$K$23,2,FALSE) -> 63100 | O17: =K17-N17 -> 0
B18: =IF(MONTH(B17)<>$A$2,"",IF(AND(SUMIF($J$81:$J$145,B17,$T$81:$T$145)=0,B17<TODAY()),"무지출",SUMIF($J$81:$J$145,B17,$T$81:$T$145))) -> 무지출 | C18: =IF(MONTH(C17)<>$A$2,"",IF(AND(SUMIF($J$81:$J$145,C17,$T$81:$T$145)=0,C17<TODAY()),"무지출",SUMIF($J$81:$J$145,C17,$T$81:$T$145))) -> 무지출 | D18: =IF(MONTH(D17)<>$A$2,"",IF(AND(SUMIF($J$81:$J$145,D17,$T$81:$T$145)=0,D17<TODAY()),"무지출",SUMIF($J$81:$J$145,D17,$T$81:$T$145))) -> 무지출 | E18: =IF(MONTH(E17)<>$A$2,"",IF(AND(SUMIF($J$81:$J$145,E17,$T$81:$T$145)=0,E17<TODAY()),"무지출",SUMIF($J$81:$J$145,E17,$T$81:$T$145))) -> 무지출 | F18: =IF(MONTH(F17)<>$A$2,"",IF(AND(SUMIF($J$81:$J$145,F17,$T$81:$T$145)=0,F17<TODAY()),"무지출",SUMIF($J$81:$J$145,F17,$T$81:$T$145))) -> 무지출 | G18: =IF(MONTH(G17)<>$A$2,"",IF(AND(SUMIF($J$81:$J$145,G17,$T$81:$T$145)=0,G17<TODAY()),"무지출",SUMIF($J$81:$J$145,G17,$T$81:$T$145))) -> 무지출 | H18: =IF(MONTH(H17)<>$A$2,"",IF(AND(SUMIF($J$81:$J$145,H17,$T$81:$T$145)=0,H17<TODAY()),"무지출",SUMIF($J$81:$J$145,H17,$T$81:$T$145))) -> 무지출 | J18: =항목!L$3 -> 의료비 | K18: =SUMIF($N$58:$N$165,J18,$T$58:$T$165) -> 0 | L18: =VLOOKUP(J18,예산!$B$41:$N$53,3,FALSE) -> 0 | M18: =L18-K18 -> 0 | N18: =VLOOKUP(J18,'1월'!$J$10:$K$23,2,FALSE) -> 0 | O18: =K18-N18 -> 0
J19: =항목!M$3 -> 유류교통비 | K19: =SUMIF($N$58:$N$165,J19,$T$58:$T$165) -> 0 | L19: =VLOOKUP(J19,예산!$B$41:$N$53,3,FALSE) -> 0 | M19: =L19-K19 -> 0 | N19: =VLOOKUP(J19,'1월'!$J$10:$K$23,2,FALSE) -> 0 | O19: =K19-N19 -> 0
B20: =B11+21 -> 45704 | C20: =C11+21 -> 45705 | D20: =D11+21 -> 45706 | E20: =E11+21 -> 45707 | F20: =F11+21 -> 45708 | G20: =G11+21 -> 45709 | H20: =H11+21 -> 45710 | J20: =항목!N$3 -> 통신비 | K20: =SUMIF($N$58:$N$165,J20,$T$58:$T$165) -> 0 | L20: =VLOOKUP(J20,예산!$B$41:$N$53,3,FALSE) -> 0 | M20: =L20-K20 -> 0 | N20: =VLOOKUP(J20,'1월'!$J$10:$K$23,2,FALSE) -> 0 | O20: =K20-N20 -> 0
B21: =IF(MONTH(B20)<>$A$2,"",IF(AND(SUMIF($J$81:$J$145,B20,$T$81:$T$145)=0,B20<TODAY()),"무지출",SUMIF($J$81:$J$145,B20,$T$81:$T$145))) -> 무지출 | C21: =IF(MONTH(C20)<>$A$2,"",IF(AND(SUMIF($J$81:$J$145,C20,$T$81:$T$145)=0,C20<TODAY()),"무지출",SUMIF($J$81:$J$145,C20,$T$81:$T$145))) -> 무지출 | D21: =IF(MONTH(D20)<>$A$2,"",IF(AND(SUMIF($J$81:$J$145,D20,$T$81:$T$145)=0,D20<TODAY()),"무지출",SUMIF($J$81:$J$145,D20,$T$81:$T$145))) -> 무지출 | E21: =IF(MONTH(E20)<>$A$2,"",IF(AND(SUMIF($J$81:$J$145,E20,$T$81:$T$145)=0,E20<TODAY()),"무지출",SUMIF($J$81:$J$145,E20,$T$81:$T$145))) -> 무지출 | F21: =IF(MONTH(F20)<>$A$2,"",IF(AND(SUMIF($J$81:$J$145,F20,$T$81:$T$145)=0,F20<TODAY()),"무지출",SUMIF($J$81:$J$145,F20,$T$81:$T$145))) -> 무지출 | G21: =IF(MONTH(G20)<>$A$2,"",IF(AND(SUMIF($J$81:$J$145,G20,$T$81:$T$145)=0,G20<TODAY()),"무지출",SUMIF($J$81:$J$145,G20,$T$81:$T$145))) -> 무지출 | H21: =IF(MONTH(H20)<>$A$2,"",IF(AND(SUMIF($J$81:$J$145,H20,$T$81:$T$145)=0,H20<TODAY()),"무지출",SUMIF($J$81:$J$145,H20,$T$81:$T$145))) -> 무지출 | J21: =항목!O$3 -> 경조사회비 | K21: =SUMIF($N$58:$N$165,J21,$T$58:$T$165) -> 0 | L21: =VLOOKUP(J21,예산!$B$41:$N$53,3,FALSE) -> 0 | M21: =L21-K21 -> 0 | N21: =VLOOKUP(J21,'1월'!$J$10:$K$23,2,FALSE) -> 0 | O21: =K21-N21 -> 0
J22: =항목!P$3 -> 용돈 | K22: =SUMIF($N$58:$N$165,J22,$T$58:$T$165) -> 0 | L22: =VLOOKUP(J22,예산!$B$41:$N$53,3,FALSE) -> 0 | M22: =L22-K22 -> 0 | N22: =VLOOKUP(J22,'1월'!$J$10:$K$23,2,FALSE) -> 0 | O22: =K22-N22 -> 0
B23: =B11+28 -> 45711 | C23: =C11+28 -> 45712 | D23: =D11+28 -> 45713 | E23: =E11+28 -> 45714 | F23: =F11+28 -> 45715 | G23: =G11+28 -> 45716 | H23: =H11+28 -> 45717 | J23: =항목!Q$3 -> 추가항목 | K23: =SUMIF($N$58:$N$165,J23,$T$58:$T$165) -> 0 | L23: =VLOOKUP(J23,예산!$B$41:$N$53,3,FALSE) -> 0 | M23: =L23-K23 -> 0 | N23: =VLOOKUP(J23,'1월'!$J$10:$K$23,2,FALSE) -> 0 | O23: =K23-N23 -> 0
B24: =IF(MONTH(B23)<>$A$2,"",IF(AND(SUMIF($J$81:$J$145,B23,$T$81:$T$145)=0,B23<TODAY()),"무지출",SUMIF($J$81:$J$145,B23,$T$81:$T$145))) -> 무지출 | C24: =IF(MONTH(C23)<>$A$2,"",IF(AND(SUMIF($J$81:$J$145,C23,$T$81:$T$145)=0,C23<TODAY()),"무지출",SUMIF($J$81:$J$145,C23,$T$81:$T$145))) -> 무지출 | D24: =IF(MONTH(D23)<>$A$2,"",IF(AND(SUMIF($J$81:$J$145,D23,$T$81:$T$145)=0,D23<TODAY()),"무지출",SUMIF($J$81:$J$145,D23,$T$81:$T$145))) -> 무지출 | E24: =IF(MONTH(E23)<>$A$2,"",IF(AND(SUMIF($J$81:$J$145,E23,$T$81:$T$145)=0,E23<TODAY()),"무지출",SUMIF($J$81:$J$145,E23,$T$81:$T$145))) -> 무지출 | F24: =IF(MONTH(F23)<>$A$2,"",IF(AND(SUMIF($J$81:$J$145,F23,$T$81:$T$145)=0,F23<TODAY()),"무지출",SUMIF($J$81:$J$145,F23,$T$81:$T$145))) -> 무지출 | G24: =IF(MONTH(G23)<>$A$2,"",IF(AND(SUMIF($J$81:$J$145,G23,$T$81:$T$145)=0,G23<TODAY()),"무지출",SUMIF($J$81:$J$145,G23,$T$81:$T$145))) -> 무지출 | H24: =IF(MONTH(H23)<>$A$2,"",IF(AND(SUMIF($J$81:$J$145,H23,$T$81:$T$145)=0,H23<TODAY()),"무지출",SUMIF($J$81:$J$145,H23,$T$81:$T$145)))
J25: MEMO
B26: =B11+35 -> 45718 | C26: =C11+35 -> 45719 | D26: =D11+35 -> 45720 | E26: =E11+35 -> 45721 | F26: =F11+35 -> 45722 | G26: =G11+35 -> 45723 | H26: =H11+35 -> 45724
B27: =IF(MONTH(B26)<>$A$2,"",IF(AND(SUMIF($J$81:$J$145,B26,$T$81:$T$145)=0,B26<TODAY()),"무지출",SUMIF($J$81:$J$145,B26,$T$81:$T$145))) | C27: =IF(MONTH(C26)<>$A$2,"",IF(AND(SUMIF($J$81:$J$145,C26,$T$81:$T$145)=0,C26<TODAY()),"무지출",SUMIF($J$81:$J$145,C26,$T$81:$T$145))) | D27: =IF(MONTH(D26)<>$A$2,"",IF(AND(SUMIF($J$81:$J$145,D26,$T$81:$T$145)=0,D26<TODAY()),"무지출",SUMIF($J$81:$J$145,D26,$T$81:$T$145))) | E27: =IF(MONTH(E26)<>$A$2,"",IF(AND(SUMIF($J$81:$J$145,E26,$T$81:$T$145)=0,E26<TODAY()),"무지출",SUMIF($J$81:$J$145,E26,$T$81:$T$145))) | F27: =IF(MONTH(F26)<>$A$2,"",IF(AND(SUMIF($J$81:$J$145,F26,$T$81:$T$145)=0,F26<TODAY()),"무지출",SUMIF($J$81:$J$145,F26,$T$81:$T$145))) | G27: =IF(MONTH(G26)<>$A$2,"",IF(AND(SUMIF($J$81:$J$145,G26,$T$81:$T$145)=0,G26<TODAY()),"무지출",SUMIF($J$81:$J$145,G26,$T$81:$T$145))) | H27: =IF(MONTH(H26)<>$A$2,"",IF(AND(SUMIF($J$81:$J$145,H26,$T$81:$T$145)=0,H26<TODAY()),"무지출",SUMIF($J$81:$J$145,H26,$T$81:$T$145)))
B30: 수입 | J30: 지출
B32: 고정수입 | C32: =SUM($H$34:$H$53) -> 0 | J32: 저축성지출 | K32: =SUM($T$34:$T$53) -> 2350000
B33: 날짜 | C33: 대상분류 | D33: 대분류 | E33: 소분류 | F33: 내용 | H33: 금액 | J33: 날짜 | K33: 대상분류 | L33: 결제분류 | M33: 결제상세 | N33: 대분류 | O33: 소분류 | P33: 지출 내용 | R33: 결제금액 | S33: 할인 | T33: 실지출 | U33: 비고
B34: 45658 | C34: 본인 | D34: 수입 | E34: 급여 | F34: 월급 | J34: 45658 | K34: 본인 | L34: 신용카드 | M34: 삼성_텝텝오 | N34: 저축성지출 | O34: 예/적금 | P34: 적금 | R34: 500000 | S34: 0 | T34: =IF(R34="","",R34-S34) -> 500000 | U34: 매월 5일 출금
J35: 45658 | K35: 본인 | L35: 신용카드 | M35: 삼성_텝텝오 | N35: 저축성지출 | O35: 퇴직연금 | P35: 개인 연금 | R35: 250000 | S35: 0 | T35: =IF(R35="","",R35-S35) -> 250000
J36: 45658 | K36: 본인 | L36: 신용카드 | M36: 삼성_텝텝오 | N36: 저축성지출 | O36: 주택청약 | P36: 주택청약 | R36: 100000 | S36: 0 | T36: =IF(R36="","",R36-S36) -> 100000
J37: 45658 | K37: 본인 | L37: 신용카드 | M37: 삼성_텝텝오 | N37: 저축성지출 | O37: 비상금 | P37: 비상금 | R37: 1500000 | S37: 0 | T37: =IF(R37="","",R37-S37) -> 1500000
T38: =IF(R38="","",R38-S38)
T39: =IF(R39="","",R39-S39)
T40: =IF(R40="","",R40-S40)
T41: =IF(R41="","",R41-S41)
T42: =IF(R42="","",R42-S42)
T43: =IF(R43="","",R43-S43)
T44: =IF(R44="","",R44-S44)
T45: =IF(R45="","",R45-S45)
...

Sheet 3월
A1: =메인!$R$3 -> 2025 | B1: ◀ 03월 ▶
A2: =메인!$G$11 -> 3
B5: 총 수입 | C5: =SUM($C$32+$C$56) -> 15000 | J5: ='1월'!J5 -> 이번달 목표 | P5: 필수지출
B6: 총 지출 | C6: =SUM($K$32+$L$56) -> 2625100
B7: 차액 | C7: =$C$5-$C$6 -> -2610100
G8: 무지출 성공 | H8: =COUNTIF(B10:H28,"무지출") -> 31
B9: 변동지출 달력 | J9: 소비성 지출 분석
B10: 일 | C10: 월 | D10: 화 | E10: 수 | F10: 목 | G10: 금 | H10: 토 | J10: 항목 | K10: 지출계 | L10: 예산 | M10: 예산대비 | N10: 전월지출 | O10: 전월대비
B11: =DATE($A$1,$A$2,1)-WEEKDAY(DATE($A$1,$A$2,1))+1 -> 45711 | C11: =B11+1 -> 45712 | D11: =C11+1 -> 45713 | E11: =D11+1 -> 45714 | F11: =E11+1 -> 45715 | G11: =F11+1 -> 45716 | H11: =G11+1 -> 45717 | J11: =항목!E$3 -> 식비 | K11: =SUMIF($N$58:$N$165,J11,$T$58:$T$165) -> 0 | L11: =VLOOKUP(J11,예산!$B$41:$N$53,4,FALSE) -> 0 | M11: =L11-K11 -> 0 | N11: =VLOOKUP(J11,'2월'!$J$10:$K$23,2,FALSE) -> 0 | O11: =K11-N11 -> 0
B12: =IF(MONTH(B11)<>$A$2,"",IF(AND(SUMIF($J$81:$J$145,B11,$R$81:$R$145)=0,B11<TODAY()),"무지출",SUMIF($J$81:$J$145,B11,$R$81:$R$145))) | C12: =IF(MONTH(C11)<>$A$2,"",IF(AND(SUMIF($J$81:$J$145,C11,$R$81:$R$145)=0,C11<TODAY()),"무지출",SUMIF($J$81:$J$145,C11,$R$81:$R$145))) | D12: =IF(MONTH(D11)<>$A$2,"",IF(AND(SUMIF($J$81:$J$145,D11,$R$81:$R$145)=0,D11<TODAY()),"무지출",SUMIF($J$81:$J$145,D11,$R$81:$R$145))) | E12: =IF(MONTH(E11)<>$A$2,"",IF(AND(SUMIF($J$81:$J$145,E11,$R$81:$R$145)=0,E11<TODAY()),"무지출",SUMIF($J$81:$J$145,E11,$R$81:$R$145))) | F12: =IF(MONTH(F11)<>$A$2,"",IF(AND(SUMIF($J$81:$J$145,F11,$R$81:$R$145)=0,F11<TODAY()),"무지출",SUMIF($J$81:$J$145,F11,$R$81:$R$145))) | G12: =IF(MONTH(G11)<>$A$2,"",IF(AND(SUMIF($J$81:$J$145,G11,$R$81:$R$145)=0,G11<TODAY()),"무지출",SUMIF($J$81:$J$145,G11,$R$81:$R$145))) | H12: =IF(MONTH(H11)<>$A$2,"",IF(AND(SUMIF($J$81:$J$145,H11,$R$81:$R$145)=0,H11<TODAY()),"무지출",SUMIF($J$81:$J$145,H11,$R$81:$R$145))) -> 무지출 | J12: =항목!F$3 -> 주거비 | K12: =SUMIF($N$58:$N$165,J12,$T$58:$T$165) -> 212000 | L12: =VLOOKUP(J12,예산!$B$41:$N$53,4,FALSE) -> 0 | M12: =L12-K12 -> -212000 | N12: =VLOOKUP(J12,'2월'!$J$10:$K$23,2,FALSE) -> 212000 | O12: =K12-N12 -> 0
J13: =항목!G$3 -> 생활용품비 | K13: =SUMIF($N$58:$N$165,J13,$T$58:$T$165) -> 0 | L13: =VLOOKUP(J13,예산!$B$41:$N$53,4,FALSE) -> 0 | M13: =L13-K13 -> 0 | N13: =VLOOKUP(J13,'2월'!$J$10:$K$23,2,FALSE) -> 0 | O13: =K13-N13 -> 0
B14: =B11+7 -> 45718 | C14: =C11+7 -> 45719 | D14: =D11+7 -> 45720 | E14: =E11+7 -> 45721 | F14: =F11+7 -> 45722 | G14: =G11+7 -> 45723 | H14: =H11+7 -> 45724 | J14: =항목!H$3 -> 반려동물비 | K14: =SUMIF($N$58:$N$165,J14,$T$58:$T$165) -> 0 | L14: =VLOOKUP(J14,예산!$B$41:$N$53,4,FALSE) -> 0 | M14: =L14-K14 -> 0 | N14: =VLOOKUP(J14,'2월'!$J$10:$K$23,2,FALSE) -> 0 | O14: =K14-N14 -> 0
B15: =IF(MONTH(B14)<>$A$2,"",IF(AND(SUMIF($J$81:$J$145,B14,$R$81:$R$145)=0,B14<TODAY()),"무지출",SUMIF($J$81:$J$145,B14,$R$81:$R$145))) -> 무지출 | C15: =IF(MONTH(C14)<>$A$2,"",IF(AND(SUMIF($J$81:$J$145,C14,$R$81:$R$145)=0,C14<TODAY()),"무지출",SUMIF($J$81:$J$145,C14,$R$81:$R$145))) -> 무지출 | D15: =IF(MONTH(D14)<>$A$2,"",IF(AND(SUMIF($J$81:$J$145,D14,$R$81:$R$145)=0,D14<TODAY()),"무지출",SUMIF($J$81:$J$145,D14,$R$81:$R$145))) -> 무지출 | E15: =IF(MONTH(E14)<>$A$2,"",IF(AND(SUMIF($J$81:$J$145,E14,$R$81:$R$145)=0,E14<TODAY()),"무지출",SUMIF($J$81:$J$145,E14,$R$81:$R$145))) -> 무지출 | F15: =IF(MONTH(F14)<>$A$2,"",IF(AND(SUMIF($J$81:$J$145,F14,$R$81:$R$145)=0,F14<TODAY()),"무지출",SUMIF($J$81:$J$145,F14,$R$81:$R$145))) -> 무지출 | G15: =IF(MONTH(G14)<>$A$2,"",IF(AND(SUMIF($J$81:$J$145,G14,$R$81:$R$145)=0,G14<TODAY()),"무지출",SUMIF($J$81:$J$145,G14,$R$81:$R$145))) -> 무지출 | H15: =IF(MONTH(H14)<>$A$2,"",IF(AND(SUMIF($J$81:$J$145,H14,$R$81:$R$145)=0,H14<TODAY()),"무지출",SUMIF($J$81:$J$145,H14,$R$81:$R$145))) -> 무지출 | J15: =항목!I$3 -> 의류미용비 | K15: =SUMIF($N$58:$N$165,J15,$T$58:$T$165) -> 0 | L15: =VLOOKUP(J15,예산!$B$41:$N$53,4,FALSE) -> 0 | M15: =L15-K15 -> 0 | N15: =VLOOKUP(J15,'2월'!$J$10:$K$23,2,FALSE) -> 0 | O15: =K15-N15 -> 0
J16: =항목!J$3 -> 교육비 | K16: =SUMIF($N$58:$N$165,J16,$T$58:$T$165) -> 0 | L16: =VLOOKUP(J16,예산!$B$41:$N$53,4,FALSE) -> 0 | M16: =L16-K16 -> 0 | N16: =VLOOKUP(J16,'2월'!$J$10:$K$23,2,FALSE) -> 0 | O16: =K16-N16 -> 0
B17: =B11+14 -> 45725 | C17: =C11+14 -> 45726 | D17: =D11+14 -> 45727 | E17: =E11+14 -> 45728 | F17: =F11+14 -> 45729 | G17: =G11+14 -> 45730 | H17: =H11+14 -> 45731 | J17: =항목!K$3 -> 문화생활비 | K17: =SUMIF($N$58:$N$165,J17,$T$58:$T$165) -> 63100 | L17: =VLOOKUP(J17,예산!$B$41:$N$53,4,FALSE) -> 0 | M17: =L17-K17 -> -63100 | N17: =VLOOKUP(J17,'2월'!$J$10:$K$23,2,FALSE) -> 63100 | O17: =K17-N17 -> 0
B18: =IF(MONTH(B17)<>$A$2,"",IF(AND(SUMIF($J$81:$J$145,B17,$R$81:$R$145)=0,B17<TODAY()),"무지출",SUMIF($J$81:$J$145,B17,$R$81:$R$145))) -> 무지출 | C18: =IF(MONTH(C17)<>$A$2,"",IF(AND(SUMIF($J$81:$J$145,C17,$R$81:$R$145)=0,C17<TODAY()),"무지출",SUMIF($J$81:$J$145,C17,$R$81:$R$145))) -> 무지출 | D18: =IF(MONTH(D17)<>$A$2,"",IF(AND(SUMIF($J$81:$J$145,D17,$R$81:$R$145)=0,D17<TODAY()),"무지출",SUMIF($J$81:$J$145,D17,$R$81:$R$145))) -> 무지출 | E18: =IF(MONTH(E17)<>$A$2,"",IF(AND(SUMIF($J$81:$J$145,E17,$R$81:$R$145)=0,E17<TODAY()),"무지출",SUMIF($J$81:$J$145,E17,$R$81:$R$145))) -> 무지출 | F18: =IF(MONTH(F17)<>$A$2,"",IF(AND(SUMIF($J$81:$J$145,F17,$R$81:$R$145)=0,F17<TODAY()),"무지출",SUMIF($J$81:$J$145,F17,$R$81:$R$145))) -> 무지출 | G18: =IF(MONTH(G17)<>$A$2,"",IF(AND(SUMIF($J$81:$J$145,G17,$R$81:$R$145)=0,G17<TODAY()),"무지출",SUMIF($J$81:$J$145,G17,$R$81:$R$145))) -> 무지출 | H18: =IF(MONTH(H17)<>$A$2,"",IF(AND(SUMIF($J$81:$J$145,H17,$R$81:$R$145)=0,H17<TODAY()),"무지출",SUMIF($J$81:$J$145,H17,$R$81:$R$145))) -> 무지출 | J18: =항목!L$3 -> 의료비 | K18: =SUMIF($N$58:$N$165,J18,$T$58:$T$165) -> 0 | L18: =VLOOKUP(J18,예산!$B$41:$N$53,4,FALSE) -> 0 | M18: =L18-K18 -> 0 | N18: =VLOOKUP(J18,'2월'!$J$10:$K$23,2,FALSE) -> 0 | O18: =K18-N18 -> 0
J19: =항목!M$3 -> 유류교통비 | K19: =SUMIF($N$58:$N$165,J19,$T$58:$T$165) -> 0 | L19: =VLOOKUP(J19,예산!$B$41:$N$53,4,FALSE) -> 0 | M19: =L19-K19 -> 0 | N19: =VLOOKUP(J19,'2월'!$J$10:$K$23,2,FALSE) -> 0 | O19: =K19-N19 -> 0
B20: =B11+21 -> 45732 | C20: =C11+21 -> 45733 | D20: =D11+21 -> 45734 | E20: =E11+21 -> 45735 | F20: =F11+21 -> 45736 | G20: =G11+21 -> 45737 | H20: =H11+21 -> 45738 | J20: =항목!N$3 -> 통신비 | K20: =SUMIF($N$58:$N$165,J20,$T$58:$T$165) -> 0 | L20: =VLOOKUP(J20,예산!$B$41:$N$53,4,FALSE) -> 0 | M20: =L20-K20 -> 0 | N20: =VLOOKUP(J20,'2월'!$J$10:$K$23,2,FALSE) -> 0 | O20: =K20-N20 -> 0
B21: =IF(MONTH(B20)<>$A$2,"",IF(AND(SUMIF($J$81:$J$145,B20,$R$81:$R$145)=0,B20<TODAY()),"무지출",SUMIF($J$81:$J$145,B20,$R$81:$R$145))) -> 무지출 | C21: =IF(MONTH(C20)<>$A$2,"",IF(AND(SUMIF($J$81:$J$145,C20,$R$81:$R$145)=0,C20<TODAY()),"무지출",SUMIF($J$81:$J$145,C20,$R$81:$R$145))) -> 무지출 | D21: =IF(MONTH(D20)<>$A$2,"",IF(AND(SUMIF($J$81:$J$145,D20,$R$81:$R$145)=0,D20<TODAY()),"무지출",SUMIF($J$81:$J$145,D20,$R$81:$R$145))) -> 무지출 | E21: =IF(MONTH(E20)<>$A$2,"",IF(AND(SUMIF($J$81:$J$145,E20,$R$81:$R$145)=0,E20<TODAY()),"무지출",SUMIF($J$81:$J$145,E20,$R$81:$R$145))) -> 무지출 | F21: =IF(MONTH(F20)<>$A$2,"",IF(AND(SUMIF($J$81:$J$145,F20,$R$81:$R$145)=0,F20<TODAY()),"무지출",SUMIF($J$81:$J$145,F20,$R$81:$R$145))) -> 무지출 | G21: =IF(MONTH(G20)<>$A$2,"",IF(AND(SUMIF($J$81:$J$145,G20,$R$81:$R$145)=0,G20<TODAY()),"무지출",SUMIF($J$81:$J$145,G20,$R$81:$R$145))) -> 무지출 | H21: =IF(MONTH(H20)<>$A$2,"",IF(AND(SUMIF($J$81:$J$145,H20,$R$81:$R$145)=0,H20<TODAY()),"무지출",SUMIF($J$81:$J$145,H20,$R$81:$R$145))) -> 무지출 | J21: =항목!O$3 -> 경조사회비 | K21: =SUMIF($N$58:$N$165,J21,$T$58:$T$165) -> 0 | L21: =VLOOKUP(J21,예산!$B$41:$N$53,4,FALSE) -> 0 | M21: =L21-K21 -> 0 | N21: =VLOOKUP(J21,'2월'!$J$10:$K$23,2,FALSE) -> 0 | O21: =K21-N21 -> 0
J22: =항목!P$3 -> 용돈 | K22: =SUMIF($N$58:$N$165,J22,$T$58:$T$165) -> 0 | L22: =VLOOKUP(J22,예산!$B$41:$N$53,4,FALSE) -> 0 | M22: =L22-K22 -> 0 | N22: =VLOOKUP(J22,'2월'!$J$10:$K$23,2,FALSE) -> 0 | O22: =K22-N22 -> 0
B23: =B11+28 -> 45739 | C23: =C11+28 -> 45740 | D23: =D11+28 -> 45741 | E23: =E11+28 -> 45742 | F23: =F11+28 -> 45743 | G23: =G11+28 -> 45744 | H23: =H11+28 -> 45745 | J23: =항목!Q$3 -> 추가항목 | K23: =SUMIF($N$58:$N$165,J23,$T$58:$T$165) -> 0 | L23: =VLOOKUP(J23,예산!$B$41:$N$53,4,FALSE) -> 0 | M23: =L23-K23 -> 0 | N23: =VLOOKUP(J23,'2월'!$J$10:$K$23,2,FALSE) -> 0 | O23: =K23-N23 -> 0
B24: =IF(MONTH(B23)<>$A$2,"",IF(AND(SUMIF($J$81:$J$145,B23,$R$81:$R$145)=0,B23<TODAY()),"무지출",SUMIF($J$81:$J$145,B23,$R$81:$R$145))) -> 무지출 | C24: =IF(MONTH(C23)<>$A$2,"",IF(AND(SUMIF($J$81:$J$145,C23,$R$81:$R$145)=0,C23<TODAY()),"무지출",SUMIF($J$81:$J$145,C23,$R$81:$R$145))) -> 무지출 | D24: =IF(MONTH(D23)<>$A$2,"",IF(AND(SUMIF($J$81:$J$145,D23,$R$81:$R$145)=0,D23<TODAY()),"무지출",SUMIF($J$81:$J$145,D23,$R$81:$R$145))) -> 무지출 | E24: =IF(MONTH(E23)<>$A$2,"",IF(AND(SUMIF($J$81:$J$145,E23,$R$81:$R$145)=0,E23<TODAY()),"무지출",SUMIF($J$81:$J$145,E23,$R$81:$R$145))) -> 무지출 | F24: =IF(MONTH(F23)<>$A$2,"",IF(AND(SUMIF($J$81:$J$145,F23,$R$81:$R$145)=0,F23<TODAY()),"무지출",SUMIF($J$81:$J$145,F23,$R$81:$R$145))) -> 무지출 | G24: =IF(MONTH(G23)<>$A$2,"",IF(AND(SUMIF($J$81:$J$145,G23,$R$81:$R$145)=0,G23<TODAY()),"무지출",SUMIF($J$81:$J$145,G23,$R$81:$R$145))) -> 무지출 | H24: =IF(MONTH(H23)<>$A$2,"",IF(AND(SUMIF($J$81:$J$145,H23,$R$81:$R$145)=0,H23<TODAY()),"무지출",SUMIF($J$81:$J$145,H23,$R$81:$R$145))) -> 무지출
J25: MEMO
B26: =B11+35 -> 45746 | C26: =C11+35 -> 45747 | D26: =D11+35 -> 45748 | E26: =E11+35 -> 45749 | F26: =F11+35 -> 45750 | G26: =G11+35 -> 45751 | H26: =H11+35 -> 45752
B27: =IF(MONTH(B26)<>$A$2,"",IF(AND(SUMIF($J$81:$J$145,B26,$R$81:$R$145)=0,B26<TODAY()),"무지출",SUMIF($J$81:$J$145,B26,$R$81:$R$145))) -> 무지출 | C27: =IF(MONTH(C26)<>$A$2,"",IF(AND(SUMIF($J$81:$J$145,C26,$R$81:$R$145)=0,C26<TODAY()),"무지출",SUMIF($J$81:$J$145,C26,$R$81:$R$145))) -> 무지출 | D27: =IF(MONTH(D26)<>$A$2,"",IF(AND(SUMIF($J$81:$J$145,D26,$R$81:$R$145)=0,D26<TODAY()),"무지출",SUMIF($J$81:$J$145,D26,$R$81:$R$145))) | E27: =IF(MONTH(E26)<>$A$2,"",IF(AND(SUMIF($J$81:$J$145,E26,$R$81:$R$145)=0,E26<TODAY()),"무지출",SUMIF($J$81:$J$145,E26,$R$81:$R$145))) | F27: =IF(MONTH(F26)<>$A$2,"",IF(AND(SUMIF($J$81:$J$145,F26,$R$81:$R$145)=0,F26<TODAY()),"무지출",SUMIF($J$81:$J$145,F26,$R$81:$R$145))) | G27: =IF(MONTH(G26)<>$A$2,"",IF(AND(SUMIF($J$81:$J$145,G26,$R$81:$R$145)=0,G26<TODAY()),"무지출",SUMIF($J$81:$J$145,G26,$R$81:$R$145))) | H27: =IF(MONTH(H26)<>$A$2,"",IF(AND(SUMIF($J$81:$J$145,H26,$R$81:$R$145)=0,H26<TODAY()),"무지출",SUMIF($J$81:$J$145,H26,$R$81:$R$145)))
B30: 수입 | J30: 지출
B32: 고정수입 | C32: =SUM($H$34:$H$53) -> 0 | J32: 저축성지출 | K32: =SUM($T$34:$T$53) -> 2350000
B33: 날짜 | C33: 대상분류 | D33: 대분류 | E33: 소분류 | F33: 내용 | H33: 금액 | J33: 날짜 | K33: 대상분류 | L33: 결제분류 | M33: 결제상세 | N33: 대분류 | O33: 소분류 | P33: 지출 내용 | R33: 결제금액 | S33: 할인 | T33: 실지출 | U33: 비고
B34: 45658 | C34: 본인 | D34: 수입 | E34: 급여 | F34: 월급 | J34: 45658 | K34: 본인 | L34: 신용카드 | M34: 삼성_텝텝오 | N34: 저축성지출 | O34: 예/적금 | P34: 적금 | R34: 500000 | S34: 0 | T34: =IF(R34="","",R34-S34) -> 500000 | U34: 매월 5일 출금
J35: 45658 | K35: 본인 | L35: 신용카드 | M35: 삼성_텝텝오 | N35: 저축성지출 | O35: 퇴직연금 | P35: 개인 연금 | R35: 250000 | S35: 0 | T35: =IF(R35="","",R35-S35) -> 250000
J36: 45658 | K36: 본인 | L36: 신용카드 | M36: 삼성_텝텝오 | N36: 저축성지출 | O36: 주택청약 | P36: 주택청약 | R36: 100000 | S36: 0 | T36: =IF(R36="","",R36-S36) -> 100000
J37: 45658 | K37: 본인 | L37: 신용카드 | M37: 삼성_텝텝오 | N37: 저축성지출 | O37: 비상금 | P37: 비상금 | R37: 1500000 | S37: 0 | T37: =IF(R37="","",R37-S37) -> 1500000
T38: =IF(R38="","",R38-S38)
T39: =IF(R39="","",R39-S39)
T40: =IF(R40="","",R40-S40)
T41: =IF(R41="","",R41-S41)
T42: =IF(R42="","",R42-S42)
T43: =IF(R43="","",R43-S43)
T44: =IF(R44="","",R44-S44)
T45: =IF(R45="","",R45-S45)
...

Sheet 4월
A1: =메인!$R$3 -> 2025 | B1: ◀ 04월 ▶
A2: =메인!$H$11 -> 4
B5: 총 수입 | C5: =SUM($C$32+$C$56) -> 15000 | J5: ='1월'!J5 -> 이번달 목표 | P5: 필수지출
B6: 총 지출 | C6: =SUM($K$32+$L$56) -> 2625100
B7: 차액 | C7: =$C$5-$C$6 -> -2610100
G8: 무지출 성공 | H8: =COUNTIF(B10:H28,"무지출") -> 30
B9: 변동지출 달력 | J9: 소비성 지출 분석
B10: 일 | C10: 월 | D10: 화 | E10: 수 | F10: 목 | G10: 금 | H10: 토 | J10: 항목 | K10: 지출계 | L10: 예산 | M10: 예산대비 | N10: 전월지출 | O10: 전월대비
B11: =DATE($A$1,$A$2,1)-WEEKDAY(DATE($A$1,$A$2,1))+1 -> 45746 | C11: =B11+1 -> 45747 | D11: =C11+1 -> 45748 | E11: =D11+1 -> 45749 | F11: =E11+1 -> 45750 | G11: =F11+1 -> 45751 | H11: =G11+1 -> 45752 | J11: =항목!E$3 -> 식비 | K11: =SUMIF($N$58:$N$165,J11,$T$58:$T$165) -> 0 | L11: =VLOOKUP(J11,예산!$B$41:$N$53,5,FALSE) -> 0 | M11: =L11-K11 -> 0 | N11: =VLOOKUP(J11,'3월'!$J$10:$K$23,2,FALSE) -> 0 | O11: =K11-N11 -> 0
B12: =IF(MONTH(B11)<>$A$2,"",IF(AND(SUMIF($J$81:$J$145,B11,$R$81:$R$145)=0,B11<TODAY()),"무지출",SUMIF($J$81:$J$145,B11,$R$81:$R$145))) | C12: =IF(MONTH(C11)<>$A$2,"",IF(AND(SUMIF($J$81:$J$145,C11,$R$81:$R$145)=0,C11<TODAY()),"무지출",SUMIF($J$81:$J$145,C11,$R$81:$R$145))) | D12: =IF(MONTH(D11)<>$A$2,"",IF(AND(SUMIF($J$81:$J$145,D11,$R$81:$R$145)=0,D11<TODAY()),"무지출",SUMIF($J$81:$J$145,D11,$R$81:$R$145))) -> 무지출 | E12: =IF(MONTH(E11)<>$A$2,"",IF(AND(SUMIF($J$81:$J$145,E11,$R$81:$R$145)=0,E11<TODAY()),"무지출",SUMIF($J$81:$J$145,E11,$R$81:$R$145))) -> 무지출 | F12: =IF(MONTH(F11)<>$A$2,"",IF(AND(SUMIF($J$81:$J$145,F11,$R$81:$R$145)=0,F11<TODAY()),"무지출",SUMIF($J$81:$J$145,F11,$R$81:$R$145))) -> 무지출 | G12: =IF(MONTH(G11)<>$A$2,"",IF(AND(SUMIF($J$81:$J$145,G11,$R$81:$R$145)=0,G11<TODAY()),"무지출",SUMIF($J$81:$J$145,G11,$R$81:$R$145))) -> 무지출 | H12: =IF(MONTH(H11)<>$A$2,"",IF(AND(SUMIF($J$81:$J$145,H11,$R$81:$R$145)=0,H11<TODAY()),"무지출",SUMIF($J$81:$J$145,H11,$R$81:$R$145))) -> 무지출 | J12: =항목!F$3 -> 주거비 | K12: =SUMIF($N$58:$N$165,J12,$T$58:$T$165) -> 212000 | L12: =VLOOKUP(J12,예산!$B$41:$N$53,5,FALSE) -> 0 | M12: =L12-K12 -> -212000 | N12: =VLOOKUP(J12,'3월'!$J$10:$K$23,2,FALSE) -> 212000 | O12: =K12-N12 -> 0
J13: =항목!G$3 -> 생활용품비 | K13: =SUMIF($N$58:$N$165,J13,$T$58:$T$165) -> 0 | L13: =VLOOKUP(J13,예산!$B$41:$N$53,5,FALSE) -> 0 | M13: =L13-K13 -> 0 | N13: =VLOOKUP(J13,'3월'!$J$10:$K$23,2,FALSE) -> 0 | O13: =K13-N13 -> 0
B14: =B11+7 -> 45753 | C14: =C11+7 -> 45754 | D14: =D11+7 -> 45755 | E14: =E11+7 -> 45756 | F14: =F11+7 -> 45757 | G14: =G11+7 -> 45758 | H14: =H11+7 -> 45759 | J14: =항목!H$3 -> 반려동물비 | K14: =SUMIF($N$58:$N$165,J14,$T$58:$T$165) -> 0 | L14: =VLOOKUP(J14,예산!$B$41:$N$53,5,FALSE) -> 0 | M14: =L14-K14 -> 0 | N14: =VLOOKUP(J14,'3월'!$J$10:$K$23,2,FALSE) -> 0 | O14: =K14-N14 -> 0
B15: =IF(MONTH(B14)<>$A$2,"",IF(AND(SUMIF($J$81:$J$145,B14,$R$81:$R$145)=0,B14<TODAY()),"무지출",SUMIF($J$81:$J$145,B14,$R$81:$R$145))) -> 무지출 | C15: =IF(MONTH(C14)<>$A$2,"",IF(AND(SUMIF($J$81:$J$145,C14,$R$81:$R$145)=0,C14<TODAY()),"무지출",SUMIF($J$81:$J$145,C14,$R$81:$R$145))) -> 무지출 | D15: =IF(MONTH(D14)<>$A$2,"",IF(AND(SUMIF($J$81:$J$145,D14,$R$81:$R$145)=0,D14<TODAY()),"무지출",SUMIF($J$81:$J$145,D14,$R$81:$R$145))) -> 무지출 | E15: =IF(MONTH(E14)<>$A$2,"",IF(AND(SUMIF($J$81:$J$145,E14,$R$81:$R$145)=0,E14<TODAY()),"무지출",SUMIF($J$81:$J$145,E14,$R$81:$R$145))) -> 무지출 | F15: =IF(MONTH(F14)<>$A$2,"",IF(AND(SUMIF($J$81:$J$145,F14,$R$81:$R$145)=0,F14<TODAY()),"무지출",SUMIF($J$81:$J$145,F14,$R$81:$R$145))) -> 무지출 | G15: =IF(MONTH(G14)<>$A$2,"",IF(AND(SUMIF($J$81:$J$145,G14,$R$81:$R$145)=0,G14<TODAY()),"무지출",SUMIF($J$81:$J$145,G14,$R$81:$R$145))) -> 무지출 | H15: =IF(MONTH(H14)<>$A$2,"",IF(AND(SUMIF($J$81:$J$145,H14,$R$81:$R$145)=0,H14<TODAY()),"무지출",SUMIF($J$81:$J$145,H14,$R$81:$R$145))) -> 무지출 | J15: =항목!I$3 -> 의류미용비 | K15: =SUMIF($N$58:$N$165,J15,$T$58:$T$165) -> 0 | L15: =VLOOKUP(J15,예산!$B$41:$N$53,5,FALSE) -> 0 | M15: =L15-K15 -> 0 | N15: =VLOOKUP(J15,'3월'!$J$10:$K$23,2,FALSE) -> 0 | O15: =K15-N15 -> 0
J16: =항목!J$3 -> 교육비 | K16: =SUMIF($N$58:$N$165,J16,$T$58:$T$165) -> 0 | L16: =VLOOKUP(J16,예산!$B$41:$N$53,5,FALSE) -> 0 | M16: =L16-K16 -> 0 | N16: =VLOOKUP(J16,'3월'!$J$10:$K$23,2,FALSE) -> 0 | O16: =K16-N16 -> 0
B17: =B11+14 -> 45760 | C17: =C11+14 -> 45761 | D17: =D11+14 -> 45762 | E17: =E11+14 -> 45763 | F17: =F11+14 -> 45764 | G17: =G11+14 -> 45765 | H17: =H11+14 -> 45766 | J17: =항목!K$3 -> 문화생활비 | K17: =SUMIF($N$58:$N$165,J17,$T$58:$T$165) -> 63100 | L17: =VLOOKUP(J17,예산!$B$41:$N$53,5,FALSE) -> 0 | M17: =L17-K17 -> -63100 | N17: =VLOOKUP(J17,'3월'!$J$10:$K$23,2,FALSE) -> 63100 | O17: =K17-N17 -> 0
B18: =IF(MONTH(B17)<>$A$2,"",IF(AND(SUMIF($J$81:$J$145,B17,$R$81:$R$145)=0,B17<TODAY()),"무지출",SUMIF($J$81:$J$145,B17,$R$81:$R$145))) -> 무지출 | C18: =IF(MONTH(C17)<>$A$2,"",IF(AND(SUMIF($J$81:$J$145,C17,$R$81:$R$145)=0,C17<TODAY()),"무지출",SUMIF($J$81:$J$145,C17,$R$81:$R$145))) -> 무지출 | D18: =IF(MONTH(D17)<>$A$2,"",IF(AND(SUMIF($J$81:$J$145,D17,$R$81:$R$145)=0,D17<TODAY()),"무지출",SUMIF($J$81:$J$145,D17,$R$81:$R$145))) -> 무지출 | E18: =IF(MONTH(E17)<>$A$2,"",IF(AND(SUMIF($J$81:$J$145,E17,$R$81:$R$145)=0,E17<TODAY()),"무지출",SUMIF($J$81:$J$145,E17,$R$81:$R$145))) -> 무지출 | F18: =IF(MONTH(F17)<>$A$2,"",IF(AND(SUMIF($J$81:$J$145,F17,$R$81:$R$145)=0,F17<TODAY()),"무지출",SUMIF($J$81:$J$145,F17,$R$81:$R$145))) -> 무지출 | G18: =IF(MONTH(G17)<>$A$2,"",IF(AND(SUMIF($J$81:$J$145,G17,$R$81:$R$145)=0,G17<TODAY()),"무지출",SUMIF($J$81:$J$145,G17,$R$81:$R$145))) -> 무지출 | H18: =IF(MONTH(H17)<>$A$2,"",IF(AND(SUMIF($J$81:$J$145,H17,$R$81:$R$145)=0,H17<TODAY()),"무지출",SUMIF($J$81:$J$145,H17,$R$81:$R$145))) -> 무지출 | J18: =항목!L$3 -> 의료비 | K18: =SUMIF($N$58:$N$165,J18,$T$58:$T$165) -> 0 | L18: =VLOOKUP(J18,예산!$B$41:$N$53,5,FALSE) -> 0 | M18: =L18-K18 -> 0 | N18: =VLOOKUP(J18,'3월'!$J$10:$K$23,2,FALSE) -> 0 | O18: =K18-N18 -> 0
J19: =항목!M$3 -> 유류교통비 | K19: =SUMIF($N$58:$N$165,J19,$T$58:$T$165) -> 0 | L19: =VLOOKUP(J19,예산!$B$41:$N$53,5,FALSE) -> 0 | M19: =L19-K19 -> 0 | N19: =VLOOKUP(J19,'3월'!$J$10:$K$23,2,FALSE) -> 0 | O19: =K19-N19 -> 0
B20: =B11+21 -> 45767 | C20: =C11+21 -> 45768 | D20: =D11+21 -> 45769 | E20: =E11+21 -> 45770 | F20: =F11+21 -> 45771 | G20: =G11+21 -> 45772 | H20: =H11+21 -> 45773 | J20: =항목!N$3 -> 통신비 | K20: =SUMIF($N$58:$N$165,J20,$T$58:$T$165) -> 0 | L20: =VLOOKUP(J20,예산!$B$41:$N$53,5,FALSE) -> 0 | M20: =L20-K20 -> 0 | N20: =VLOOKUP(J20,'3월'!$J$10:$K$23,2,FALSE) -> 0 | O20: =K20-N20 -> 0
B21: =IF(MONTH(B20)<>$A$2,"",IF(AND(SUMIF($J$81:$J$145,B20,$R$81:$R$145)=0,B20<TODAY()),"무지출",SUMIF($J$81:$J$145,B20,$R$81:$R$145))) -> 무지출 | C21: =IF(MONTH(C20)<>$A$2,"",IF(AND(SUMIF($J$81:$J$145,C20,$R$81:$R$145)=0,C20<TODAY()),"무지출",SUMIF($J$81:$J$145,C20,$R$81:$R$145))) -> 무지출 | D21: =IF(MONTH(D20)<>$A$2,"",IF(AND(SUMIF($J$81:$J$145,D20,$R$81:$R$145)=0,D20<TODAY()),"무지출",SUMIF($J$81:$J$145,D20,$R$81:$R$145))) -> 무지출 | E21: =IF(MONTH(E20)<>$A$2,"",IF(AND(SUMIF($J$81:$J$145,E20,$R$81:$R$145)=0,E20<TODAY()),"무지출",SUMIF($J$81:$J$145,E20,$R$81:$R$145))) -> 무지출 | F21: =IF(MONTH(F20)<>$A$2,"",IF(AND(SUMIF($J$81:$J$145,F20,$R$81:$R$145)=0,F20<TODAY()),"무지출",SUMIF($J$81:$J$145,F20,$R$81:$R$145))) -> 무지출 | G21: =IF(MONTH(G20)<>$A$2,"",IF(AND(SUMIF($J$81:$J$145,G20,$R$81:$R$145)=0,G20<TODAY()),"무지출",SUMIF($J$81:$J$145,G20,$R$81:$R$145))) -> 무지출 | H21: =IF(MONTH(H20)<>$A$2,"",IF(AND(SUMIF($J$81:$J$145,H20,$R$81:$R$145)=0,H20<TODAY()),"무지출",SUMIF($J$81:$J$145,H20,$R$81:$R$145))) -> 무지출 | J21: =항목!O$3 -> 경조사회비 | K21: =SUMIF($N$58:$N$165,J21,$T$58:$T$165) -> 0 | L21: =VLOOKUP(J21,예산!$B$41:$N$53,5,FALSE) -> 0 | M21: =L21-K21 -> 0 | N21: =VLOOKUP(J21,'3월'!$J$10:$K$23,2,FALSE) -> 0 | O21: =K21-N21 -> 0
J22: =항목!P$3 -> 용돈 | K22: =SUMIF($N$58:$N$165,J22,$T$58:$T$165) -> 0 | L22: =VLOOKUP(J22,예산!$B$41:$N$53,5,FALSE) -> 0 | M22: =L22-K22 -> 0 | N22: =VLOOKUP(J22,'3월'!$J$10:$K$23,2,FALSE) -> 0 | O22: =K22-N22 -> 0
B23: =B11+28 -> 45774 | C23: =C11+28 -> 45775 | D23: =D11+28 -> 45776 | E23: =E11+28 -> 45777 | F23: =F11+28 -> 45778 | G23: =G11+28 -> 45779 | H23: =H11+28 -> 45780 | J23: =항목!Q$3 -> 추가항목 | K23: =SUMIF($N$58:$N$165,J23,$T$58:$T$165) -> 0 | L23: =VLOOKUP(J23,예산!$B$41:$N$53,5,FALSE) -> 0 | M23: =L23-K23 -> 0 | N23: =VLOOKUP(J23,'3월'!$J$10:$K$23,2,FALSE) -> 0 | O23: =K23-N23 -> 0
B24: =IF(MONTH(B23)<>$A$2,"",IF(AND(SUMIF($J$81:$J$145,B23,$R$81:$R$145)=0,B23<TODAY()),"무지출",SUMIF($J$81:$J$145,B23,$R$81:$R$145))) -> 무지출 | C24: =IF(MONTH(C23)<>$A$2,"",IF(AND(SUMIF($J$81:$J$145,C23,$R$81:$R$145)=0,C23<TODAY()),"무지출",SUMIF($J$81:$J$145,C23,$R$81:$R$145))) -> 무지출 | D24: =IF(MONTH(D23)<>$A$2,"",IF(AND(SUMIF($J$81:$J$145,D23,$R$81:$R$145)=0,D23<TODAY()),"무지출",SUMIF($J$81:$J$145,D23,$R$81:$R$145))) -> 무지출 | E24: =IF(MONTH(E23)<>$A$2,"",IF(AND(SUMIF($J$81:$J$145,E23,$R$81:$R$145)=0,E23<TODAY()),"무지출",SUMIF($J$81:$J$145,E23,$R$81:$R$145))) -> 무지출 | F24: =IF(MONTH(F23)<>$A$2,"",IF(AND(SUMIF($J$81:$J$145,F23,$R$81:$R$145)=0,F23<TODAY()),"무지출",SUMIF($J$81:$J$145,F23,$R$81:$R$145))) | G24: =IF(MONTH(G23)<>$A$2,"",IF(AND(SUMIF($J$81:$J$145,G23,$R$81:$R$145)=0,G23<TODAY()),"무지출",SUMIF($J$81:$J$145,G23,$R$81:$R$145))) | H24: =IF(MONTH(H23)<>$A$2,"",IF(AND(SUMIF($J$81:$J$145,H23,$R$81:$R$145)=0,H23<TODAY()),"무지출",SUMIF($J$81:$J$145,H23,$R$81:$R$145)))
J25: MEMO
B26: =B11+35 -> 45781 | C26: =C11+35 -> 45782 | D26: =D11+35 -> 45783 | E26: =E11+35 -> 45784 | F26: =F11+35 -> 45785 | G26: =G11+35 -> 45786 | H26: =H11+35 -> 45787
B27: =IF(MONTH(B26)<>$A$2,"",IF(AND(SUMIF($J$81:$J$145,B26,$R$81:$R$145)=0,B26<TODAY()),"무지출",SUMIF($J$81:$J$145,B26,$R$81:$R$145))) | C27: =IF(MONTH(C26)<>$A$2,"",IF(AND(SUMIF($J$81:$J$145,C26,$R$81:$R$145)=0,C26<TODAY()),"무지출",SUMIF($J$81:$J$145,C26,$R$81:$R$145))) | D27: =IF(MONTH(D26)<>$A$2,"",IF(AND(SUMIF($J$81:$J$145,D26,$R$81:$R$145)=0,D26<TODAY()),"무지출",SUMIF($J$81:$J$145,D26,$R$81:$R$145))) | E27: =IF(MONTH(E26)<>$A$2,"",IF(AND(SUMIF($J$81:$J$145,E26,$R$81:$R$145)=0,E26<TODAY()),"무지출",SUMIF($J$81:$J$145,E26,$R$81:$R$145))) | F27: =IF(MONTH(F26)<>$A$2,"",IF(AND(SUMIF($J$81:$J$145,F26,$R$81:$R$145)=0,F26<TODAY()),"무지출",SUMIF($J$81:$J$145,F26,$R$81:$R$145))) | G27: =IF(MONTH(G26)<>$A$2,"",IF(AND(SUMIF($J$81:$J$145,G26,$R$81:$R$145)=0,G26<TODAY()),"무지출",SUMIF($J$81:$J$145,G26,$R$81:$R$145))) | H27: =IF(MONTH(H26)<>$A$2,"",IF(AND(SUMIF($J$81:$J$145,H26,$R$81:$R$145)=0,H26<TODAY()),"무지출",SUMIF($J$81:$J$145,H26,$R$81:$R$145)))
B30: 수입 | J30: 지출
B32: 고정수입 | C32: =SUM($H$34:$H$53) -> 0 | J32: 저축성지출 | K32: =SUM($T$34:$T$53) -> 2350000
B33: 날짜 | C33: 대상분류 | D33: 대분류 | E33: 소분류 | F33: 내용 | H33: 금액 | J33: 날짜 | K33: 대상분류 | L33: 결제분류 | M33: 결제상세 | N33: 대분류 | O33: 소분류 | P33: 지출 내용 | R33: 결제금액 | S33: 할인 | T33: 실지출 | U33: 비고
B34: 45658 | C34: 본인 | D34: 수입 | E34: 급여 | F34: 월급 | J34: 45658 | K34: 본인 | L34: 신용카드 | M34: 삼성_텝텝오 | N34: 저축성지출 | O34: 예/적금 | P34: 적금 | R34: 500000 | S34: 0 | T34: =IF(R34="","",R34-S34) -> 500000 | U34: 매월 5일 출금
